[2024-05-11 21:01:18,138][flwr][INFO] - Starting Flower simulation, config: num_rounds=10, no round_timeout
[2024-05-11 21:01:23,507][flwr][INFO] - Flower VCE: Ray initialized with resources: {'CPU': 8.0, 'node:__internal_head__': 1.0, 'memory': 10774152807.0, 'node:127.0.0.1': 1.0, 'object_store_memory': 5387076403.0}
[2024-05-11 21:01:23,508][flwr][INFO] - Optimize your simulation with Flower VCE: https://flower.ai/docs/framework/how-to-run-simulations.html
[2024-05-11 21:01:23,509][flwr][INFO] - No `client_resources` specified. Using minimal resources for clients.
[2024-05-11 21:01:23,509][flwr][INFO] - Flower VCE: Resources for each Virtual Client: {'num_cpus': 1, 'num_gpus': 0.0}
[2024-05-11 21:01:23,522][flwr][INFO] - Flower VCE: Creating VirtualClientEngineActorPool with 8 actors
[2024-05-11 21:01:23,523][flwr][INFO] - [INIT]
[2024-05-11 21:01:23,523][flwr][INFO] - Requesting initial parameters from one random client
[2024-05-11 21:01:28,199][flwr][INFO] - Received initial parameters from one random client
[2024-05-11 21:01:28,200][flwr][INFO] - Evaluating initial global parameters
[2024-05-11 21:01:28,200][flwr][INFO] - 
[2024-05-11 21:01:28,201][flwr][INFO] - [ROUND 1]
[2024-05-11 21:01:28,202][flwr][INFO] - configure_fit: strategy sampled 1 clients (out of 2)
[2024-05-11 21:01:28,219][flwr][ERROR] - Traceback (most recent call last):
  File "C:\Users\jyaka\anaconda3\envs\flower\lib\site-packages\flwr\simulation\ray_transport\ray_client_proxy.py", line 73, in _submit_job
    out_mssg, updated_context = self.actor_pool.get_client_result(
  File "C:\Users\jyaka\anaconda3\envs\flower\lib\site-packages\flwr\simulation\ray_transport\ray_actor.py", line 399, in get_client_result
    return self._fetch_future_result(cid)
  File "C:\Users\jyaka\anaconda3\envs\flower\lib\site-packages\flwr\simulation\ray_transport\ray_actor.py", line 280, in _fetch_future_result
    res_cid, out_mssg, updated_context = ray.get(
  File "C:\Users\jyaka\anaconda3\envs\flower\lib\site-packages\ray\_private\auto_init_hook.py", line 24, in auto_init_wrapper
    return fn(*args, **kwargs)
  File "C:\Users\jyaka\anaconda3\envs\flower\lib\site-packages\ray\_private\client_mode_hook.py", line 103, in wrapper
    return func(*args, **kwargs)
  File "C:\Users\jyaka\anaconda3\envs\flower\lib\site-packages\ray\_private\worker.py", line 2524, in get
    raise value.as_instanceof_cause()
ray.exceptions.RayTaskError(ClientAppException): [36mray::ClientAppActor.run()[39m (pid=24760, ip=127.0.0.1, actor_id=0bda77c27b6b10b0fe356e3b01000000, repr=<flwr.simulation.ray_transport.ray_actor.ClientAppActor object at 0x0000023F214E7160>)
  File "C:\Users\jyaka\anaconda3\envs\flower\lib\site-packages\flwr\client\client_app.py", line 98, in __call__
    return self._call(message, context)
  File "C:\Users\jyaka\anaconda3\envs\flower\lib\site-packages\flwr\client\client_app.py", line 81, in ffn
    out_message = handle_legacy_message_from_msgtype(
  File "C:\Users\jyaka\anaconda3\envs\flower\lib\site-packages\flwr\client\message_handler\message_handler.py", line 130, in handle_legacy_message_from_msgtype
    fit_res = maybe_call_fit(
  File "C:\Users\jyaka\anaconda3\envs\flower\lib\site-packages\flwr\client\client.py", line 234, in maybe_call_fit
    return client.fit(fit_ins)
  File "C:\Users\jyaka\anaconda3\envs\flower\lib\site-packages\flwr\client\numpy_client.py", line 238, in _fit
    results = self.numpy_client.fit(parameters, ins.config)  # type: ignore
  File "C:\Users\jyaka\Documents\research\flower_tutorial\client.py", line 37, in fit
    epochs = config["epochs"]
KeyError: 'epochs'

The above exception was the direct cause of the following exception:

[36mray::ClientAppActor.run()[39m (pid=24760, ip=127.0.0.1, actor_id=0bda77c27b6b10b0fe356e3b01000000, repr=<flwr.simulation.ray_transport.ray_actor.ClientAppActor object at 0x0000023F214E7160>)
  File "python\ray\_raylet.pyx", line 1418, in ray._raylet.execute_task
  File "python\ray\_raylet.pyx", line 1498, in ray._raylet.execute_task
  File "python\ray\_raylet.pyx", line 1424, in ray._raylet.execute_task
  File "python\ray\_raylet.pyx", line 1364, in ray._raylet.execute_task.function_executor
  File "C:\Users\jyaka\anaconda3\envs\flower\lib\site-packages\ray\_private\function_manager.py", line 726, in actor_method_executor
    return method(__ray_actor, *args, **kwargs)
  File "C:\Users\jyaka\anaconda3\envs\flower\lib\site-packages\ray\util\tracing\tracing_helper.py", line 464, in _resume_span
    return method(self, *_args, **_kwargs)
  File "C:\Users\jyaka\anaconda3\envs\flower\lib\site-packages\flwr\simulation\ray_transport\ray_actor.py", line 64, in run
    raise ClientAppException(str(ex)) from ex
flwr.client.client_app.ClientAppException: 
Exception ClientAppException occurred. Message: 'epochs'

[2024-05-11 21:01:28,227][flwr][ERROR] - [36mray::ClientAppActor.run()[39m (pid=24760, ip=127.0.0.1, actor_id=0bda77c27b6b10b0fe356e3b01000000, repr=<flwr.simulation.ray_transport.ray_actor.ClientAppActor object at 0x0000023F214E7160>)
  File "C:\Users\jyaka\anaconda3\envs\flower\lib\site-packages\flwr\client\client_app.py", line 98, in __call__
    return self._call(message, context)
  File "C:\Users\jyaka\anaconda3\envs\flower\lib\site-packages\flwr\client\client_app.py", line 81, in ffn
    out_message = handle_legacy_message_from_msgtype(
  File "C:\Users\jyaka\anaconda3\envs\flower\lib\site-packages\flwr\client\message_handler\message_handler.py", line 130, in handle_legacy_message_from_msgtype
    fit_res = maybe_call_fit(
  File "C:\Users\jyaka\anaconda3\envs\flower\lib\site-packages\flwr\client\client.py", line 234, in maybe_call_fit
    return client.fit(fit_ins)
  File "C:\Users\jyaka\anaconda3\envs\flower\lib\site-packages\flwr\client\numpy_client.py", line 238, in _fit
    results = self.numpy_client.fit(parameters, ins.config)  # type: ignore
  File "C:\Users\jyaka\Documents\research\flower_tutorial\client.py", line 37, in fit
    epochs = config["epochs"]
KeyError: 'epochs'

The above exception was the direct cause of the following exception:

[36mray::ClientAppActor.run()[39m (pid=24760, ip=127.0.0.1, actor_id=0bda77c27b6b10b0fe356e3b01000000, repr=<flwr.simulation.ray_transport.ray_actor.ClientAppActor object at 0x0000023F214E7160>)
  File "python\ray\_raylet.pyx", line 1418, in ray._raylet.execute_task
  File "python\ray\_raylet.pyx", line 1498, in ray._raylet.execute_task
  File "python\ray\_raylet.pyx", line 1424, in ray._raylet.execute_task
  File "python\ray\_raylet.pyx", line 1364, in ray._raylet.execute_task.function_executor
  File "C:\Users\jyaka\anaconda3\envs\flower\lib\site-packages\ray\_private\function_manager.py", line 726, in actor_method_executor
    return method(__ray_actor, *args, **kwargs)
  File "C:\Users\jyaka\anaconda3\envs\flower\lib\site-packages\ray\util\tracing\tracing_helper.py", line 464, in _resume_span
    return method(self, *_args, **_kwargs)
  File "C:\Users\jyaka\anaconda3\envs\flower\lib\site-packages\flwr\simulation\ray_transport\ray_actor.py", line 64, in run
    raise ClientAppException(str(ex)) from ex
flwr.client.client_app.ClientAppException: 
Exception ClientAppException occurred. Message: 'epochs'
[2024-05-11 21:01:28,234][flwr][INFO] - aggregate_fit: received 0 results and 1 failures
[2024-05-11 21:01:28,234][flwr][INFO] - configure_evaluate: strategy sampled 2 clients (out of 2)
[2024-05-11 21:01:28,246][flwr][ERROR] - Traceback (most recent call last):
  File "C:\Users\jyaka\anaconda3\envs\flower\lib\site-packages\flwr\simulation\ray_transport\ray_client_proxy.py", line 73, in _submit_job
    out_mssg, updated_context = self.actor_pool.get_client_result(
  File "C:\Users\jyaka\anaconda3\envs\flower\lib\site-packages\flwr\simulation\ray_transport\ray_actor.py", line 399, in get_client_result
    return self._fetch_future_result(cid)
  File "C:\Users\jyaka\anaconda3\envs\flower\lib\site-packages\flwr\simulation\ray_transport\ray_actor.py", line 280, in _fetch_future_result
    res_cid, out_mssg, updated_context = ray.get(
  File "C:\Users\jyaka\anaconda3\envs\flower\lib\site-packages\ray\_private\auto_init_hook.py", line 24, in auto_init_wrapper
    return fn(*args, **kwargs)
  File "C:\Users\jyaka\anaconda3\envs\flower\lib\site-packages\ray\_private\client_mode_hook.py", line 103, in wrapper
    return func(*args, **kwargs)
  File "C:\Users\jyaka\anaconda3\envs\flower\lib\site-packages\ray\_private\worker.py", line 2524, in get
    raise value.as_instanceof_cause()
ray.exceptions.RayTaskError(ClientAppException): [36mray::ClientAppActor.run()[39m (pid=24760, ip=127.0.0.1, actor_id=0bda77c27b6b10b0fe356e3b01000000, repr=<flwr.simulation.ray_transport.ray_actor.ClientAppActor object at 0x0000023F214E7160>)
  File "C:\Users\jyaka\anaconda3\envs\flower\lib\site-packages\flwr\client\client_app.py", line 98, in __call__
    return self._call(message, context)
  File "C:\Users\jyaka\anaconda3\envs\flower\lib\site-packages\flwr\client\client_app.py", line 81, in ffn
    out_message = handle_legacy_message_from_msgtype(
  File "C:\Users\jyaka\anaconda3\envs\flower\lib\site-packages\flwr\client\message_handler\message_handler.py", line 137, in handle_legacy_message_from_msgtype
    evaluate_res = maybe_call_evaluate(
  File "C:\Users\jyaka\anaconda3\envs\flower\lib\site-packages\flwr\client\client.py", line 254, in maybe_call_evaluate
    return client.evaluate(evaluate_ins)
  File "C:\Users\jyaka\anaconda3\envs\flower\lib\site-packages\flwr\client\numpy_client.py", line 262, in _evaluate
    results = self.numpy_client.evaluate(parameters, ins.config)  # type: ignore
  File "C:\Users\jyaka\Documents\research\flower_tutorial\client.py", line 45, in evaluate
    self.set_parameters(self.model, parameters)
TypeError: set_parameters() takes 2 positional arguments but 3 were given

The above exception was the direct cause of the following exception:

[36mray::ClientAppActor.run()[39m (pid=24760, ip=127.0.0.1, actor_id=0bda77c27b6b10b0fe356e3b01000000, repr=<flwr.simulation.ray_transport.ray_actor.ClientAppActor object at 0x0000023F214E7160>)
  File "python\ray\_raylet.pyx", line 1418, in ray._raylet.execute_task
  File "python\ray\_raylet.pyx", line 1498, in ray._raylet.execute_task
  File "python\ray\_raylet.pyx", line 1424, in ray._raylet.execute_task
  File "python\ray\_raylet.pyx", line 1364, in ray._raylet.execute_task.function_executor
  File "C:\Users\jyaka\anaconda3\envs\flower\lib\site-packages\ray\_private\function_manager.py", line 726, in actor_method_executor
    return method(__ray_actor, *args, **kwargs)
  File "C:\Users\jyaka\anaconda3\envs\flower\lib\site-packages\ray\util\tracing\tracing_helper.py", line 464, in _resume_span
    return method(self, *_args, **_kwargs)
  File "C:\Users\jyaka\anaconda3\envs\flower\lib\site-packages\flwr\simulation\ray_transport\ray_actor.py", line 64, in run
    raise ClientAppException(str(ex)) from ex
flwr.client.client_app.ClientAppException: 
Exception ClientAppException occurred. Message: set_parameters() takes 2 positional arguments but 3 were given

[2024-05-11 21:01:28,258][flwr][ERROR] - [36mray::ClientAppActor.run()[39m (pid=24760, ip=127.0.0.1, actor_id=0bda77c27b6b10b0fe356e3b01000000, repr=<flwr.simulation.ray_transport.ray_actor.ClientAppActor object at 0x0000023F214E7160>)
  File "C:\Users\jyaka\anaconda3\envs\flower\lib\site-packages\flwr\client\client_app.py", line 98, in __call__
    return self._call(message, context)
  File "C:\Users\jyaka\anaconda3\envs\flower\lib\site-packages\flwr\client\client_app.py", line 81, in ffn
    out_message = handle_legacy_message_from_msgtype(
  File "C:\Users\jyaka\anaconda3\envs\flower\lib\site-packages\flwr\client\message_handler\message_handler.py", line 137, in handle_legacy_message_from_msgtype
    evaluate_res = maybe_call_evaluate(
  File "C:\Users\jyaka\anaconda3\envs\flower\lib\site-packages\flwr\client\client.py", line 254, in maybe_call_evaluate
    return client.evaluate(evaluate_ins)
  File "C:\Users\jyaka\anaconda3\envs\flower\lib\site-packages\flwr\client\numpy_client.py", line 262, in _evaluate
    results = self.numpy_client.evaluate(parameters, ins.config)  # type: ignore
  File "C:\Users\jyaka\Documents\research\flower_tutorial\client.py", line 45, in evaluate
    self.set_parameters(self.model, parameters)
TypeError: set_parameters() takes 2 positional arguments but 3 were given

The above exception was the direct cause of the following exception:

[36mray::ClientAppActor.run()[39m (pid=24760, ip=127.0.0.1, actor_id=0bda77c27b6b10b0fe356e3b01000000, repr=<flwr.simulation.ray_transport.ray_actor.ClientAppActor object at 0x0000023F214E7160>)
  File "python\ray\_raylet.pyx", line 1418, in ray._raylet.execute_task
  File "python\ray\_raylet.pyx", line 1498, in ray._raylet.execute_task
  File "python\ray\_raylet.pyx", line 1424, in ray._raylet.execute_task
  File "python\ray\_raylet.pyx", line 1364, in ray._raylet.execute_task.function_executor
  File "C:\Users\jyaka\anaconda3\envs\flower\lib\site-packages\ray\_private\function_manager.py", line 726, in actor_method_executor
    return method(__ray_actor, *args, **kwargs)
  File "C:\Users\jyaka\anaconda3\envs\flower\lib\site-packages\ray\util\tracing\tracing_helper.py", line 464, in _resume_span
    return method(self, *_args, **_kwargs)
  File "C:\Users\jyaka\anaconda3\envs\flower\lib\site-packages\flwr\simulation\ray_transport\ray_actor.py", line 64, in run
    raise ClientAppException(str(ex)) from ex
flwr.client.client_app.ClientAppException: 
Exception ClientAppException occurred. Message: set_parameters() takes 2 positional arguments but 3 were given
[2024-05-11 21:01:30,982][flwr][ERROR] - Traceback (most recent call last):
  File "C:\Users\jyaka\anaconda3\envs\flower\lib\site-packages\flwr\simulation\ray_transport\ray_client_proxy.py", line 73, in _submit_job
    out_mssg, updated_context = self.actor_pool.get_client_result(
  File "C:\Users\jyaka\anaconda3\envs\flower\lib\site-packages\flwr\simulation\ray_transport\ray_actor.py", line 399, in get_client_result
    return self._fetch_future_result(cid)
  File "C:\Users\jyaka\anaconda3\envs\flower\lib\site-packages\flwr\simulation\ray_transport\ray_actor.py", line 280, in _fetch_future_result
    res_cid, out_mssg, updated_context = ray.get(
  File "C:\Users\jyaka\anaconda3\envs\flower\lib\site-packages\ray\_private\auto_init_hook.py", line 24, in auto_init_wrapper
    return fn(*args, **kwargs)
  File "C:\Users\jyaka\anaconda3\envs\flower\lib\site-packages\ray\_private\client_mode_hook.py", line 103, in wrapper
    return func(*args, **kwargs)
  File "C:\Users\jyaka\anaconda3\envs\flower\lib\site-packages\ray\_private\worker.py", line 2524, in get
    raise value.as_instanceof_cause()
ray.exceptions.RayTaskError(ClientAppException): [36mray::ClientAppActor.run()[39m (pid=9728, ip=127.0.0.1, actor_id=449d6fb233f4c3623911c51301000000, repr=<flwr.simulation.ray_transport.ray_actor.ClientAppActor object at 0x000001709AF0B0D0>)
  File "C:\Users\jyaka\anaconda3\envs\flower\lib\site-packages\flwr\client\client_app.py", line 98, in __call__
    return self._call(message, context)
  File "C:\Users\jyaka\anaconda3\envs\flower\lib\site-packages\flwr\client\client_app.py", line 81, in ffn
    out_message = handle_legacy_message_from_msgtype(
  File "C:\Users\jyaka\anaconda3\envs\flower\lib\site-packages\flwr\client\message_handler\message_handler.py", line 137, in handle_legacy_message_from_msgtype
    evaluate_res = maybe_call_evaluate(
  File "C:\Users\jyaka\anaconda3\envs\flower\lib\site-packages\flwr\client\client.py", line 254, in maybe_call_evaluate
    return client.evaluate(evaluate_ins)
  File "C:\Users\jyaka\anaconda3\envs\flower\lib\site-packages\flwr\client\numpy_client.py", line 262, in _evaluate
    results = self.numpy_client.evaluate(parameters, ins.config)  # type: ignore
  File "C:\Users\jyaka\Documents\research\flower_tutorial\client.py", line 45, in evaluate
    self.set_parameters(self.model, parameters)
TypeError: set_parameters() takes 2 positional arguments but 3 were given

The above exception was the direct cause of the following exception:

[36mray::ClientAppActor.run()[39m (pid=9728, ip=127.0.0.1, actor_id=449d6fb233f4c3623911c51301000000, repr=<flwr.simulation.ray_transport.ray_actor.ClientAppActor object at 0x000001709AF0B0D0>)
  File "python\ray\_raylet.pyx", line 1418, in ray._raylet.execute_task
  File "python\ray\_raylet.pyx", line 1498, in ray._raylet.execute_task
  File "python\ray\_raylet.pyx", line 1424, in ray._raylet.execute_task
  File "python\ray\_raylet.pyx", line 1364, in ray._raylet.execute_task.function_executor
  File "C:\Users\jyaka\anaconda3\envs\flower\lib\site-packages\ray\_private\function_manager.py", line 726, in actor_method_executor
    return method(__ray_actor, *args, **kwargs)
  File "C:\Users\jyaka\anaconda3\envs\flower\lib\site-packages\ray\util\tracing\tracing_helper.py", line 464, in _resume_span
    return method(self, *_args, **_kwargs)
  File "C:\Users\jyaka\anaconda3\envs\flower\lib\site-packages\flwr\simulation\ray_transport\ray_actor.py", line 64, in run
    raise ClientAppException(str(ex)) from ex
flwr.client.client_app.ClientAppException: 
Exception ClientAppException occurred. Message: set_parameters() takes 2 positional arguments but 3 were given

[2024-05-11 21:01:30,991][flwr][ERROR] - [36mray::ClientAppActor.run()[39m (pid=9728, ip=127.0.0.1, actor_id=449d6fb233f4c3623911c51301000000, repr=<flwr.simulation.ray_transport.ray_actor.ClientAppActor object at 0x000001709AF0B0D0>)
  File "C:\Users\jyaka\anaconda3\envs\flower\lib\site-packages\flwr\client\client_app.py", line 98, in __call__
    return self._call(message, context)
  File "C:\Users\jyaka\anaconda3\envs\flower\lib\site-packages\flwr\client\client_app.py", line 81, in ffn
    out_message = handle_legacy_message_from_msgtype(
  File "C:\Users\jyaka\anaconda3\envs\flower\lib\site-packages\flwr\client\message_handler\message_handler.py", line 137, in handle_legacy_message_from_msgtype
    evaluate_res = maybe_call_evaluate(
  File "C:\Users\jyaka\anaconda3\envs\flower\lib\site-packages\flwr\client\client.py", line 254, in maybe_call_evaluate
    return client.evaluate(evaluate_ins)
  File "C:\Users\jyaka\anaconda3\envs\flower\lib\site-packages\flwr\client\numpy_client.py", line 262, in _evaluate
    results = self.numpy_client.evaluate(parameters, ins.config)  # type: ignore
  File "C:\Users\jyaka\Documents\research\flower_tutorial\client.py", line 45, in evaluate
    self.set_parameters(self.model, parameters)
TypeError: set_parameters() takes 2 positional arguments but 3 were given

The above exception was the direct cause of the following exception:

[36mray::ClientAppActor.run()[39m (pid=9728, ip=127.0.0.1, actor_id=449d6fb233f4c3623911c51301000000, repr=<flwr.simulation.ray_transport.ray_actor.ClientAppActor object at 0x000001709AF0B0D0>)
  File "python\ray\_raylet.pyx", line 1418, in ray._raylet.execute_task
  File "python\ray\_raylet.pyx", line 1498, in ray._raylet.execute_task
  File "python\ray\_raylet.pyx", line 1424, in ray._raylet.execute_task
  File "python\ray\_raylet.pyx", line 1364, in ray._raylet.execute_task.function_executor
  File "C:\Users\jyaka\anaconda3\envs\flower\lib\site-packages\ray\_private\function_manager.py", line 726, in actor_method_executor
    return method(__ray_actor, *args, **kwargs)
  File "C:\Users\jyaka\anaconda3\envs\flower\lib\site-packages\ray\util\tracing\tracing_helper.py", line 464, in _resume_span
    return method(self, *_args, **_kwargs)
  File "C:\Users\jyaka\anaconda3\envs\flower\lib\site-packages\flwr\simulation\ray_transport\ray_actor.py", line 64, in run
    raise ClientAppException(str(ex)) from ex
flwr.client.client_app.ClientAppException: 
Exception ClientAppException occurred. Message: set_parameters() takes 2 positional arguments but 3 were given
[2024-05-11 21:01:30,996][flwr][INFO] - aggregate_evaluate: received 0 results and 2 failures
[2024-05-11 21:01:30,997][flwr][INFO] - 
[2024-05-11 21:01:30,997][flwr][INFO] - [ROUND 2]
[2024-05-11 21:01:30,998][flwr][INFO] - configure_fit: strategy sampled 1 clients (out of 2)
[2024-05-11 21:01:31,010][flwr][ERROR] - Traceback (most recent call last):
  File "C:\Users\jyaka\anaconda3\envs\flower\lib\site-packages\flwr\simulation\ray_transport\ray_client_proxy.py", line 73, in _submit_job
    out_mssg, updated_context = self.actor_pool.get_client_result(
  File "C:\Users\jyaka\anaconda3\envs\flower\lib\site-packages\flwr\simulation\ray_transport\ray_actor.py", line 399, in get_client_result
    return self._fetch_future_result(cid)
  File "C:\Users\jyaka\anaconda3\envs\flower\lib\site-packages\flwr\simulation\ray_transport\ray_actor.py", line 280, in _fetch_future_result
    res_cid, out_mssg, updated_context = ray.get(
  File "C:\Users\jyaka\anaconda3\envs\flower\lib\site-packages\ray\_private\auto_init_hook.py", line 24, in auto_init_wrapper
    return fn(*args, **kwargs)
  File "C:\Users\jyaka\anaconda3\envs\flower\lib\site-packages\ray\_private\client_mode_hook.py", line 103, in wrapper
    return func(*args, **kwargs)
  File "C:\Users\jyaka\anaconda3\envs\flower\lib\site-packages\ray\_private\worker.py", line 2524, in get
    raise value.as_instanceof_cause()
ray.exceptions.RayTaskError(ClientAppException): [36mray::ClientAppActor.run()[39m (pid=9728, ip=127.0.0.1, actor_id=449d6fb233f4c3623911c51301000000, repr=<flwr.simulation.ray_transport.ray_actor.ClientAppActor object at 0x000001709AF0B0D0>)
  File "C:\Users\jyaka\anaconda3\envs\flower\lib\site-packages\flwr\client\client_app.py", line 98, in __call__
    return self._call(message, context)
  File "C:\Users\jyaka\anaconda3\envs\flower\lib\site-packages\flwr\client\client_app.py", line 81, in ffn
    out_message = handle_legacy_message_from_msgtype(
  File "C:\Users\jyaka\anaconda3\envs\flower\lib\site-packages\flwr\client\message_handler\message_handler.py", line 130, in handle_legacy_message_from_msgtype
    fit_res = maybe_call_fit(
  File "C:\Users\jyaka\anaconda3\envs\flower\lib\site-packages\flwr\client\client.py", line 234, in maybe_call_fit
    return client.fit(fit_ins)
  File "C:\Users\jyaka\anaconda3\envs\flower\lib\site-packages\flwr\client\numpy_client.py", line 238, in _fit
    results = self.numpy_client.fit(parameters, ins.config)  # type: ignore
  File "C:\Users\jyaka\Documents\research\flower_tutorial\client.py", line 37, in fit
    epochs = config["epochs"]
KeyError: 'epochs'

The above exception was the direct cause of the following exception:

[36mray::ClientAppActor.run()[39m (pid=9728, ip=127.0.0.1, actor_id=449d6fb233f4c3623911c51301000000, repr=<flwr.simulation.ray_transport.ray_actor.ClientAppActor object at 0x000001709AF0B0D0>)
  File "python\ray\_raylet.pyx", line 1418, in ray._raylet.execute_task
  File "python\ray\_raylet.pyx", line 1498, in ray._raylet.execute_task
  File "python\ray\_raylet.pyx", line 1424, in ray._raylet.execute_task
  File "python\ray\_raylet.pyx", line 1364, in ray._raylet.execute_task.function_executor
  File "C:\Users\jyaka\anaconda3\envs\flower\lib\site-packages\ray\_private\function_manager.py", line 726, in actor_method_executor
    return method(__ray_actor, *args, **kwargs)
  File "C:\Users\jyaka\anaconda3\envs\flower\lib\site-packages\ray\util\tracing\tracing_helper.py", line 464, in _resume_span
    return method(self, *_args, **_kwargs)
  File "C:\Users\jyaka\anaconda3\envs\flower\lib\site-packages\flwr\simulation\ray_transport\ray_actor.py", line 64, in run
    raise ClientAppException(str(ex)) from ex
flwr.client.client_app.ClientAppException: 
Exception ClientAppException occurred. Message: 'epochs'

[2024-05-11 21:01:31,019][flwr][ERROR] - [36mray::ClientAppActor.run()[39m (pid=9728, ip=127.0.0.1, actor_id=449d6fb233f4c3623911c51301000000, repr=<flwr.simulation.ray_transport.ray_actor.ClientAppActor object at 0x000001709AF0B0D0>)
  File "C:\Users\jyaka\anaconda3\envs\flower\lib\site-packages\flwr\client\client_app.py", line 98, in __call__
    return self._call(message, context)
  File "C:\Users\jyaka\anaconda3\envs\flower\lib\site-packages\flwr\client\client_app.py", line 81, in ffn
    out_message = handle_legacy_message_from_msgtype(
  File "C:\Users\jyaka\anaconda3\envs\flower\lib\site-packages\flwr\client\message_handler\message_handler.py", line 130, in handle_legacy_message_from_msgtype
    fit_res = maybe_call_fit(
  File "C:\Users\jyaka\anaconda3\envs\flower\lib\site-packages\flwr\client\client.py", line 234, in maybe_call_fit
    return client.fit(fit_ins)
  File "C:\Users\jyaka\anaconda3\envs\flower\lib\site-packages\flwr\client\numpy_client.py", line 238, in _fit
    results = self.numpy_client.fit(parameters, ins.config)  # type: ignore
  File "C:\Users\jyaka\Documents\research\flower_tutorial\client.py", line 37, in fit
    epochs = config["epochs"]
KeyError: 'epochs'

The above exception was the direct cause of the following exception:

[36mray::ClientAppActor.run()[39m (pid=9728, ip=127.0.0.1, actor_id=449d6fb233f4c3623911c51301000000, repr=<flwr.simulation.ray_transport.ray_actor.ClientAppActor object at 0x000001709AF0B0D0>)
  File "python\ray\_raylet.pyx", line 1418, in ray._raylet.execute_task
  File "python\ray\_raylet.pyx", line 1498, in ray._raylet.execute_task
  File "python\ray\_raylet.pyx", line 1424, in ray._raylet.execute_task
  File "python\ray\_raylet.pyx", line 1364, in ray._raylet.execute_task.function_executor
  File "C:\Users\jyaka\anaconda3\envs\flower\lib\site-packages\ray\_private\function_manager.py", line 726, in actor_method_executor
    return method(__ray_actor, *args, **kwargs)
  File "C:\Users\jyaka\anaconda3\envs\flower\lib\site-packages\ray\util\tracing\tracing_helper.py", line 464, in _resume_span
    return method(self, *_args, **_kwargs)
  File "C:\Users\jyaka\anaconda3\envs\flower\lib\site-packages\flwr\simulation\ray_transport\ray_actor.py", line 64, in run
    raise ClientAppException(str(ex)) from ex
flwr.client.client_app.ClientAppException: 
Exception ClientAppException occurred. Message: 'epochs'
[2024-05-11 21:01:31,024][flwr][INFO] - aggregate_fit: received 0 results and 1 failures
[2024-05-11 21:01:31,025][flwr][INFO] - configure_evaluate: strategy sampled 2 clients (out of 2)
[2024-05-11 21:01:31,037][flwr][ERROR] - Traceback (most recent call last):
  File "C:\Users\jyaka\anaconda3\envs\flower\lib\site-packages\flwr\simulation\ray_transport\ray_client_proxy.py", line 73, in _submit_job
    out_mssg, updated_context = self.actor_pool.get_client_result(
  File "C:\Users\jyaka\anaconda3\envs\flower\lib\site-packages\flwr\simulation\ray_transport\ray_actor.py", line 399, in get_client_result
    return self._fetch_future_result(cid)
  File "C:\Users\jyaka\anaconda3\envs\flower\lib\site-packages\flwr\simulation\ray_transport\ray_actor.py", line 280, in _fetch_future_result
    res_cid, out_mssg, updated_context = ray.get(
  File "C:\Users\jyaka\anaconda3\envs\flower\lib\site-packages\ray\_private\auto_init_hook.py", line 24, in auto_init_wrapper
    return fn(*args, **kwargs)
  File "C:\Users\jyaka\anaconda3\envs\flower\lib\site-packages\ray\_private\client_mode_hook.py", line 103, in wrapper
    return func(*args, **kwargs)
  File "C:\Users\jyaka\anaconda3\envs\flower\lib\site-packages\ray\_private\worker.py", line 2524, in get
    raise value.as_instanceof_cause()
ray.exceptions.RayTaskError(ClientAppException): [36mray::ClientAppActor.run()[39m (pid=9728, ip=127.0.0.1, actor_id=449d6fb233f4c3623911c51301000000, repr=<flwr.simulation.ray_transport.ray_actor.ClientAppActor object at 0x000001709AF0B0D0>)
  File "C:\Users\jyaka\anaconda3\envs\flower\lib\site-packages\flwr\client\client_app.py", line 98, in __call__
    return self._call(message, context)
  File "C:\Users\jyaka\anaconda3\envs\flower\lib\site-packages\flwr\client\client_app.py", line 81, in ffn
    out_message = handle_legacy_message_from_msgtype(
  File "C:\Users\jyaka\anaconda3\envs\flower\lib\site-packages\flwr\client\message_handler\message_handler.py", line 137, in handle_legacy_message_from_msgtype
    evaluate_res = maybe_call_evaluate(
  File "C:\Users\jyaka\anaconda3\envs\flower\lib\site-packages\flwr\client\client.py", line 254, in maybe_call_evaluate
    return client.evaluate(evaluate_ins)
  File "C:\Users\jyaka\anaconda3\envs\flower\lib\site-packages\flwr\client\numpy_client.py", line 262, in _evaluate
    results = self.numpy_client.evaluate(parameters, ins.config)  # type: ignore
  File "C:\Users\jyaka\Documents\research\flower_tutorial\client.py", line 45, in evaluate
    self.set_parameters(self.model, parameters)
TypeError: set_parameters() takes 2 positional arguments but 3 were given

The above exception was the direct cause of the following exception:

[36mray::ClientAppActor.run()[39m (pid=9728, ip=127.0.0.1, actor_id=449d6fb233f4c3623911c51301000000, repr=<flwr.simulation.ray_transport.ray_actor.ClientAppActor object at 0x000001709AF0B0D0>)
  File "python\ray\_raylet.pyx", line 1418, in ray._raylet.execute_task
  File "python\ray\_raylet.pyx", line 1498, in ray._raylet.execute_task
  File "python\ray\_raylet.pyx", line 1424, in ray._raylet.execute_task
  File "python\ray\_raylet.pyx", line 1364, in ray._raylet.execute_task.function_executor
  File "C:\Users\jyaka\anaconda3\envs\flower\lib\site-packages\ray\_private\function_manager.py", line 726, in actor_method_executor
    return method(__ray_actor, *args, **kwargs)
  File "C:\Users\jyaka\anaconda3\envs\flower\lib\site-packages\ray\util\tracing\tracing_helper.py", line 464, in _resume_span
    return method(self, *_args, **_kwargs)
  File "C:\Users\jyaka\anaconda3\envs\flower\lib\site-packages\flwr\simulation\ray_transport\ray_actor.py", line 64, in run
    raise ClientAppException(str(ex)) from ex
flwr.client.client_app.ClientAppException: 
Exception ClientAppException occurred. Message: set_parameters() takes 2 positional arguments but 3 were given

[2024-05-11 21:01:31,040][flwr][ERROR] - Traceback (most recent call last):
  File "C:\Users\jyaka\anaconda3\envs\flower\lib\site-packages\flwr\simulation\ray_transport\ray_client_proxy.py", line 73, in _submit_job
    out_mssg, updated_context = self.actor_pool.get_client_result(
  File "C:\Users\jyaka\anaconda3\envs\flower\lib\site-packages\flwr\simulation\ray_transport\ray_actor.py", line 399, in get_client_result
    return self._fetch_future_result(cid)
  File "C:\Users\jyaka\anaconda3\envs\flower\lib\site-packages\flwr\simulation\ray_transport\ray_actor.py", line 280, in _fetch_future_result
    res_cid, out_mssg, updated_context = ray.get(
  File "C:\Users\jyaka\anaconda3\envs\flower\lib\site-packages\ray\_private\auto_init_hook.py", line 24, in auto_init_wrapper
    return fn(*args, **kwargs)
  File "C:\Users\jyaka\anaconda3\envs\flower\lib\site-packages\ray\_private\client_mode_hook.py", line 103, in wrapper
    return func(*args, **kwargs)
  File "C:\Users\jyaka\anaconda3\envs\flower\lib\site-packages\ray\_private\worker.py", line 2524, in get
    raise value.as_instanceof_cause()
ray.exceptions.RayTaskError(ClientAppException): [36mray::ClientAppActor.run()[39m (pid=24760, ip=127.0.0.1, actor_id=0bda77c27b6b10b0fe356e3b01000000, repr=<flwr.simulation.ray_transport.ray_actor.ClientAppActor object at 0x0000023F214E7160>)
  File "C:\Users\jyaka\anaconda3\envs\flower\lib\site-packages\flwr\client\client_app.py", line 98, in __call__
    return self._call(message, context)
  File "C:\Users\jyaka\anaconda3\envs\flower\lib\site-packages\flwr\client\client_app.py", line 81, in ffn
    out_message = handle_legacy_message_from_msgtype(
  File "C:\Users\jyaka\anaconda3\envs\flower\lib\site-packages\flwr\client\message_handler\message_handler.py", line 137, in handle_legacy_message_from_msgtype
    evaluate_res = maybe_call_evaluate(
  File "C:\Users\jyaka\anaconda3\envs\flower\lib\site-packages\flwr\client\client.py", line 254, in maybe_call_evaluate
    return client.evaluate(evaluate_ins)
  File "C:\Users\jyaka\anaconda3\envs\flower\lib\site-packages\flwr\client\numpy_client.py", line 262, in _evaluate
    results = self.numpy_client.evaluate(parameters, ins.config)  # type: ignore
  File "C:\Users\jyaka\Documents\research\flower_tutorial\client.py", line 45, in evaluate
    self.set_parameters(self.model, parameters)
TypeError: set_parameters() takes 2 positional arguments but 3 were given

The above exception was the direct cause of the following exception:

[36mray::ClientAppActor.run()[39m (pid=24760, ip=127.0.0.1, actor_id=0bda77c27b6b10b0fe356e3b01000000, repr=<flwr.simulation.ray_transport.ray_actor.ClientAppActor object at 0x0000023F214E7160>)
  File "python\ray\_raylet.pyx", line 1418, in ray._raylet.execute_task
  File "python\ray\_raylet.pyx", line 1498, in ray._raylet.execute_task
  File "python\ray\_raylet.pyx", line 1424, in ray._raylet.execute_task
  File "python\ray\_raylet.pyx", line 1364, in ray._raylet.execute_task.function_executor
  File "C:\Users\jyaka\anaconda3\envs\flower\lib\site-packages\ray\_private\function_manager.py", line 726, in actor_method_executor
    return method(__ray_actor, *args, **kwargs)
  File "C:\Users\jyaka\anaconda3\envs\flower\lib\site-packages\ray\util\tracing\tracing_helper.py", line 464, in _resume_span
    return method(self, *_args, **_kwargs)
  File "C:\Users\jyaka\anaconda3\envs\flower\lib\site-packages\flwr\simulation\ray_transport\ray_actor.py", line 64, in run
    raise ClientAppException(str(ex)) from ex
flwr.client.client_app.ClientAppException: 
Exception ClientAppException occurred. Message: set_parameters() takes 2 positional arguments but 3 were given

[2024-05-11 21:01:31,048][flwr][ERROR] - [36mray::ClientAppActor.run()[39m (pid=9728, ip=127.0.0.1, actor_id=449d6fb233f4c3623911c51301000000, repr=<flwr.simulation.ray_transport.ray_actor.ClientAppActor object at 0x000001709AF0B0D0>)
  File "C:\Users\jyaka\anaconda3\envs\flower\lib\site-packages\flwr\client\client_app.py", line 98, in __call__
    return self._call(message, context)
  File "C:\Users\jyaka\anaconda3\envs\flower\lib\site-packages\flwr\client\client_app.py", line 81, in ffn
    out_message = handle_legacy_message_from_msgtype(
  File "C:\Users\jyaka\anaconda3\envs\flower\lib\site-packages\flwr\client\message_handler\message_handler.py", line 137, in handle_legacy_message_from_msgtype
    evaluate_res = maybe_call_evaluate(
  File "C:\Users\jyaka\anaconda3\envs\flower\lib\site-packages\flwr\client\client.py", line 254, in maybe_call_evaluate
    return client.evaluate(evaluate_ins)
  File "C:\Users\jyaka\anaconda3\envs\flower\lib\site-packages\flwr\client\numpy_client.py", line 262, in _evaluate
    results = self.numpy_client.evaluate(parameters, ins.config)  # type: ignore
  File "C:\Users\jyaka\Documents\research\flower_tutorial\client.py", line 45, in evaluate
    self.set_parameters(self.model, parameters)
TypeError: set_parameters() takes 2 positional arguments but 3 were given

The above exception was the direct cause of the following exception:

[36mray::ClientAppActor.run()[39m (pid=9728, ip=127.0.0.1, actor_id=449d6fb233f4c3623911c51301000000, repr=<flwr.simulation.ray_transport.ray_actor.ClientAppActor object at 0x000001709AF0B0D0>)
  File "python\ray\_raylet.pyx", line 1418, in ray._raylet.execute_task
  File "python\ray\_raylet.pyx", line 1498, in ray._raylet.execute_task
  File "python\ray\_raylet.pyx", line 1424, in ray._raylet.execute_task
  File "python\ray\_raylet.pyx", line 1364, in ray._raylet.execute_task.function_executor
  File "C:\Users\jyaka\anaconda3\envs\flower\lib\site-packages\ray\_private\function_manager.py", line 726, in actor_method_executor
    return method(__ray_actor, *args, **kwargs)
  File "C:\Users\jyaka\anaconda3\envs\flower\lib\site-packages\ray\util\tracing\tracing_helper.py", line 464, in _resume_span
    return method(self, *_args, **_kwargs)
  File "C:\Users\jyaka\anaconda3\envs\flower\lib\site-packages\flwr\simulation\ray_transport\ray_actor.py", line 64, in run
    raise ClientAppException(str(ex)) from ex
flwr.client.client_app.ClientAppException: 
Exception ClientAppException occurred. Message: set_parameters() takes 2 positional arguments but 3 were given
[2024-05-11 21:01:31,055][flwr][ERROR] - [36mray::ClientAppActor.run()[39m (pid=24760, ip=127.0.0.1, actor_id=0bda77c27b6b10b0fe356e3b01000000, repr=<flwr.simulation.ray_transport.ray_actor.ClientAppActor object at 0x0000023F214E7160>)
  File "C:\Users\jyaka\anaconda3\envs\flower\lib\site-packages\flwr\client\client_app.py", line 98, in __call__
    return self._call(message, context)
  File "C:\Users\jyaka\anaconda3\envs\flower\lib\site-packages\flwr\client\client_app.py", line 81, in ffn
    out_message = handle_legacy_message_from_msgtype(
  File "C:\Users\jyaka\anaconda3\envs\flower\lib\site-packages\flwr\client\message_handler\message_handler.py", line 137, in handle_legacy_message_from_msgtype
    evaluate_res = maybe_call_evaluate(
  File "C:\Users\jyaka\anaconda3\envs\flower\lib\site-packages\flwr\client\client.py", line 254, in maybe_call_evaluate
    return client.evaluate(evaluate_ins)
  File "C:\Users\jyaka\anaconda3\envs\flower\lib\site-packages\flwr\client\numpy_client.py", line 262, in _evaluate
    results = self.numpy_client.evaluate(parameters, ins.config)  # type: ignore
  File "C:\Users\jyaka\Documents\research\flower_tutorial\client.py", line 45, in evaluate
    self.set_parameters(self.model, parameters)
TypeError: set_parameters() takes 2 positional arguments but 3 were given

The above exception was the direct cause of the following exception:

[36mray::ClientAppActor.run()[39m (pid=24760, ip=127.0.0.1, actor_id=0bda77c27b6b10b0fe356e3b01000000, repr=<flwr.simulation.ray_transport.ray_actor.ClientAppActor object at 0x0000023F214E7160>)
  File "python\ray\_raylet.pyx", line 1418, in ray._raylet.execute_task
  File "python\ray\_raylet.pyx", line 1498, in ray._raylet.execute_task
  File "python\ray\_raylet.pyx", line 1424, in ray._raylet.execute_task
  File "python\ray\_raylet.pyx", line 1364, in ray._raylet.execute_task.function_executor
  File "C:\Users\jyaka\anaconda3\envs\flower\lib\site-packages\ray\_private\function_manager.py", line 726, in actor_method_executor
    return method(__ray_actor, *args, **kwargs)
  File "C:\Users\jyaka\anaconda3\envs\flower\lib\site-packages\ray\util\tracing\tracing_helper.py", line 464, in _resume_span
    return method(self, *_args, **_kwargs)
  File "C:\Users\jyaka\anaconda3\envs\flower\lib\site-packages\flwr\simulation\ray_transport\ray_actor.py", line 64, in run
    raise ClientAppException(str(ex)) from ex
flwr.client.client_app.ClientAppException: 
Exception ClientAppException occurred. Message: set_parameters() takes 2 positional arguments but 3 were given
[2024-05-11 21:01:31,066][flwr][INFO] - aggregate_evaluate: received 0 results and 2 failures
[2024-05-11 21:01:31,067][flwr][INFO] - 
[2024-05-11 21:01:31,067][flwr][INFO] - [ROUND 3]
[2024-05-11 21:01:31,068][flwr][INFO] - configure_fit: strategy sampled 1 clients (out of 2)
[2024-05-11 21:01:31,079][flwr][ERROR] - Traceback (most recent call last):
  File "C:\Users\jyaka\anaconda3\envs\flower\lib\site-packages\flwr\simulation\ray_transport\ray_client_proxy.py", line 73, in _submit_job
    out_mssg, updated_context = self.actor_pool.get_client_result(
  File "C:\Users\jyaka\anaconda3\envs\flower\lib\site-packages\flwr\simulation\ray_transport\ray_actor.py", line 399, in get_client_result
    return self._fetch_future_result(cid)
  File "C:\Users\jyaka\anaconda3\envs\flower\lib\site-packages\flwr\simulation\ray_transport\ray_actor.py", line 280, in _fetch_future_result
    res_cid, out_mssg, updated_context = ray.get(
  File "C:\Users\jyaka\anaconda3\envs\flower\lib\site-packages\ray\_private\auto_init_hook.py", line 24, in auto_init_wrapper
    return fn(*args, **kwargs)
  File "C:\Users\jyaka\anaconda3\envs\flower\lib\site-packages\ray\_private\client_mode_hook.py", line 103, in wrapper
    return func(*args, **kwargs)
  File "C:\Users\jyaka\anaconda3\envs\flower\lib\site-packages\ray\_private\worker.py", line 2524, in get
    raise value.as_instanceof_cause()
ray.exceptions.RayTaskError(ClientAppException): [36mray::ClientAppActor.run()[39m (pid=24760, ip=127.0.0.1, actor_id=0bda77c27b6b10b0fe356e3b01000000, repr=<flwr.simulation.ray_transport.ray_actor.ClientAppActor object at 0x0000023F214E7160>)
  File "C:\Users\jyaka\anaconda3\envs\flower\lib\site-packages\flwr\client\client_app.py", line 98, in __call__
    return self._call(message, context)
  File "C:\Users\jyaka\anaconda3\envs\flower\lib\site-packages\flwr\client\client_app.py", line 81, in ffn
    out_message = handle_legacy_message_from_msgtype(
  File "C:\Users\jyaka\anaconda3\envs\flower\lib\site-packages\flwr\client\message_handler\message_handler.py", line 130, in handle_legacy_message_from_msgtype
    fit_res = maybe_call_fit(
  File "C:\Users\jyaka\anaconda3\envs\flower\lib\site-packages\flwr\client\client.py", line 234, in maybe_call_fit
    return client.fit(fit_ins)
  File "C:\Users\jyaka\anaconda3\envs\flower\lib\site-packages\flwr\client\numpy_client.py", line 238, in _fit
    results = self.numpy_client.fit(parameters, ins.config)  # type: ignore
  File "C:\Users\jyaka\Documents\research\flower_tutorial\client.py", line 37, in fit
    epochs = config["epochs"]
KeyError: 'epochs'

The above exception was the direct cause of the following exception:

[36mray::ClientAppActor.run()[39m (pid=24760, ip=127.0.0.1, actor_id=0bda77c27b6b10b0fe356e3b01000000, repr=<flwr.simulation.ray_transport.ray_actor.ClientAppActor object at 0x0000023F214E7160>)
  File "python\ray\_raylet.pyx", line 1418, in ray._raylet.execute_task
  File "python\ray\_raylet.pyx", line 1498, in ray._raylet.execute_task
  File "python\ray\_raylet.pyx", line 1424, in ray._raylet.execute_task
  File "python\ray\_raylet.pyx", line 1364, in ray._raylet.execute_task.function_executor
  File "C:\Users\jyaka\anaconda3\envs\flower\lib\site-packages\ray\_private\function_manager.py", line 726, in actor_method_executor
    return method(__ray_actor, *args, **kwargs)
  File "C:\Users\jyaka\anaconda3\envs\flower\lib\site-packages\ray\util\tracing\tracing_helper.py", line 464, in _resume_span
    return method(self, *_args, **_kwargs)
  File "C:\Users\jyaka\anaconda3\envs\flower\lib\site-packages\flwr\simulation\ray_transport\ray_actor.py", line 64, in run
    raise ClientAppException(str(ex)) from ex
flwr.client.client_app.ClientAppException: 
Exception ClientAppException occurred. Message: 'epochs'

[2024-05-11 21:01:31,093][flwr][ERROR] - [36mray::ClientAppActor.run()[39m (pid=24760, ip=127.0.0.1, actor_id=0bda77c27b6b10b0fe356e3b01000000, repr=<flwr.simulation.ray_transport.ray_actor.ClientAppActor object at 0x0000023F214E7160>)
  File "C:\Users\jyaka\anaconda3\envs\flower\lib\site-packages\flwr\client\client_app.py", line 98, in __call__
    return self._call(message, context)
  File "C:\Users\jyaka\anaconda3\envs\flower\lib\site-packages\flwr\client\client_app.py", line 81, in ffn
    out_message = handle_legacy_message_from_msgtype(
  File "C:\Users\jyaka\anaconda3\envs\flower\lib\site-packages\flwr\client\message_handler\message_handler.py", line 130, in handle_legacy_message_from_msgtype
    fit_res = maybe_call_fit(
  File "C:\Users\jyaka\anaconda3\envs\flower\lib\site-packages\flwr\client\client.py", line 234, in maybe_call_fit
    return client.fit(fit_ins)
  File "C:\Users\jyaka\anaconda3\envs\flower\lib\site-packages\flwr\client\numpy_client.py", line 238, in _fit
    results = self.numpy_client.fit(parameters, ins.config)  # type: ignore
  File "C:\Users\jyaka\Documents\research\flower_tutorial\client.py", line 37, in fit
    epochs = config["epochs"]
KeyError: 'epochs'

The above exception was the direct cause of the following exception:

[36mray::ClientAppActor.run()[39m (pid=24760, ip=127.0.0.1, actor_id=0bda77c27b6b10b0fe356e3b01000000, repr=<flwr.simulation.ray_transport.ray_actor.ClientAppActor object at 0x0000023F214E7160>)
  File "python\ray\_raylet.pyx", line 1418, in ray._raylet.execute_task
  File "python\ray\_raylet.pyx", line 1498, in ray._raylet.execute_task
  File "python\ray\_raylet.pyx", line 1424, in ray._raylet.execute_task
  File "python\ray\_raylet.pyx", line 1364, in ray._raylet.execute_task.function_executor
  File "C:\Users\jyaka\anaconda3\envs\flower\lib\site-packages\ray\_private\function_manager.py", line 726, in actor_method_executor
    return method(__ray_actor, *args, **kwargs)
  File "C:\Users\jyaka\anaconda3\envs\flower\lib\site-packages\ray\util\tracing\tracing_helper.py", line 464, in _resume_span
    return method(self, *_args, **_kwargs)
  File "C:\Users\jyaka\anaconda3\envs\flower\lib\site-packages\flwr\simulation\ray_transport\ray_actor.py", line 64, in run
    raise ClientAppException(str(ex)) from ex
flwr.client.client_app.ClientAppException: 
Exception ClientAppException occurred. Message: 'epochs'
[2024-05-11 21:01:31,099][flwr][INFO] - aggregate_fit: received 0 results and 1 failures
[2024-05-11 21:01:31,100][flwr][INFO] - configure_evaluate: strategy sampled 2 clients (out of 2)
[2024-05-11 21:01:31,111][flwr][ERROR] - Traceback (most recent call last):
  File "C:\Users\jyaka\anaconda3\envs\flower\lib\site-packages\flwr\simulation\ray_transport\ray_client_proxy.py", line 73, in _submit_job
    out_mssg, updated_context = self.actor_pool.get_client_result(
  File "C:\Users\jyaka\anaconda3\envs\flower\lib\site-packages\flwr\simulation\ray_transport\ray_actor.py", line 399, in get_client_result
    return self._fetch_future_result(cid)
  File "C:\Users\jyaka\anaconda3\envs\flower\lib\site-packages\flwr\simulation\ray_transport\ray_actor.py", line 280, in _fetch_future_result
    res_cid, out_mssg, updated_context = ray.get(
  File "C:\Users\jyaka\anaconda3\envs\flower\lib\site-packages\ray\_private\auto_init_hook.py", line 24, in auto_init_wrapper
    return fn(*args, **kwargs)
  File "C:\Users\jyaka\anaconda3\envs\flower\lib\site-packages\ray\_private\client_mode_hook.py", line 103, in wrapper
    return func(*args, **kwargs)
  File "C:\Users\jyaka\anaconda3\envs\flower\lib\site-packages\ray\_private\worker.py", line 2524, in get
    raise value.as_instanceof_cause()
ray.exceptions.RayTaskError(ClientAppException): [36mray::ClientAppActor.run()[39m (pid=24760, ip=127.0.0.1, actor_id=0bda77c27b6b10b0fe356e3b01000000, repr=<flwr.simulation.ray_transport.ray_actor.ClientAppActor object at 0x0000023F214E7160>)
  File "C:\Users\jyaka\anaconda3\envs\flower\lib\site-packages\flwr\client\client_app.py", line 98, in __call__
    return self._call(message, context)
  File "C:\Users\jyaka\anaconda3\envs\flower\lib\site-packages\flwr\client\client_app.py", line 81, in ffn
    out_message = handle_legacy_message_from_msgtype(
  File "C:\Users\jyaka\anaconda3\envs\flower\lib\site-packages\flwr\client\message_handler\message_handler.py", line 137, in handle_legacy_message_from_msgtype
    evaluate_res = maybe_call_evaluate(
  File "C:\Users\jyaka\anaconda3\envs\flower\lib\site-packages\flwr\client\client.py", line 254, in maybe_call_evaluate
    return client.evaluate(evaluate_ins)
  File "C:\Users\jyaka\anaconda3\envs\flower\lib\site-packages\flwr\client\numpy_client.py", line 262, in _evaluate
    results = self.numpy_client.evaluate(parameters, ins.config)  # type: ignore
  File "C:\Users\jyaka\Documents\research\flower_tutorial\client.py", line 45, in evaluate
    self.set_parameters(self.model, parameters)
TypeError: set_parameters() takes 2 positional arguments but 3 were given

The above exception was the direct cause of the following exception:

[36mray::ClientAppActor.run()[39m (pid=24760, ip=127.0.0.1, actor_id=0bda77c27b6b10b0fe356e3b01000000, repr=<flwr.simulation.ray_transport.ray_actor.ClientAppActor object at 0x0000023F214E7160>)
  File "python\ray\_raylet.pyx", line 1418, in ray._raylet.execute_task
  File "python\ray\_raylet.pyx", line 1498, in ray._raylet.execute_task
  File "python\ray\_raylet.pyx", line 1424, in ray._raylet.execute_task
  File "python\ray\_raylet.pyx", line 1364, in ray._raylet.execute_task.function_executor
  File "C:\Users\jyaka\anaconda3\envs\flower\lib\site-packages\ray\_private\function_manager.py", line 726, in actor_method_executor
    return method(__ray_actor, *args, **kwargs)
  File "C:\Users\jyaka\anaconda3\envs\flower\lib\site-packages\ray\util\tracing\tracing_helper.py", line 464, in _resume_span
    return method(self, *_args, **_kwargs)
  File "C:\Users\jyaka\anaconda3\envs\flower\lib\site-packages\flwr\simulation\ray_transport\ray_actor.py", line 64, in run
    raise ClientAppException(str(ex)) from ex
flwr.client.client_app.ClientAppException: 
Exception ClientAppException occurred. Message: set_parameters() takes 2 positional arguments but 3 were given

[2024-05-11 21:01:31,114][flwr][ERROR] - Traceback (most recent call last):
  File "C:\Users\jyaka\anaconda3\envs\flower\lib\site-packages\flwr\simulation\ray_transport\ray_client_proxy.py", line 73, in _submit_job
    out_mssg, updated_context = self.actor_pool.get_client_result(
  File "C:\Users\jyaka\anaconda3\envs\flower\lib\site-packages\flwr\simulation\ray_transport\ray_actor.py", line 399, in get_client_result
    return self._fetch_future_result(cid)
  File "C:\Users\jyaka\anaconda3\envs\flower\lib\site-packages\flwr\simulation\ray_transport\ray_actor.py", line 280, in _fetch_future_result
    res_cid, out_mssg, updated_context = ray.get(
  File "C:\Users\jyaka\anaconda3\envs\flower\lib\site-packages\ray\_private\auto_init_hook.py", line 24, in auto_init_wrapper
    return fn(*args, **kwargs)
  File "C:\Users\jyaka\anaconda3\envs\flower\lib\site-packages\ray\_private\client_mode_hook.py", line 103, in wrapper
    return func(*args, **kwargs)
  File "C:\Users\jyaka\anaconda3\envs\flower\lib\site-packages\ray\_private\worker.py", line 2524, in get
    raise value.as_instanceof_cause()
ray.exceptions.RayTaskError(ClientAppException): [36mray::ClientAppActor.run()[39m (pid=9728, ip=127.0.0.1, actor_id=449d6fb233f4c3623911c51301000000, repr=<flwr.simulation.ray_transport.ray_actor.ClientAppActor object at 0x000001709AF0B0D0>)
  File "C:\Users\jyaka\anaconda3\envs\flower\lib\site-packages\flwr\client\client_app.py", line 98, in __call__
    return self._call(message, context)
  File "C:\Users\jyaka\anaconda3\envs\flower\lib\site-packages\flwr\client\client_app.py", line 81, in ffn
    out_message = handle_legacy_message_from_msgtype(
  File "C:\Users\jyaka\anaconda3\envs\flower\lib\site-packages\flwr\client\message_handler\message_handler.py", line 137, in handle_legacy_message_from_msgtype
    evaluate_res = maybe_call_evaluate(
  File "C:\Users\jyaka\anaconda3\envs\flower\lib\site-packages\flwr\client\client.py", line 254, in maybe_call_evaluate
    return client.evaluate(evaluate_ins)
  File "C:\Users\jyaka\anaconda3\envs\flower\lib\site-packages\flwr\client\numpy_client.py", line 262, in _evaluate
    results = self.numpy_client.evaluate(parameters, ins.config)  # type: ignore
  File "C:\Users\jyaka\Documents\research\flower_tutorial\client.py", line 45, in evaluate
    self.set_parameters(self.model, parameters)
TypeError: set_parameters() takes 2 positional arguments but 3 were given

The above exception was the direct cause of the following exception:

[36mray::ClientAppActor.run()[39m (pid=9728, ip=127.0.0.1, actor_id=449d6fb233f4c3623911c51301000000, repr=<flwr.simulation.ray_transport.ray_actor.ClientAppActor object at 0x000001709AF0B0D0>)
  File "python\ray\_raylet.pyx", line 1418, in ray._raylet.execute_task
  File "python\ray\_raylet.pyx", line 1498, in ray._raylet.execute_task
  File "python\ray\_raylet.pyx", line 1424, in ray._raylet.execute_task
  File "python\ray\_raylet.pyx", line 1364, in ray._raylet.execute_task.function_executor
  File "C:\Users\jyaka\anaconda3\envs\flower\lib\site-packages\ray\_private\function_manager.py", line 726, in actor_method_executor
    return method(__ray_actor, *args, **kwargs)
  File "C:\Users\jyaka\anaconda3\envs\flower\lib\site-packages\ray\util\tracing\tracing_helper.py", line 464, in _resume_span
    return method(self, *_args, **_kwargs)
  File "C:\Users\jyaka\anaconda3\envs\flower\lib\site-packages\flwr\simulation\ray_transport\ray_actor.py", line 64, in run
    raise ClientAppException(str(ex)) from ex
flwr.client.client_app.ClientAppException: 
Exception ClientAppException occurred. Message: set_parameters() takes 2 positional arguments but 3 were given

[2024-05-11 21:01:31,123][flwr][ERROR] - [36mray::ClientAppActor.run()[39m (pid=24760, ip=127.0.0.1, actor_id=0bda77c27b6b10b0fe356e3b01000000, repr=<flwr.simulation.ray_transport.ray_actor.ClientAppActor object at 0x0000023F214E7160>)
  File "C:\Users\jyaka\anaconda3\envs\flower\lib\site-packages\flwr\client\client_app.py", line 98, in __call__
    return self._call(message, context)
  File "C:\Users\jyaka\anaconda3\envs\flower\lib\site-packages\flwr\client\client_app.py", line 81, in ffn
    out_message = handle_legacy_message_from_msgtype(
  File "C:\Users\jyaka\anaconda3\envs\flower\lib\site-packages\flwr\client\message_handler\message_handler.py", line 137, in handle_legacy_message_from_msgtype
    evaluate_res = maybe_call_evaluate(
  File "C:\Users\jyaka\anaconda3\envs\flower\lib\site-packages\flwr\client\client.py", line 254, in maybe_call_evaluate
    return client.evaluate(evaluate_ins)
  File "C:\Users\jyaka\anaconda3\envs\flower\lib\site-packages\flwr\client\numpy_client.py", line 262, in _evaluate
    results = self.numpy_client.evaluate(parameters, ins.config)  # type: ignore
  File "C:\Users\jyaka\Documents\research\flower_tutorial\client.py", line 45, in evaluate
    self.set_parameters(self.model, parameters)
TypeError: set_parameters() takes 2 positional arguments but 3 were given

The above exception was the direct cause of the following exception:

[36mray::ClientAppActor.run()[39m (pid=24760, ip=127.0.0.1, actor_id=0bda77c27b6b10b0fe356e3b01000000, repr=<flwr.simulation.ray_transport.ray_actor.ClientAppActor object at 0x0000023F214E7160>)
  File "python\ray\_raylet.pyx", line 1418, in ray._raylet.execute_task
  File "python\ray\_raylet.pyx", line 1498, in ray._raylet.execute_task
  File "python\ray\_raylet.pyx", line 1424, in ray._raylet.execute_task
  File "python\ray\_raylet.pyx", line 1364, in ray._raylet.execute_task.function_executor
  File "C:\Users\jyaka\anaconda3\envs\flower\lib\site-packages\ray\_private\function_manager.py", line 726, in actor_method_executor
    return method(__ray_actor, *args, **kwargs)
  File "C:\Users\jyaka\anaconda3\envs\flower\lib\site-packages\ray\util\tracing\tracing_helper.py", line 464, in _resume_span
    return method(self, *_args, **_kwargs)
  File "C:\Users\jyaka\anaconda3\envs\flower\lib\site-packages\flwr\simulation\ray_transport\ray_actor.py", line 64, in run
    raise ClientAppException(str(ex)) from ex
flwr.client.client_app.ClientAppException: 
Exception ClientAppException occurred. Message: set_parameters() takes 2 positional arguments but 3 were given
[2024-05-11 21:01:31,131][flwr][ERROR] - [36mray::ClientAppActor.run()[39m (pid=9728, ip=127.0.0.1, actor_id=449d6fb233f4c3623911c51301000000, repr=<flwr.simulation.ray_transport.ray_actor.ClientAppActor object at 0x000001709AF0B0D0>)
  File "C:\Users\jyaka\anaconda3\envs\flower\lib\site-packages\flwr\client\client_app.py", line 98, in __call__
    return self._call(message, context)
  File "C:\Users\jyaka\anaconda3\envs\flower\lib\site-packages\flwr\client\client_app.py", line 81, in ffn
    out_message = handle_legacy_message_from_msgtype(
  File "C:\Users\jyaka\anaconda3\envs\flower\lib\site-packages\flwr\client\message_handler\message_handler.py", line 137, in handle_legacy_message_from_msgtype
    evaluate_res = maybe_call_evaluate(
  File "C:\Users\jyaka\anaconda3\envs\flower\lib\site-packages\flwr\client\client.py", line 254, in maybe_call_evaluate
    return client.evaluate(evaluate_ins)
  File "C:\Users\jyaka\anaconda3\envs\flower\lib\site-packages\flwr\client\numpy_client.py", line 262, in _evaluate
    results = self.numpy_client.evaluate(parameters, ins.config)  # type: ignore
  File "C:\Users\jyaka\Documents\research\flower_tutorial\client.py", line 45, in evaluate
    self.set_parameters(self.model, parameters)
TypeError: set_parameters() takes 2 positional arguments but 3 were given

The above exception was the direct cause of the following exception:

[36mray::ClientAppActor.run()[39m (pid=9728, ip=127.0.0.1, actor_id=449d6fb233f4c3623911c51301000000, repr=<flwr.simulation.ray_transport.ray_actor.ClientAppActor object at 0x000001709AF0B0D0>)
  File "python\ray\_raylet.pyx", line 1418, in ray._raylet.execute_task
  File "python\ray\_raylet.pyx", line 1498, in ray._raylet.execute_task
  File "python\ray\_raylet.pyx", line 1424, in ray._raylet.execute_task
  File "python\ray\_raylet.pyx", line 1364, in ray._raylet.execute_task.function_executor
  File "C:\Users\jyaka\anaconda3\envs\flower\lib\site-packages\ray\_private\function_manager.py", line 726, in actor_method_executor
    return method(__ray_actor, *args, **kwargs)
  File "C:\Users\jyaka\anaconda3\envs\flower\lib\site-packages\ray\util\tracing\tracing_helper.py", line 464, in _resume_span
    return method(self, *_args, **_kwargs)
  File "C:\Users\jyaka\anaconda3\envs\flower\lib\site-packages\flwr\simulation\ray_transport\ray_actor.py", line 64, in run
    raise ClientAppException(str(ex)) from ex
flwr.client.client_app.ClientAppException: 
Exception ClientAppException occurred. Message: set_parameters() takes 2 positional arguments but 3 were given
[2024-05-11 21:01:31,141][flwr][INFO] - aggregate_evaluate: received 0 results and 2 failures
[2024-05-11 21:01:31,142][flwr][INFO] - 
[2024-05-11 21:01:31,142][flwr][INFO] - [ROUND 4]
[2024-05-11 21:01:31,143][flwr][INFO] - configure_fit: strategy sampled 1 clients (out of 2)
[2024-05-11 21:01:31,155][flwr][ERROR] - Traceback (most recent call last):
  File "C:\Users\jyaka\anaconda3\envs\flower\lib\site-packages\flwr\simulation\ray_transport\ray_client_proxy.py", line 73, in _submit_job
    out_mssg, updated_context = self.actor_pool.get_client_result(
  File "C:\Users\jyaka\anaconda3\envs\flower\lib\site-packages\flwr\simulation\ray_transport\ray_actor.py", line 399, in get_client_result
    return self._fetch_future_result(cid)
  File "C:\Users\jyaka\anaconda3\envs\flower\lib\site-packages\flwr\simulation\ray_transport\ray_actor.py", line 280, in _fetch_future_result
    res_cid, out_mssg, updated_context = ray.get(
  File "C:\Users\jyaka\anaconda3\envs\flower\lib\site-packages\ray\_private\auto_init_hook.py", line 24, in auto_init_wrapper
    return fn(*args, **kwargs)
  File "C:\Users\jyaka\anaconda3\envs\flower\lib\site-packages\ray\_private\client_mode_hook.py", line 103, in wrapper
    return func(*args, **kwargs)
  File "C:\Users\jyaka\anaconda3\envs\flower\lib\site-packages\ray\_private\worker.py", line 2524, in get
    raise value.as_instanceof_cause()
ray.exceptions.RayTaskError(ClientAppException): [36mray::ClientAppActor.run()[39m (pid=9728, ip=127.0.0.1, actor_id=449d6fb233f4c3623911c51301000000, repr=<flwr.simulation.ray_transport.ray_actor.ClientAppActor object at 0x000001709AF0B0D0>)
  File "C:\Users\jyaka\anaconda3\envs\flower\lib\site-packages\flwr\client\client_app.py", line 98, in __call__
    return self._call(message, context)
  File "C:\Users\jyaka\anaconda3\envs\flower\lib\site-packages\flwr\client\client_app.py", line 81, in ffn
    out_message = handle_legacy_message_from_msgtype(
  File "C:\Users\jyaka\anaconda3\envs\flower\lib\site-packages\flwr\client\message_handler\message_handler.py", line 130, in handle_legacy_message_from_msgtype
    fit_res = maybe_call_fit(
  File "C:\Users\jyaka\anaconda3\envs\flower\lib\site-packages\flwr\client\client.py", line 234, in maybe_call_fit
    return client.fit(fit_ins)
  File "C:\Users\jyaka\anaconda3\envs\flower\lib\site-packages\flwr\client\numpy_client.py", line 238, in _fit
    results = self.numpy_client.fit(parameters, ins.config)  # type: ignore
  File "C:\Users\jyaka\Documents\research\flower_tutorial\client.py", line 37, in fit
    epochs = config["epochs"]
KeyError: 'epochs'

The above exception was the direct cause of the following exception:

[36mray::ClientAppActor.run()[39m (pid=9728, ip=127.0.0.1, actor_id=449d6fb233f4c3623911c51301000000, repr=<flwr.simulation.ray_transport.ray_actor.ClientAppActor object at 0x000001709AF0B0D0>)
  File "python\ray\_raylet.pyx", line 1418, in ray._raylet.execute_task
  File "python\ray\_raylet.pyx", line 1498, in ray._raylet.execute_task
  File "python\ray\_raylet.pyx", line 1424, in ray._raylet.execute_task
  File "python\ray\_raylet.pyx", line 1364, in ray._raylet.execute_task.function_executor
  File "C:\Users\jyaka\anaconda3\envs\flower\lib\site-packages\ray\_private\function_manager.py", line 726, in actor_method_executor
    return method(__ray_actor, *args, **kwargs)
  File "C:\Users\jyaka\anaconda3\envs\flower\lib\site-packages\ray\util\tracing\tracing_helper.py", line 464, in _resume_span
    return method(self, *_args, **_kwargs)
  File "C:\Users\jyaka\anaconda3\envs\flower\lib\site-packages\flwr\simulation\ray_transport\ray_actor.py", line 64, in run
    raise ClientAppException(str(ex)) from ex
flwr.client.client_app.ClientAppException: 
Exception ClientAppException occurred. Message: 'epochs'

[2024-05-11 21:01:31,164][flwr][ERROR] - [36mray::ClientAppActor.run()[39m (pid=9728, ip=127.0.0.1, actor_id=449d6fb233f4c3623911c51301000000, repr=<flwr.simulation.ray_transport.ray_actor.ClientAppActor object at 0x000001709AF0B0D0>)
  File "C:\Users\jyaka\anaconda3\envs\flower\lib\site-packages\flwr\client\client_app.py", line 98, in __call__
    return self._call(message, context)
  File "C:\Users\jyaka\anaconda3\envs\flower\lib\site-packages\flwr\client\client_app.py", line 81, in ffn
    out_message = handle_legacy_message_from_msgtype(
  File "C:\Users\jyaka\anaconda3\envs\flower\lib\site-packages\flwr\client\message_handler\message_handler.py", line 130, in handle_legacy_message_from_msgtype
    fit_res = maybe_call_fit(
  File "C:\Users\jyaka\anaconda3\envs\flower\lib\site-packages\flwr\client\client.py", line 234, in maybe_call_fit
    return client.fit(fit_ins)
  File "C:\Users\jyaka\anaconda3\envs\flower\lib\site-packages\flwr\client\numpy_client.py", line 238, in _fit
    results = self.numpy_client.fit(parameters, ins.config)  # type: ignore
  File "C:\Users\jyaka\Documents\research\flower_tutorial\client.py", line 37, in fit
    epochs = config["epochs"]
KeyError: 'epochs'

The above exception was the direct cause of the following exception:

[36mray::ClientAppActor.run()[39m (pid=9728, ip=127.0.0.1, actor_id=449d6fb233f4c3623911c51301000000, repr=<flwr.simulation.ray_transport.ray_actor.ClientAppActor object at 0x000001709AF0B0D0>)
  File "python\ray\_raylet.pyx", line 1418, in ray._raylet.execute_task
  File "python\ray\_raylet.pyx", line 1498, in ray._raylet.execute_task
  File "python\ray\_raylet.pyx", line 1424, in ray._raylet.execute_task
  File "python\ray\_raylet.pyx", line 1364, in ray._raylet.execute_task.function_executor
  File "C:\Users\jyaka\anaconda3\envs\flower\lib\site-packages\ray\_private\function_manager.py", line 726, in actor_method_executor
    return method(__ray_actor, *args, **kwargs)
  File "C:\Users\jyaka\anaconda3\envs\flower\lib\site-packages\ray\util\tracing\tracing_helper.py", line 464, in _resume_span
    return method(self, *_args, **_kwargs)
  File "C:\Users\jyaka\anaconda3\envs\flower\lib\site-packages\flwr\simulation\ray_transport\ray_actor.py", line 64, in run
    raise ClientAppException(str(ex)) from ex
flwr.client.client_app.ClientAppException: 
Exception ClientAppException occurred. Message: 'epochs'
[2024-05-11 21:01:31,170][flwr][INFO] - aggregate_fit: received 0 results and 1 failures
[2024-05-11 21:01:31,171][flwr][INFO] - configure_evaluate: strategy sampled 2 clients (out of 2)
[2024-05-11 21:01:31,182][flwr][ERROR] - Traceback (most recent call last):
  File "C:\Users\jyaka\anaconda3\envs\flower\lib\site-packages\flwr\simulation\ray_transport\ray_client_proxy.py", line 73, in _submit_job
    out_mssg, updated_context = self.actor_pool.get_client_result(
  File "C:\Users\jyaka\anaconda3\envs\flower\lib\site-packages\flwr\simulation\ray_transport\ray_actor.py", line 399, in get_client_result
    return self._fetch_future_result(cid)
  File "C:\Users\jyaka\anaconda3\envs\flower\lib\site-packages\flwr\simulation\ray_transport\ray_actor.py", line 280, in _fetch_future_result
    res_cid, out_mssg, updated_context = ray.get(
  File "C:\Users\jyaka\anaconda3\envs\flower\lib\site-packages\ray\_private\auto_init_hook.py", line 24, in auto_init_wrapper
    return fn(*args, **kwargs)
  File "C:\Users\jyaka\anaconda3\envs\flower\lib\site-packages\ray\_private\client_mode_hook.py", line 103, in wrapper
    return func(*args, **kwargs)
  File "C:\Users\jyaka\anaconda3\envs\flower\lib\site-packages\ray\_private\worker.py", line 2524, in get
    raise value.as_instanceof_cause()
ray.exceptions.RayTaskError(ClientAppException): [36mray::ClientAppActor.run()[39m (pid=9728, ip=127.0.0.1, actor_id=449d6fb233f4c3623911c51301000000, repr=<flwr.simulation.ray_transport.ray_actor.ClientAppActor object at 0x000001709AF0B0D0>)
  File "C:\Users\jyaka\anaconda3\envs\flower\lib\site-packages\flwr\client\client_app.py", line 98, in __call__
    return self._call(message, context)
  File "C:\Users\jyaka\anaconda3\envs\flower\lib\site-packages\flwr\client\client_app.py", line 81, in ffn
    out_message = handle_legacy_message_from_msgtype(
  File "C:\Users\jyaka\anaconda3\envs\flower\lib\site-packages\flwr\client\message_handler\message_handler.py", line 137, in handle_legacy_message_from_msgtype
    evaluate_res = maybe_call_evaluate(
  File "C:\Users\jyaka\anaconda3\envs\flower\lib\site-packages\flwr\client\client.py", line 254, in maybe_call_evaluate
    return client.evaluate(evaluate_ins)
  File "C:\Users\jyaka\anaconda3\envs\flower\lib\site-packages\flwr\client\numpy_client.py", line 262, in _evaluate
    results = self.numpy_client.evaluate(parameters, ins.config)  # type: ignore
  File "C:\Users\jyaka\Documents\research\flower_tutorial\client.py", line 45, in evaluate
    self.set_parameters(self.model, parameters)
TypeError: set_parameters() takes 2 positional arguments but 3 were given

The above exception was the direct cause of the following exception:

[36mray::ClientAppActor.run()[39m (pid=9728, ip=127.0.0.1, actor_id=449d6fb233f4c3623911c51301000000, repr=<flwr.simulation.ray_transport.ray_actor.ClientAppActor object at 0x000001709AF0B0D0>)
  File "python\ray\_raylet.pyx", line 1418, in ray._raylet.execute_task
  File "python\ray\_raylet.pyx", line 1498, in ray._raylet.execute_task
  File "python\ray\_raylet.pyx", line 1424, in ray._raylet.execute_task
  File "python\ray\_raylet.pyx", line 1364, in ray._raylet.execute_task.function_executor
  File "C:\Users\jyaka\anaconda3\envs\flower\lib\site-packages\ray\_private\function_manager.py", line 726, in actor_method_executor
    return method(__ray_actor, *args, **kwargs)
  File "C:\Users\jyaka\anaconda3\envs\flower\lib\site-packages\ray\util\tracing\tracing_helper.py", line 464, in _resume_span
    return method(self, *_args, **_kwargs)
  File "C:\Users\jyaka\anaconda3\envs\flower\lib\site-packages\flwr\simulation\ray_transport\ray_actor.py", line 64, in run
    raise ClientAppException(str(ex)) from ex
flwr.client.client_app.ClientAppException: 
Exception ClientAppException occurred. Message: set_parameters() takes 2 positional arguments but 3 were given

[2024-05-11 21:01:31,184][flwr][ERROR] - Traceback (most recent call last):
  File "C:\Users\jyaka\anaconda3\envs\flower\lib\site-packages\flwr\simulation\ray_transport\ray_client_proxy.py", line 73, in _submit_job
    out_mssg, updated_context = self.actor_pool.get_client_result(
  File "C:\Users\jyaka\anaconda3\envs\flower\lib\site-packages\flwr\simulation\ray_transport\ray_actor.py", line 399, in get_client_result
    return self._fetch_future_result(cid)
  File "C:\Users\jyaka\anaconda3\envs\flower\lib\site-packages\flwr\simulation\ray_transport\ray_actor.py", line 280, in _fetch_future_result
    res_cid, out_mssg, updated_context = ray.get(
  File "C:\Users\jyaka\anaconda3\envs\flower\lib\site-packages\ray\_private\auto_init_hook.py", line 24, in auto_init_wrapper
    return fn(*args, **kwargs)
  File "C:\Users\jyaka\anaconda3\envs\flower\lib\site-packages\ray\_private\client_mode_hook.py", line 103, in wrapper
    return func(*args, **kwargs)
  File "C:\Users\jyaka\anaconda3\envs\flower\lib\site-packages\ray\_private\worker.py", line 2524, in get
    raise value.as_instanceof_cause()
ray.exceptions.RayTaskError(ClientAppException): [36mray::ClientAppActor.run()[39m (pid=24760, ip=127.0.0.1, actor_id=0bda77c27b6b10b0fe356e3b01000000, repr=<flwr.simulation.ray_transport.ray_actor.ClientAppActor object at 0x0000023F214E7160>)
  File "C:\Users\jyaka\anaconda3\envs\flower\lib\site-packages\flwr\client\client_app.py", line 98, in __call__
    return self._call(message, context)
  File "C:\Users\jyaka\anaconda3\envs\flower\lib\site-packages\flwr\client\client_app.py", line 81, in ffn
    out_message = handle_legacy_message_from_msgtype(
  File "C:\Users\jyaka\anaconda3\envs\flower\lib\site-packages\flwr\client\message_handler\message_handler.py", line 137, in handle_legacy_message_from_msgtype
    evaluate_res = maybe_call_evaluate(
  File "C:\Users\jyaka\anaconda3\envs\flower\lib\site-packages\flwr\client\client.py", line 254, in maybe_call_evaluate
    return client.evaluate(evaluate_ins)
  File "C:\Users\jyaka\anaconda3\envs\flower\lib\site-packages\flwr\client\numpy_client.py", line 262, in _evaluate
    results = self.numpy_client.evaluate(parameters, ins.config)  # type: ignore
  File "C:\Users\jyaka\Documents\research\flower_tutorial\client.py", line 45, in evaluate
    self.set_parameters(self.model, parameters)
TypeError: set_parameters() takes 2 positional arguments but 3 were given

The above exception was the direct cause of the following exception:

[36mray::ClientAppActor.run()[39m (pid=24760, ip=127.0.0.1, actor_id=0bda77c27b6b10b0fe356e3b01000000, repr=<flwr.simulation.ray_transport.ray_actor.ClientAppActor object at 0x0000023F214E7160>)
  File "python\ray\_raylet.pyx", line 1418, in ray._raylet.execute_task
  File "python\ray\_raylet.pyx", line 1498, in ray._raylet.execute_task
  File "python\ray\_raylet.pyx", line 1424, in ray._raylet.execute_task
  File "python\ray\_raylet.pyx", line 1364, in ray._raylet.execute_task.function_executor
  File "C:\Users\jyaka\anaconda3\envs\flower\lib\site-packages\ray\_private\function_manager.py", line 726, in actor_method_executor
    return method(__ray_actor, *args, **kwargs)
  File "C:\Users\jyaka\anaconda3\envs\flower\lib\site-packages\ray\util\tracing\tracing_helper.py", line 464, in _resume_span
    return method(self, *_args, **_kwargs)
  File "C:\Users\jyaka\anaconda3\envs\flower\lib\site-packages\flwr\simulation\ray_transport\ray_actor.py", line 64, in run
    raise ClientAppException(str(ex)) from ex
flwr.client.client_app.ClientAppException: 
Exception ClientAppException occurred. Message: set_parameters() takes 2 positional arguments but 3 were given

[2024-05-11 21:01:31,194][flwr][ERROR] - [36mray::ClientAppActor.run()[39m (pid=9728, ip=127.0.0.1, actor_id=449d6fb233f4c3623911c51301000000, repr=<flwr.simulation.ray_transport.ray_actor.ClientAppActor object at 0x000001709AF0B0D0>)
  File "C:\Users\jyaka\anaconda3\envs\flower\lib\site-packages\flwr\client\client_app.py", line 98, in __call__
    return self._call(message, context)
  File "C:\Users\jyaka\anaconda3\envs\flower\lib\site-packages\flwr\client\client_app.py", line 81, in ffn
    out_message = handle_legacy_message_from_msgtype(
  File "C:\Users\jyaka\anaconda3\envs\flower\lib\site-packages\flwr\client\message_handler\message_handler.py", line 137, in handle_legacy_message_from_msgtype
    evaluate_res = maybe_call_evaluate(
  File "C:\Users\jyaka\anaconda3\envs\flower\lib\site-packages\flwr\client\client.py", line 254, in maybe_call_evaluate
    return client.evaluate(evaluate_ins)
  File "C:\Users\jyaka\anaconda3\envs\flower\lib\site-packages\flwr\client\numpy_client.py", line 262, in _evaluate
    results = self.numpy_client.evaluate(parameters, ins.config)  # type: ignore
  File "C:\Users\jyaka\Documents\research\flower_tutorial\client.py", line 45, in evaluate
    self.set_parameters(self.model, parameters)
TypeError: set_parameters() takes 2 positional arguments but 3 were given

The above exception was the direct cause of the following exception:

[36mray::ClientAppActor.run()[39m (pid=9728, ip=127.0.0.1, actor_id=449d6fb233f4c3623911c51301000000, repr=<flwr.simulation.ray_transport.ray_actor.ClientAppActor object at 0x000001709AF0B0D0>)
  File "python\ray\_raylet.pyx", line 1418, in ray._raylet.execute_task
  File "python\ray\_raylet.pyx", line 1498, in ray._raylet.execute_task
  File "python\ray\_raylet.pyx", line 1424, in ray._raylet.execute_task
  File "python\ray\_raylet.pyx", line 1364, in ray._raylet.execute_task.function_executor
  File "C:\Users\jyaka\anaconda3\envs\flower\lib\site-packages\ray\_private\function_manager.py", line 726, in actor_method_executor
    return method(__ray_actor, *args, **kwargs)
  File "C:\Users\jyaka\anaconda3\envs\flower\lib\site-packages\ray\util\tracing\tracing_helper.py", line 464, in _resume_span
    return method(self, *_args, **_kwargs)
  File "C:\Users\jyaka\anaconda3\envs\flower\lib\site-packages\flwr\simulation\ray_transport\ray_actor.py", line 64, in run
    raise ClientAppException(str(ex)) from ex
flwr.client.client_app.ClientAppException: 
Exception ClientAppException occurred. Message: set_parameters() takes 2 positional arguments but 3 were given
[2024-05-11 21:01:31,202][flwr][ERROR] - [36mray::ClientAppActor.run()[39m (pid=24760, ip=127.0.0.1, actor_id=0bda77c27b6b10b0fe356e3b01000000, repr=<flwr.simulation.ray_transport.ray_actor.ClientAppActor object at 0x0000023F214E7160>)
  File "C:\Users\jyaka\anaconda3\envs\flower\lib\site-packages\flwr\client\client_app.py", line 98, in __call__
    return self._call(message, context)
  File "C:\Users\jyaka\anaconda3\envs\flower\lib\site-packages\flwr\client\client_app.py", line 81, in ffn
    out_message = handle_legacy_message_from_msgtype(
  File "C:\Users\jyaka\anaconda3\envs\flower\lib\site-packages\flwr\client\message_handler\message_handler.py", line 137, in handle_legacy_message_from_msgtype
    evaluate_res = maybe_call_evaluate(
  File "C:\Users\jyaka\anaconda3\envs\flower\lib\site-packages\flwr\client\client.py", line 254, in maybe_call_evaluate
    return client.evaluate(evaluate_ins)
  File "C:\Users\jyaka\anaconda3\envs\flower\lib\site-packages\flwr\client\numpy_client.py", line 262, in _evaluate
    results = self.numpy_client.evaluate(parameters, ins.config)  # type: ignore
  File "C:\Users\jyaka\Documents\research\flower_tutorial\client.py", line 45, in evaluate
    self.set_parameters(self.model, parameters)
TypeError: set_parameters() takes 2 positional arguments but 3 were given

The above exception was the direct cause of the following exception:

[36mray::ClientAppActor.run()[39m (pid=24760, ip=127.0.0.1, actor_id=0bda77c27b6b10b0fe356e3b01000000, repr=<flwr.simulation.ray_transport.ray_actor.ClientAppActor object at 0x0000023F214E7160>)
  File "python\ray\_raylet.pyx", line 1418, in ray._raylet.execute_task
  File "python\ray\_raylet.pyx", line 1498, in ray._raylet.execute_task
  File "python\ray\_raylet.pyx", line 1424, in ray._raylet.execute_task
  File "python\ray\_raylet.pyx", line 1364, in ray._raylet.execute_task.function_executor
  File "C:\Users\jyaka\anaconda3\envs\flower\lib\site-packages\ray\_private\function_manager.py", line 726, in actor_method_executor
    return method(__ray_actor, *args, **kwargs)
  File "C:\Users\jyaka\anaconda3\envs\flower\lib\site-packages\ray\util\tracing\tracing_helper.py", line 464, in _resume_span
    return method(self, *_args, **_kwargs)
  File "C:\Users\jyaka\anaconda3\envs\flower\lib\site-packages\flwr\simulation\ray_transport\ray_actor.py", line 64, in run
    raise ClientAppException(str(ex)) from ex
flwr.client.client_app.ClientAppException: 
Exception ClientAppException occurred. Message: set_parameters() takes 2 positional arguments but 3 were given
[2024-05-11 21:01:31,216][flwr][INFO] - aggregate_evaluate: received 0 results and 2 failures
[2024-05-11 21:01:31,217][flwr][INFO] - 
[2024-05-11 21:01:31,217][flwr][INFO] - [ROUND 5]
[2024-05-11 21:01:31,218][flwr][INFO] - configure_fit: strategy sampled 1 clients (out of 2)
[2024-05-11 21:01:31,228][flwr][ERROR] - Traceback (most recent call last):
  File "C:\Users\jyaka\anaconda3\envs\flower\lib\site-packages\flwr\simulation\ray_transport\ray_client_proxy.py", line 73, in _submit_job
    out_mssg, updated_context = self.actor_pool.get_client_result(
  File "C:\Users\jyaka\anaconda3\envs\flower\lib\site-packages\flwr\simulation\ray_transport\ray_actor.py", line 399, in get_client_result
    return self._fetch_future_result(cid)
  File "C:\Users\jyaka\anaconda3\envs\flower\lib\site-packages\flwr\simulation\ray_transport\ray_actor.py", line 280, in _fetch_future_result
    res_cid, out_mssg, updated_context = ray.get(
  File "C:\Users\jyaka\anaconda3\envs\flower\lib\site-packages\ray\_private\auto_init_hook.py", line 24, in auto_init_wrapper
    return fn(*args, **kwargs)
  File "C:\Users\jyaka\anaconda3\envs\flower\lib\site-packages\ray\_private\client_mode_hook.py", line 103, in wrapper
    return func(*args, **kwargs)
  File "C:\Users\jyaka\anaconda3\envs\flower\lib\site-packages\ray\_private\worker.py", line 2524, in get
    raise value.as_instanceof_cause()
ray.exceptions.RayTaskError(ClientAppException): [36mray::ClientAppActor.run()[39m (pid=24760, ip=127.0.0.1, actor_id=0bda77c27b6b10b0fe356e3b01000000, repr=<flwr.simulation.ray_transport.ray_actor.ClientAppActor object at 0x0000023F214E7160>)
  File "C:\Users\jyaka\anaconda3\envs\flower\lib\site-packages\flwr\client\client_app.py", line 98, in __call__
    return self._call(message, context)
  File "C:\Users\jyaka\anaconda3\envs\flower\lib\site-packages\flwr\client\client_app.py", line 81, in ffn
    out_message = handle_legacy_message_from_msgtype(
  File "C:\Users\jyaka\anaconda3\envs\flower\lib\site-packages\flwr\client\message_handler\message_handler.py", line 130, in handle_legacy_message_from_msgtype
    fit_res = maybe_call_fit(
  File "C:\Users\jyaka\anaconda3\envs\flower\lib\site-packages\flwr\client\client.py", line 234, in maybe_call_fit
    return client.fit(fit_ins)
  File "C:\Users\jyaka\anaconda3\envs\flower\lib\site-packages\flwr\client\numpy_client.py", line 238, in _fit
    results = self.numpy_client.fit(parameters, ins.config)  # type: ignore
  File "C:\Users\jyaka\Documents\research\flower_tutorial\client.py", line 37, in fit
    epochs = config["epochs"]
KeyError: 'epochs'

The above exception was the direct cause of the following exception:

[36mray::ClientAppActor.run()[39m (pid=24760, ip=127.0.0.1, actor_id=0bda77c27b6b10b0fe356e3b01000000, repr=<flwr.simulation.ray_transport.ray_actor.ClientAppActor object at 0x0000023F214E7160>)
  File "python\ray\_raylet.pyx", line 1418, in ray._raylet.execute_task
  File "python\ray\_raylet.pyx", line 1498, in ray._raylet.execute_task
  File "python\ray\_raylet.pyx", line 1424, in ray._raylet.execute_task
  File "python\ray\_raylet.pyx", line 1364, in ray._raylet.execute_task.function_executor
  File "C:\Users\jyaka\anaconda3\envs\flower\lib\site-packages\ray\_private\function_manager.py", line 726, in actor_method_executor
    return method(__ray_actor, *args, **kwargs)
  File "C:\Users\jyaka\anaconda3\envs\flower\lib\site-packages\ray\util\tracing\tracing_helper.py", line 464, in _resume_span
    return method(self, *_args, **_kwargs)
  File "C:\Users\jyaka\anaconda3\envs\flower\lib\site-packages\flwr\simulation\ray_transport\ray_actor.py", line 64, in run
    raise ClientAppException(str(ex)) from ex
flwr.client.client_app.ClientAppException: 
Exception ClientAppException occurred. Message: 'epochs'

[2024-05-11 21:01:31,240][flwr][ERROR] - [36mray::ClientAppActor.run()[39m (pid=24760, ip=127.0.0.1, actor_id=0bda77c27b6b10b0fe356e3b01000000, repr=<flwr.simulation.ray_transport.ray_actor.ClientAppActor object at 0x0000023F214E7160>)
  File "C:\Users\jyaka\anaconda3\envs\flower\lib\site-packages\flwr\client\client_app.py", line 98, in __call__
    return self._call(message, context)
  File "C:\Users\jyaka\anaconda3\envs\flower\lib\site-packages\flwr\client\client_app.py", line 81, in ffn
    out_message = handle_legacy_message_from_msgtype(
  File "C:\Users\jyaka\anaconda3\envs\flower\lib\site-packages\flwr\client\message_handler\message_handler.py", line 130, in handle_legacy_message_from_msgtype
    fit_res = maybe_call_fit(
  File "C:\Users\jyaka\anaconda3\envs\flower\lib\site-packages\flwr\client\client.py", line 234, in maybe_call_fit
    return client.fit(fit_ins)
  File "C:\Users\jyaka\anaconda3\envs\flower\lib\site-packages\flwr\client\numpy_client.py", line 238, in _fit
    results = self.numpy_client.fit(parameters, ins.config)  # type: ignore
  File "C:\Users\jyaka\Documents\research\flower_tutorial\client.py", line 37, in fit
    epochs = config["epochs"]
KeyError: 'epochs'

The above exception was the direct cause of the following exception:

[36mray::ClientAppActor.run()[39m (pid=24760, ip=127.0.0.1, actor_id=0bda77c27b6b10b0fe356e3b01000000, repr=<flwr.simulation.ray_transport.ray_actor.ClientAppActor object at 0x0000023F214E7160>)
  File "python\ray\_raylet.pyx", line 1418, in ray._raylet.execute_task
  File "python\ray\_raylet.pyx", line 1498, in ray._raylet.execute_task
  File "python\ray\_raylet.pyx", line 1424, in ray._raylet.execute_task
  File "python\ray\_raylet.pyx", line 1364, in ray._raylet.execute_task.function_executor
  File "C:\Users\jyaka\anaconda3\envs\flower\lib\site-packages\ray\_private\function_manager.py", line 726, in actor_method_executor
    return method(__ray_actor, *args, **kwargs)
  File "C:\Users\jyaka\anaconda3\envs\flower\lib\site-packages\ray\util\tracing\tracing_helper.py", line 464, in _resume_span
    return method(self, *_args, **_kwargs)
  File "C:\Users\jyaka\anaconda3\envs\flower\lib\site-packages\flwr\simulation\ray_transport\ray_actor.py", line 64, in run
    raise ClientAppException(str(ex)) from ex
flwr.client.client_app.ClientAppException: 
Exception ClientAppException occurred. Message: 'epochs'
[2024-05-11 21:01:31,245][flwr][INFO] - aggregate_fit: received 0 results and 1 failures
[2024-05-11 21:01:31,246][flwr][INFO] - configure_evaluate: strategy sampled 2 clients (out of 2)
[2024-05-11 21:01:31,259][flwr][ERROR] - Traceback (most recent call last):
  File "C:\Users\jyaka\anaconda3\envs\flower\lib\site-packages\flwr\simulation\ray_transport\ray_client_proxy.py", line 73, in _submit_job
    out_mssg, updated_context = self.actor_pool.get_client_result(
  File "C:\Users\jyaka\anaconda3\envs\flower\lib\site-packages\flwr\simulation\ray_transport\ray_actor.py", line 399, in get_client_result
    return self._fetch_future_result(cid)
  File "C:\Users\jyaka\anaconda3\envs\flower\lib\site-packages\flwr\simulation\ray_transport\ray_actor.py", line 280, in _fetch_future_result
    res_cid, out_mssg, updated_context = ray.get(
  File "C:\Users\jyaka\anaconda3\envs\flower\lib\site-packages\ray\_private\auto_init_hook.py", line 24, in auto_init_wrapper
    return fn(*args, **kwargs)
  File "C:\Users\jyaka\anaconda3\envs\flower\lib\site-packages\ray\_private\client_mode_hook.py", line 103, in wrapper
    return func(*args, **kwargs)
  File "C:\Users\jyaka\anaconda3\envs\flower\lib\site-packages\ray\_private\worker.py", line 2524, in get
    raise value.as_instanceof_cause()
ray.exceptions.RayTaskError(ClientAppException): [36mray::ClientAppActor.run()[39m (pid=24760, ip=127.0.0.1, actor_id=0bda77c27b6b10b0fe356e3b01000000, repr=<flwr.simulation.ray_transport.ray_actor.ClientAppActor object at 0x0000023F214E7160>)
  File "C:\Users\jyaka\anaconda3\envs\flower\lib\site-packages\flwr\client\client_app.py", line 98, in __call__
    return self._call(message, context)
  File "C:\Users\jyaka\anaconda3\envs\flower\lib\site-packages\flwr\client\client_app.py", line 81, in ffn
    out_message = handle_legacy_message_from_msgtype(
  File "C:\Users\jyaka\anaconda3\envs\flower\lib\site-packages\flwr\client\message_handler\message_handler.py", line 137, in handle_legacy_message_from_msgtype
    evaluate_res = maybe_call_evaluate(
  File "C:\Users\jyaka\anaconda3\envs\flower\lib\site-packages\flwr\client\client.py", line 254, in maybe_call_evaluate
    return client.evaluate(evaluate_ins)
  File "C:\Users\jyaka\anaconda3\envs\flower\lib\site-packages\flwr\client\numpy_client.py", line 262, in _evaluate
    results = self.numpy_client.evaluate(parameters, ins.config)  # type: ignore
  File "C:\Users\jyaka\Documents\research\flower_tutorial\client.py", line 45, in evaluate
    self.set_parameters(self.model, parameters)
TypeError: set_parameters() takes 2 positional arguments but 3 were given

The above exception was the direct cause of the following exception:

[36mray::ClientAppActor.run()[39m (pid=24760, ip=127.0.0.1, actor_id=0bda77c27b6b10b0fe356e3b01000000, repr=<flwr.simulation.ray_transport.ray_actor.ClientAppActor object at 0x0000023F214E7160>)
  File "python\ray\_raylet.pyx", line 1418, in ray._raylet.execute_task
  File "python\ray\_raylet.pyx", line 1498, in ray._raylet.execute_task
  File "python\ray\_raylet.pyx", line 1424, in ray._raylet.execute_task
  File "python\ray\_raylet.pyx", line 1364, in ray._raylet.execute_task.function_executor
  File "C:\Users\jyaka\anaconda3\envs\flower\lib\site-packages\ray\_private\function_manager.py", line 726, in actor_method_executor
    return method(__ray_actor, *args, **kwargs)
  File "C:\Users\jyaka\anaconda3\envs\flower\lib\site-packages\ray\util\tracing\tracing_helper.py", line 464, in _resume_span
    return method(self, *_args, **_kwargs)
  File "C:\Users\jyaka\anaconda3\envs\flower\lib\site-packages\flwr\simulation\ray_transport\ray_actor.py", line 64, in run
    raise ClientAppException(str(ex)) from ex
flwr.client.client_app.ClientAppException: 
Exception ClientAppException occurred. Message: set_parameters() takes 2 positional arguments but 3 were given

[2024-05-11 21:01:31,264][flwr][ERROR] - Traceback (most recent call last):
  File "C:\Users\jyaka\anaconda3\envs\flower\lib\site-packages\flwr\simulation\ray_transport\ray_client_proxy.py", line 73, in _submit_job
    out_mssg, updated_context = self.actor_pool.get_client_result(
  File "C:\Users\jyaka\anaconda3\envs\flower\lib\site-packages\flwr\simulation\ray_transport\ray_actor.py", line 399, in get_client_result
    return self._fetch_future_result(cid)
  File "C:\Users\jyaka\anaconda3\envs\flower\lib\site-packages\flwr\simulation\ray_transport\ray_actor.py", line 280, in _fetch_future_result
    res_cid, out_mssg, updated_context = ray.get(
  File "C:\Users\jyaka\anaconda3\envs\flower\lib\site-packages\ray\_private\auto_init_hook.py", line 24, in auto_init_wrapper
    return fn(*args, **kwargs)
  File "C:\Users\jyaka\anaconda3\envs\flower\lib\site-packages\ray\_private\client_mode_hook.py", line 103, in wrapper
    return func(*args, **kwargs)
  File "C:\Users\jyaka\anaconda3\envs\flower\lib\site-packages\ray\_private\worker.py", line 2524, in get
    raise value.as_instanceof_cause()
ray.exceptions.RayTaskError(ClientAppException): [36mray::ClientAppActor.run()[39m (pid=9728, ip=127.0.0.1, actor_id=449d6fb233f4c3623911c51301000000, repr=<flwr.simulation.ray_transport.ray_actor.ClientAppActor object at 0x000001709AF0B0D0>)
  File "C:\Users\jyaka\anaconda3\envs\flower\lib\site-packages\flwr\client\client_app.py", line 98, in __call__
    return self._call(message, context)
  File "C:\Users\jyaka\anaconda3\envs\flower\lib\site-packages\flwr\client\client_app.py", line 81, in ffn
    out_message = handle_legacy_message_from_msgtype(
  File "C:\Users\jyaka\anaconda3\envs\flower\lib\site-packages\flwr\client\message_handler\message_handler.py", line 137, in handle_legacy_message_from_msgtype
    evaluate_res = maybe_call_evaluate(
  File "C:\Users\jyaka\anaconda3\envs\flower\lib\site-packages\flwr\client\client.py", line 254, in maybe_call_evaluate
    return client.evaluate(evaluate_ins)
  File "C:\Users\jyaka\anaconda3\envs\flower\lib\site-packages\flwr\client\numpy_client.py", line 262, in _evaluate
    results = self.numpy_client.evaluate(parameters, ins.config)  # type: ignore
  File "C:\Users\jyaka\Documents\research\flower_tutorial\client.py", line 45, in evaluate
    self.set_parameters(self.model, parameters)
TypeError: set_parameters() takes 2 positional arguments but 3 were given

The above exception was the direct cause of the following exception:

[36mray::ClientAppActor.run()[39m (pid=9728, ip=127.0.0.1, actor_id=449d6fb233f4c3623911c51301000000, repr=<flwr.simulation.ray_transport.ray_actor.ClientAppActor object at 0x000001709AF0B0D0>)
  File "python\ray\_raylet.pyx", line 1418, in ray._raylet.execute_task
  File "python\ray\_raylet.pyx", line 1498, in ray._raylet.execute_task
  File "python\ray\_raylet.pyx", line 1424, in ray._raylet.execute_task
  File "python\ray\_raylet.pyx", line 1364, in ray._raylet.execute_task.function_executor
  File "C:\Users\jyaka\anaconda3\envs\flower\lib\site-packages\ray\_private\function_manager.py", line 726, in actor_method_executor
    return method(__ray_actor, *args, **kwargs)
  File "C:\Users\jyaka\anaconda3\envs\flower\lib\site-packages\ray\util\tracing\tracing_helper.py", line 464, in _resume_span
    return method(self, *_args, **_kwargs)
  File "C:\Users\jyaka\anaconda3\envs\flower\lib\site-packages\flwr\simulation\ray_transport\ray_actor.py", line 64, in run
    raise ClientAppException(str(ex)) from ex
flwr.client.client_app.ClientAppException: 
Exception ClientAppException occurred. Message: set_parameters() takes 2 positional arguments but 3 were given

[2024-05-11 21:01:31,271][flwr][ERROR] - [36mray::ClientAppActor.run()[39m (pid=24760, ip=127.0.0.1, actor_id=0bda77c27b6b10b0fe356e3b01000000, repr=<flwr.simulation.ray_transport.ray_actor.ClientAppActor object at 0x0000023F214E7160>)
  File "C:\Users\jyaka\anaconda3\envs\flower\lib\site-packages\flwr\client\client_app.py", line 98, in __call__
    return self._call(message, context)
  File "C:\Users\jyaka\anaconda3\envs\flower\lib\site-packages\flwr\client\client_app.py", line 81, in ffn
    out_message = handle_legacy_message_from_msgtype(
  File "C:\Users\jyaka\anaconda3\envs\flower\lib\site-packages\flwr\client\message_handler\message_handler.py", line 137, in handle_legacy_message_from_msgtype
    evaluate_res = maybe_call_evaluate(
  File "C:\Users\jyaka\anaconda3\envs\flower\lib\site-packages\flwr\client\client.py", line 254, in maybe_call_evaluate
    return client.evaluate(evaluate_ins)
  File "C:\Users\jyaka\anaconda3\envs\flower\lib\site-packages\flwr\client\numpy_client.py", line 262, in _evaluate
    results = self.numpy_client.evaluate(parameters, ins.config)  # type: ignore
  File "C:\Users\jyaka\Documents\research\flower_tutorial\client.py", line 45, in evaluate
    self.set_parameters(self.model, parameters)
TypeError: set_parameters() takes 2 positional arguments but 3 were given

The above exception was the direct cause of the following exception:

[36mray::ClientAppActor.run()[39m (pid=24760, ip=127.0.0.1, actor_id=0bda77c27b6b10b0fe356e3b01000000, repr=<flwr.simulation.ray_transport.ray_actor.ClientAppActor object at 0x0000023F214E7160>)
  File "python\ray\_raylet.pyx", line 1418, in ray._raylet.execute_task
  File "python\ray\_raylet.pyx", line 1498, in ray._raylet.execute_task
  File "python\ray\_raylet.pyx", line 1424, in ray._raylet.execute_task
  File "python\ray\_raylet.pyx", line 1364, in ray._raylet.execute_task.function_executor
  File "C:\Users\jyaka\anaconda3\envs\flower\lib\site-packages\ray\_private\function_manager.py", line 726, in actor_method_executor
    return method(__ray_actor, *args, **kwargs)
  File "C:\Users\jyaka\anaconda3\envs\flower\lib\site-packages\ray\util\tracing\tracing_helper.py", line 464, in _resume_span
    return method(self, *_args, **_kwargs)
  File "C:\Users\jyaka\anaconda3\envs\flower\lib\site-packages\flwr\simulation\ray_transport\ray_actor.py", line 64, in run
    raise ClientAppException(str(ex)) from ex
flwr.client.client_app.ClientAppException: 
Exception ClientAppException occurred. Message: set_parameters() takes 2 positional arguments but 3 were given
[2024-05-11 21:01:31,280][flwr][ERROR] - [36mray::ClientAppActor.run()[39m (pid=9728, ip=127.0.0.1, actor_id=449d6fb233f4c3623911c51301000000, repr=<flwr.simulation.ray_transport.ray_actor.ClientAppActor object at 0x000001709AF0B0D0>)
  File "C:\Users\jyaka\anaconda3\envs\flower\lib\site-packages\flwr\client\client_app.py", line 98, in __call__
    return self._call(message, context)
  File "C:\Users\jyaka\anaconda3\envs\flower\lib\site-packages\flwr\client\client_app.py", line 81, in ffn
    out_message = handle_legacy_message_from_msgtype(
  File "C:\Users\jyaka\anaconda3\envs\flower\lib\site-packages\flwr\client\message_handler\message_handler.py", line 137, in handle_legacy_message_from_msgtype
    evaluate_res = maybe_call_evaluate(
  File "C:\Users\jyaka\anaconda3\envs\flower\lib\site-packages\flwr\client\client.py", line 254, in maybe_call_evaluate
    return client.evaluate(evaluate_ins)
  File "C:\Users\jyaka\anaconda3\envs\flower\lib\site-packages\flwr\client\numpy_client.py", line 262, in _evaluate
    results = self.numpy_client.evaluate(parameters, ins.config)  # type: ignore
  File "C:\Users\jyaka\Documents\research\flower_tutorial\client.py", line 45, in evaluate
    self.set_parameters(self.model, parameters)
TypeError: set_parameters() takes 2 positional arguments but 3 were given

The above exception was the direct cause of the following exception:

[36mray::ClientAppActor.run()[39m (pid=9728, ip=127.0.0.1, actor_id=449d6fb233f4c3623911c51301000000, repr=<flwr.simulation.ray_transport.ray_actor.ClientAppActor object at 0x000001709AF0B0D0>)
  File "python\ray\_raylet.pyx", line 1418, in ray._raylet.execute_task
  File "python\ray\_raylet.pyx", line 1498, in ray._raylet.execute_task
  File "python\ray\_raylet.pyx", line 1424, in ray._raylet.execute_task
  File "python\ray\_raylet.pyx", line 1364, in ray._raylet.execute_task.function_executor
  File "C:\Users\jyaka\anaconda3\envs\flower\lib\site-packages\ray\_private\function_manager.py", line 726, in actor_method_executor
    return method(__ray_actor, *args, **kwargs)
  File "C:\Users\jyaka\anaconda3\envs\flower\lib\site-packages\ray\util\tracing\tracing_helper.py", line 464, in _resume_span
    return method(self, *_args, **_kwargs)
  File "C:\Users\jyaka\anaconda3\envs\flower\lib\site-packages\flwr\simulation\ray_transport\ray_actor.py", line 64, in run
    raise ClientAppException(str(ex)) from ex
flwr.client.client_app.ClientAppException: 
Exception ClientAppException occurred. Message: set_parameters() takes 2 positional arguments but 3 were given
[2024-05-11 21:01:31,290][flwr][INFO] - aggregate_evaluate: received 0 results and 2 failures
[2024-05-11 21:01:31,291][flwr][INFO] - 
[2024-05-11 21:01:31,291][flwr][INFO] - [ROUND 6]
[2024-05-11 21:01:31,292][flwr][INFO] - configure_fit: strategy sampled 1 clients (out of 2)
[2024-05-11 21:01:31,303][flwr][ERROR] - Traceback (most recent call last):
  File "C:\Users\jyaka\anaconda3\envs\flower\lib\site-packages\flwr\simulation\ray_transport\ray_client_proxy.py", line 73, in _submit_job
    out_mssg, updated_context = self.actor_pool.get_client_result(
  File "C:\Users\jyaka\anaconda3\envs\flower\lib\site-packages\flwr\simulation\ray_transport\ray_actor.py", line 399, in get_client_result
    return self._fetch_future_result(cid)
  File "C:\Users\jyaka\anaconda3\envs\flower\lib\site-packages\flwr\simulation\ray_transport\ray_actor.py", line 280, in _fetch_future_result
    res_cid, out_mssg, updated_context = ray.get(
  File "C:\Users\jyaka\anaconda3\envs\flower\lib\site-packages\ray\_private\auto_init_hook.py", line 24, in auto_init_wrapper
    return fn(*args, **kwargs)
  File "C:\Users\jyaka\anaconda3\envs\flower\lib\site-packages\ray\_private\client_mode_hook.py", line 103, in wrapper
    return func(*args, **kwargs)
  File "C:\Users\jyaka\anaconda3\envs\flower\lib\site-packages\ray\_private\worker.py", line 2524, in get
    raise value.as_instanceof_cause()
ray.exceptions.RayTaskError(ClientAppException): [36mray::ClientAppActor.run()[39m (pid=9728, ip=127.0.0.1, actor_id=449d6fb233f4c3623911c51301000000, repr=<flwr.simulation.ray_transport.ray_actor.ClientAppActor object at 0x000001709AF0B0D0>)
  File "C:\Users\jyaka\anaconda3\envs\flower\lib\site-packages\flwr\client\client_app.py", line 98, in __call__
    return self._call(message, context)
  File "C:\Users\jyaka\anaconda3\envs\flower\lib\site-packages\flwr\client\client_app.py", line 81, in ffn
    out_message = handle_legacy_message_from_msgtype(
  File "C:\Users\jyaka\anaconda3\envs\flower\lib\site-packages\flwr\client\message_handler\message_handler.py", line 130, in handle_legacy_message_from_msgtype
    fit_res = maybe_call_fit(
  File "C:\Users\jyaka\anaconda3\envs\flower\lib\site-packages\flwr\client\client.py", line 234, in maybe_call_fit
    return client.fit(fit_ins)
  File "C:\Users\jyaka\anaconda3\envs\flower\lib\site-packages\flwr\client\numpy_client.py", line 238, in _fit
    results = self.numpy_client.fit(parameters, ins.config)  # type: ignore
  File "C:\Users\jyaka\Documents\research\flower_tutorial\client.py", line 37, in fit
    epochs = config["epochs"]
KeyError: 'epochs'

The above exception was the direct cause of the following exception:

[36mray::ClientAppActor.run()[39m (pid=9728, ip=127.0.0.1, actor_id=449d6fb233f4c3623911c51301000000, repr=<flwr.simulation.ray_transport.ray_actor.ClientAppActor object at 0x000001709AF0B0D0>)
  File "python\ray\_raylet.pyx", line 1418, in ray._raylet.execute_task
  File "python\ray\_raylet.pyx", line 1498, in ray._raylet.execute_task
  File "python\ray\_raylet.pyx", line 1424, in ray._raylet.execute_task
  File "python\ray\_raylet.pyx", line 1364, in ray._raylet.execute_task.function_executor
  File "C:\Users\jyaka\anaconda3\envs\flower\lib\site-packages\ray\_private\function_manager.py", line 726, in actor_method_executor
    return method(__ray_actor, *args, **kwargs)
  File "C:\Users\jyaka\anaconda3\envs\flower\lib\site-packages\ray\util\tracing\tracing_helper.py", line 464, in _resume_span
    return method(self, *_args, **_kwargs)
  File "C:\Users\jyaka\anaconda3\envs\flower\lib\site-packages\flwr\simulation\ray_transport\ray_actor.py", line 64, in run
    raise ClientAppException(str(ex)) from ex
flwr.client.client_app.ClientAppException: 
Exception ClientAppException occurred. Message: 'epochs'

[2024-05-11 21:01:31,313][flwr][ERROR] - [36mray::ClientAppActor.run()[39m (pid=9728, ip=127.0.0.1, actor_id=449d6fb233f4c3623911c51301000000, repr=<flwr.simulation.ray_transport.ray_actor.ClientAppActor object at 0x000001709AF0B0D0>)
  File "C:\Users\jyaka\anaconda3\envs\flower\lib\site-packages\flwr\client\client_app.py", line 98, in __call__
    return self._call(message, context)
  File "C:\Users\jyaka\anaconda3\envs\flower\lib\site-packages\flwr\client\client_app.py", line 81, in ffn
    out_message = handle_legacy_message_from_msgtype(
  File "C:\Users\jyaka\anaconda3\envs\flower\lib\site-packages\flwr\client\message_handler\message_handler.py", line 130, in handle_legacy_message_from_msgtype
    fit_res = maybe_call_fit(
  File "C:\Users\jyaka\anaconda3\envs\flower\lib\site-packages\flwr\client\client.py", line 234, in maybe_call_fit
    return client.fit(fit_ins)
  File "C:\Users\jyaka\anaconda3\envs\flower\lib\site-packages\flwr\client\numpy_client.py", line 238, in _fit
    results = self.numpy_client.fit(parameters, ins.config)  # type: ignore
  File "C:\Users\jyaka\Documents\research\flower_tutorial\client.py", line 37, in fit
    epochs = config["epochs"]
KeyError: 'epochs'

The above exception was the direct cause of the following exception:

[36mray::ClientAppActor.run()[39m (pid=9728, ip=127.0.0.1, actor_id=449d6fb233f4c3623911c51301000000, repr=<flwr.simulation.ray_transport.ray_actor.ClientAppActor object at 0x000001709AF0B0D0>)
  File "python\ray\_raylet.pyx", line 1418, in ray._raylet.execute_task
  File "python\ray\_raylet.pyx", line 1498, in ray._raylet.execute_task
  File "python\ray\_raylet.pyx", line 1424, in ray._raylet.execute_task
  File "python\ray\_raylet.pyx", line 1364, in ray._raylet.execute_task.function_executor
  File "C:\Users\jyaka\anaconda3\envs\flower\lib\site-packages\ray\_private\function_manager.py", line 726, in actor_method_executor
    return method(__ray_actor, *args, **kwargs)
  File "C:\Users\jyaka\anaconda3\envs\flower\lib\site-packages\ray\util\tracing\tracing_helper.py", line 464, in _resume_span
    return method(self, *_args, **_kwargs)
  File "C:\Users\jyaka\anaconda3\envs\flower\lib\site-packages\flwr\simulation\ray_transport\ray_actor.py", line 64, in run
    raise ClientAppException(str(ex)) from ex
flwr.client.client_app.ClientAppException: 
Exception ClientAppException occurred. Message: 'epochs'
[2024-05-11 21:01:31,318][flwr][INFO] - aggregate_fit: received 0 results and 1 failures
[2024-05-11 21:01:31,319][flwr][INFO] - configure_evaluate: strategy sampled 2 clients (out of 2)
[2024-05-11 21:01:31,331][flwr][ERROR] - Traceback (most recent call last):
  File "C:\Users\jyaka\anaconda3\envs\flower\lib\site-packages\flwr\simulation\ray_transport\ray_client_proxy.py", line 73, in _submit_job
    out_mssg, updated_context = self.actor_pool.get_client_result(
  File "C:\Users\jyaka\anaconda3\envs\flower\lib\site-packages\flwr\simulation\ray_transport\ray_actor.py", line 399, in get_client_result
    return self._fetch_future_result(cid)
  File "C:\Users\jyaka\anaconda3\envs\flower\lib\site-packages\flwr\simulation\ray_transport\ray_actor.py", line 280, in _fetch_future_result
    res_cid, out_mssg, updated_context = ray.get(
  File "C:\Users\jyaka\anaconda3\envs\flower\lib\site-packages\ray\_private\auto_init_hook.py", line 24, in auto_init_wrapper
    return fn(*args, **kwargs)
  File "C:\Users\jyaka\anaconda3\envs\flower\lib\site-packages\ray\_private\client_mode_hook.py", line 103, in wrapper
    return func(*args, **kwargs)
  File "C:\Users\jyaka\anaconda3\envs\flower\lib\site-packages\ray\_private\worker.py", line 2524, in get
    raise value.as_instanceof_cause()
ray.exceptions.RayTaskError(ClientAppException): [36mray::ClientAppActor.run()[39m (pid=9728, ip=127.0.0.1, actor_id=449d6fb233f4c3623911c51301000000, repr=<flwr.simulation.ray_transport.ray_actor.ClientAppActor object at 0x000001709AF0B0D0>)
  File "C:\Users\jyaka\anaconda3\envs\flower\lib\site-packages\flwr\client\client_app.py", line 98, in __call__
    return self._call(message, context)
  File "C:\Users\jyaka\anaconda3\envs\flower\lib\site-packages\flwr\client\client_app.py", line 81, in ffn
    out_message = handle_legacy_message_from_msgtype(
  File "C:\Users\jyaka\anaconda3\envs\flower\lib\site-packages\flwr\client\message_handler\message_handler.py", line 137, in handle_legacy_message_from_msgtype
    evaluate_res = maybe_call_evaluate(
  File "C:\Users\jyaka\anaconda3\envs\flower\lib\site-packages\flwr\client\client.py", line 254, in maybe_call_evaluate
    return client.evaluate(evaluate_ins)
  File "C:\Users\jyaka\anaconda3\envs\flower\lib\site-packages\flwr\client\numpy_client.py", line 262, in _evaluate
    results = self.numpy_client.evaluate(parameters, ins.config)  # type: ignore
  File "C:\Users\jyaka\Documents\research\flower_tutorial\client.py", line 45, in evaluate
    self.set_parameters(self.model, parameters)
TypeError: set_parameters() takes 2 positional arguments but 3 were given

The above exception was the direct cause of the following exception:

[36mray::ClientAppActor.run()[39m (pid=9728, ip=127.0.0.1, actor_id=449d6fb233f4c3623911c51301000000, repr=<flwr.simulation.ray_transport.ray_actor.ClientAppActor object at 0x000001709AF0B0D0>)
  File "python\ray\_raylet.pyx", line 1418, in ray._raylet.execute_task
  File "python\ray\_raylet.pyx", line 1498, in ray._raylet.execute_task
  File "python\ray\_raylet.pyx", line 1424, in ray._raylet.execute_task
  File "python\ray\_raylet.pyx", line 1364, in ray._raylet.execute_task.function_executor
  File "C:\Users\jyaka\anaconda3\envs\flower\lib\site-packages\ray\_private\function_manager.py", line 726, in actor_method_executor
    return method(__ray_actor, *args, **kwargs)
  File "C:\Users\jyaka\anaconda3\envs\flower\lib\site-packages\ray\util\tracing\tracing_helper.py", line 464, in _resume_span
    return method(self, *_args, **_kwargs)
  File "C:\Users\jyaka\anaconda3\envs\flower\lib\site-packages\flwr\simulation\ray_transport\ray_actor.py", line 64, in run
    raise ClientAppException(str(ex)) from ex
flwr.client.client_app.ClientAppException: 
Exception ClientAppException occurred. Message: set_parameters() takes 2 positional arguments but 3 were given

[2024-05-11 21:01:31,333][flwr][ERROR] - Traceback (most recent call last):
  File "C:\Users\jyaka\anaconda3\envs\flower\lib\site-packages\flwr\simulation\ray_transport\ray_client_proxy.py", line 73, in _submit_job
    out_mssg, updated_context = self.actor_pool.get_client_result(
  File "C:\Users\jyaka\anaconda3\envs\flower\lib\site-packages\flwr\simulation\ray_transport\ray_actor.py", line 399, in get_client_result
    return self._fetch_future_result(cid)
  File "C:\Users\jyaka\anaconda3\envs\flower\lib\site-packages\flwr\simulation\ray_transport\ray_actor.py", line 280, in _fetch_future_result
    res_cid, out_mssg, updated_context = ray.get(
  File "C:\Users\jyaka\anaconda3\envs\flower\lib\site-packages\ray\_private\auto_init_hook.py", line 24, in auto_init_wrapper
    return fn(*args, **kwargs)
  File "C:\Users\jyaka\anaconda3\envs\flower\lib\site-packages\ray\_private\client_mode_hook.py", line 103, in wrapper
    return func(*args, **kwargs)
  File "C:\Users\jyaka\anaconda3\envs\flower\lib\site-packages\ray\_private\worker.py", line 2524, in get
    raise value.as_instanceof_cause()
ray.exceptions.RayTaskError(ClientAppException): [36mray::ClientAppActor.run()[39m (pid=24760, ip=127.0.0.1, actor_id=0bda77c27b6b10b0fe356e3b01000000, repr=<flwr.simulation.ray_transport.ray_actor.ClientAppActor object at 0x0000023F214E7160>)
  File "C:\Users\jyaka\anaconda3\envs\flower\lib\site-packages\flwr\client\client_app.py", line 98, in __call__
    return self._call(message, context)
  File "C:\Users\jyaka\anaconda3\envs\flower\lib\site-packages\flwr\client\client_app.py", line 81, in ffn
    out_message = handle_legacy_message_from_msgtype(
  File "C:\Users\jyaka\anaconda3\envs\flower\lib\site-packages\flwr\client\message_handler\message_handler.py", line 137, in handle_legacy_message_from_msgtype
    evaluate_res = maybe_call_evaluate(
  File "C:\Users\jyaka\anaconda3\envs\flower\lib\site-packages\flwr\client\client.py", line 254, in maybe_call_evaluate
    return client.evaluate(evaluate_ins)
  File "C:\Users\jyaka\anaconda3\envs\flower\lib\site-packages\flwr\client\numpy_client.py", line 262, in _evaluate
    results = self.numpy_client.evaluate(parameters, ins.config)  # type: ignore
  File "C:\Users\jyaka\Documents\research\flower_tutorial\client.py", line 45, in evaluate
    self.set_parameters(self.model, parameters)
TypeError: set_parameters() takes 2 positional arguments but 3 were given

The above exception was the direct cause of the following exception:

[36mray::ClientAppActor.run()[39m (pid=24760, ip=127.0.0.1, actor_id=0bda77c27b6b10b0fe356e3b01000000, repr=<flwr.simulation.ray_transport.ray_actor.ClientAppActor object at 0x0000023F214E7160>)
  File "python\ray\_raylet.pyx", line 1418, in ray._raylet.execute_task
  File "python\ray\_raylet.pyx", line 1498, in ray._raylet.execute_task
  File "python\ray\_raylet.pyx", line 1424, in ray._raylet.execute_task
  File "python\ray\_raylet.pyx", line 1364, in ray._raylet.execute_task.function_executor
  File "C:\Users\jyaka\anaconda3\envs\flower\lib\site-packages\ray\_private\function_manager.py", line 726, in actor_method_executor
    return method(__ray_actor, *args, **kwargs)
  File "C:\Users\jyaka\anaconda3\envs\flower\lib\site-packages\ray\util\tracing\tracing_helper.py", line 464, in _resume_span
    return method(self, *_args, **_kwargs)
  File "C:\Users\jyaka\anaconda3\envs\flower\lib\site-packages\flwr\simulation\ray_transport\ray_actor.py", line 64, in run
    raise ClientAppException(str(ex)) from ex
flwr.client.client_app.ClientAppException: 
Exception ClientAppException occurred. Message: set_parameters() takes 2 positional arguments but 3 were given

[2024-05-11 21:01:31,343][flwr][ERROR] - [36mray::ClientAppActor.run()[39m (pid=9728, ip=127.0.0.1, actor_id=449d6fb233f4c3623911c51301000000, repr=<flwr.simulation.ray_transport.ray_actor.ClientAppActor object at 0x000001709AF0B0D0>)
  File "C:\Users\jyaka\anaconda3\envs\flower\lib\site-packages\flwr\client\client_app.py", line 98, in __call__
    return self._call(message, context)
  File "C:\Users\jyaka\anaconda3\envs\flower\lib\site-packages\flwr\client\client_app.py", line 81, in ffn
    out_message = handle_legacy_message_from_msgtype(
  File "C:\Users\jyaka\anaconda3\envs\flower\lib\site-packages\flwr\client\message_handler\message_handler.py", line 137, in handle_legacy_message_from_msgtype
    evaluate_res = maybe_call_evaluate(
  File "C:\Users\jyaka\anaconda3\envs\flower\lib\site-packages\flwr\client\client.py", line 254, in maybe_call_evaluate
    return client.evaluate(evaluate_ins)
  File "C:\Users\jyaka\anaconda3\envs\flower\lib\site-packages\flwr\client\numpy_client.py", line 262, in _evaluate
    results = self.numpy_client.evaluate(parameters, ins.config)  # type: ignore
  File "C:\Users\jyaka\Documents\research\flower_tutorial\client.py", line 45, in evaluate
    self.set_parameters(self.model, parameters)
TypeError: set_parameters() takes 2 positional arguments but 3 were given

The above exception was the direct cause of the following exception:

[36mray::ClientAppActor.run()[39m (pid=9728, ip=127.0.0.1, actor_id=449d6fb233f4c3623911c51301000000, repr=<flwr.simulation.ray_transport.ray_actor.ClientAppActor object at 0x000001709AF0B0D0>)
  File "python\ray\_raylet.pyx", line 1418, in ray._raylet.execute_task
  File "python\ray\_raylet.pyx", line 1498, in ray._raylet.execute_task
  File "python\ray\_raylet.pyx", line 1424, in ray._raylet.execute_task
  File "python\ray\_raylet.pyx", line 1364, in ray._raylet.execute_task.function_executor
  File "C:\Users\jyaka\anaconda3\envs\flower\lib\site-packages\ray\_private\function_manager.py", line 726, in actor_method_executor
    return method(__ray_actor, *args, **kwargs)
  File "C:\Users\jyaka\anaconda3\envs\flower\lib\site-packages\ray\util\tracing\tracing_helper.py", line 464, in _resume_span
    return method(self, *_args, **_kwargs)
  File "C:\Users\jyaka\anaconda3\envs\flower\lib\site-packages\flwr\simulation\ray_transport\ray_actor.py", line 64, in run
    raise ClientAppException(str(ex)) from ex
flwr.client.client_app.ClientAppException: 
Exception ClientAppException occurred. Message: set_parameters() takes 2 positional arguments but 3 were given
[2024-05-11 21:01:31,353][flwr][ERROR] - [36mray::ClientAppActor.run()[39m (pid=24760, ip=127.0.0.1, actor_id=0bda77c27b6b10b0fe356e3b01000000, repr=<flwr.simulation.ray_transport.ray_actor.ClientAppActor object at 0x0000023F214E7160>)
  File "C:\Users\jyaka\anaconda3\envs\flower\lib\site-packages\flwr\client\client_app.py", line 98, in __call__
    return self._call(message, context)
  File "C:\Users\jyaka\anaconda3\envs\flower\lib\site-packages\flwr\client\client_app.py", line 81, in ffn
    out_message = handle_legacy_message_from_msgtype(
  File "C:\Users\jyaka\anaconda3\envs\flower\lib\site-packages\flwr\client\message_handler\message_handler.py", line 137, in handle_legacy_message_from_msgtype
    evaluate_res = maybe_call_evaluate(
  File "C:\Users\jyaka\anaconda3\envs\flower\lib\site-packages\flwr\client\client.py", line 254, in maybe_call_evaluate
    return client.evaluate(evaluate_ins)
  File "C:\Users\jyaka\anaconda3\envs\flower\lib\site-packages\flwr\client\numpy_client.py", line 262, in _evaluate
    results = self.numpy_client.evaluate(parameters, ins.config)  # type: ignore
  File "C:\Users\jyaka\Documents\research\flower_tutorial\client.py", line 45, in evaluate
    self.set_parameters(self.model, parameters)
TypeError: set_parameters() takes 2 positional arguments but 3 were given

The above exception was the direct cause of the following exception:

[36mray::ClientAppActor.run()[39m (pid=24760, ip=127.0.0.1, actor_id=0bda77c27b6b10b0fe356e3b01000000, repr=<flwr.simulation.ray_transport.ray_actor.ClientAppActor object at 0x0000023F214E7160>)
  File "python\ray\_raylet.pyx", line 1418, in ray._raylet.execute_task
  File "python\ray\_raylet.pyx", line 1498, in ray._raylet.execute_task
  File "python\ray\_raylet.pyx", line 1424, in ray._raylet.execute_task
  File "python\ray\_raylet.pyx", line 1364, in ray._raylet.execute_task.function_executor
  File "C:\Users\jyaka\anaconda3\envs\flower\lib\site-packages\ray\_private\function_manager.py", line 726, in actor_method_executor
    return method(__ray_actor, *args, **kwargs)
  File "C:\Users\jyaka\anaconda3\envs\flower\lib\site-packages\ray\util\tracing\tracing_helper.py", line 464, in _resume_span
    return method(self, *_args, **_kwargs)
  File "C:\Users\jyaka\anaconda3\envs\flower\lib\site-packages\flwr\simulation\ray_transport\ray_actor.py", line 64, in run
    raise ClientAppException(str(ex)) from ex
flwr.client.client_app.ClientAppException: 
Exception ClientAppException occurred. Message: set_parameters() takes 2 positional arguments but 3 were given
[2024-05-11 21:01:31,364][flwr][INFO] - aggregate_evaluate: received 0 results and 2 failures
[2024-05-11 21:01:31,364][flwr][INFO] - 
[2024-05-11 21:01:31,365][flwr][INFO] - [ROUND 7]
[2024-05-11 21:01:31,365][flwr][INFO] - configure_fit: strategy sampled 1 clients (out of 2)
[2024-05-11 21:01:31,376][flwr][ERROR] - Traceback (most recent call last):
  File "C:\Users\jyaka\anaconda3\envs\flower\lib\site-packages\flwr\simulation\ray_transport\ray_client_proxy.py", line 73, in _submit_job
    out_mssg, updated_context = self.actor_pool.get_client_result(
  File "C:\Users\jyaka\anaconda3\envs\flower\lib\site-packages\flwr\simulation\ray_transport\ray_actor.py", line 399, in get_client_result
    return self._fetch_future_result(cid)
  File "C:\Users\jyaka\anaconda3\envs\flower\lib\site-packages\flwr\simulation\ray_transport\ray_actor.py", line 280, in _fetch_future_result
    res_cid, out_mssg, updated_context = ray.get(
  File "C:\Users\jyaka\anaconda3\envs\flower\lib\site-packages\ray\_private\auto_init_hook.py", line 24, in auto_init_wrapper
    return fn(*args, **kwargs)
  File "C:\Users\jyaka\anaconda3\envs\flower\lib\site-packages\ray\_private\client_mode_hook.py", line 103, in wrapper
    return func(*args, **kwargs)
  File "C:\Users\jyaka\anaconda3\envs\flower\lib\site-packages\ray\_private\worker.py", line 2524, in get
    raise value.as_instanceof_cause()
ray.exceptions.RayTaskError(ClientAppException): [36mray::ClientAppActor.run()[39m (pid=24760, ip=127.0.0.1, actor_id=0bda77c27b6b10b0fe356e3b01000000, repr=<flwr.simulation.ray_transport.ray_actor.ClientAppActor object at 0x0000023F214E7160>)
  File "C:\Users\jyaka\anaconda3\envs\flower\lib\site-packages\flwr\client\client_app.py", line 98, in __call__
    return self._call(message, context)
  File "C:\Users\jyaka\anaconda3\envs\flower\lib\site-packages\flwr\client\client_app.py", line 81, in ffn
    out_message = handle_legacy_message_from_msgtype(
  File "C:\Users\jyaka\anaconda3\envs\flower\lib\site-packages\flwr\client\message_handler\message_handler.py", line 130, in handle_legacy_message_from_msgtype
    fit_res = maybe_call_fit(
  File "C:\Users\jyaka\anaconda3\envs\flower\lib\site-packages\flwr\client\client.py", line 234, in maybe_call_fit
    return client.fit(fit_ins)
  File "C:\Users\jyaka\anaconda3\envs\flower\lib\site-packages\flwr\client\numpy_client.py", line 238, in _fit
    results = self.numpy_client.fit(parameters, ins.config)  # type: ignore
  File "C:\Users\jyaka\Documents\research\flower_tutorial\client.py", line 37, in fit
    epochs = config["epochs"]
KeyError: 'epochs'

The above exception was the direct cause of the following exception:

[36mray::ClientAppActor.run()[39m (pid=24760, ip=127.0.0.1, actor_id=0bda77c27b6b10b0fe356e3b01000000, repr=<flwr.simulation.ray_transport.ray_actor.ClientAppActor object at 0x0000023F214E7160>)
  File "python\ray\_raylet.pyx", line 1418, in ray._raylet.execute_task
  File "python\ray\_raylet.pyx", line 1498, in ray._raylet.execute_task
  File "python\ray\_raylet.pyx", line 1424, in ray._raylet.execute_task
  File "python\ray\_raylet.pyx", line 1364, in ray._raylet.execute_task.function_executor
  File "C:\Users\jyaka\anaconda3\envs\flower\lib\site-packages\ray\_private\function_manager.py", line 726, in actor_method_executor
    return method(__ray_actor, *args, **kwargs)
  File "C:\Users\jyaka\anaconda3\envs\flower\lib\site-packages\ray\util\tracing\tracing_helper.py", line 464, in _resume_span
    return method(self, *_args, **_kwargs)
  File "C:\Users\jyaka\anaconda3\envs\flower\lib\site-packages\flwr\simulation\ray_transport\ray_actor.py", line 64, in run
    raise ClientAppException(str(ex)) from ex
flwr.client.client_app.ClientAppException: 
Exception ClientAppException occurred. Message: 'epochs'

[2024-05-11 21:01:31,387][flwr][ERROR] - [36mray::ClientAppActor.run()[39m (pid=24760, ip=127.0.0.1, actor_id=0bda77c27b6b10b0fe356e3b01000000, repr=<flwr.simulation.ray_transport.ray_actor.ClientAppActor object at 0x0000023F214E7160>)
  File "C:\Users\jyaka\anaconda3\envs\flower\lib\site-packages\flwr\client\client_app.py", line 98, in __call__
    return self._call(message, context)
  File "C:\Users\jyaka\anaconda3\envs\flower\lib\site-packages\flwr\client\client_app.py", line 81, in ffn
    out_message = handle_legacy_message_from_msgtype(
  File "C:\Users\jyaka\anaconda3\envs\flower\lib\site-packages\flwr\client\message_handler\message_handler.py", line 130, in handle_legacy_message_from_msgtype
    fit_res = maybe_call_fit(
  File "C:\Users\jyaka\anaconda3\envs\flower\lib\site-packages\flwr\client\client.py", line 234, in maybe_call_fit
    return client.fit(fit_ins)
  File "C:\Users\jyaka\anaconda3\envs\flower\lib\site-packages\flwr\client\numpy_client.py", line 238, in _fit
    results = self.numpy_client.fit(parameters, ins.config)  # type: ignore
  File "C:\Users\jyaka\Documents\research\flower_tutorial\client.py", line 37, in fit
    epochs = config["epochs"]
KeyError: 'epochs'

The above exception was the direct cause of the following exception:

[36mray::ClientAppActor.run()[39m (pid=24760, ip=127.0.0.1, actor_id=0bda77c27b6b10b0fe356e3b01000000, repr=<flwr.simulation.ray_transport.ray_actor.ClientAppActor object at 0x0000023F214E7160>)
  File "python\ray\_raylet.pyx", line 1418, in ray._raylet.execute_task
  File "python\ray\_raylet.pyx", line 1498, in ray._raylet.execute_task
  File "python\ray\_raylet.pyx", line 1424, in ray._raylet.execute_task
  File "python\ray\_raylet.pyx", line 1364, in ray._raylet.execute_task.function_executor
  File "C:\Users\jyaka\anaconda3\envs\flower\lib\site-packages\ray\_private\function_manager.py", line 726, in actor_method_executor
    return method(__ray_actor, *args, **kwargs)
  File "C:\Users\jyaka\anaconda3\envs\flower\lib\site-packages\ray\util\tracing\tracing_helper.py", line 464, in _resume_span
    return method(self, *_args, **_kwargs)
  File "C:\Users\jyaka\anaconda3\envs\flower\lib\site-packages\flwr\simulation\ray_transport\ray_actor.py", line 64, in run
    raise ClientAppException(str(ex)) from ex
flwr.client.client_app.ClientAppException: 
Exception ClientAppException occurred. Message: 'epochs'
[2024-05-11 21:01:31,392][flwr][INFO] - aggregate_fit: received 0 results and 1 failures
[2024-05-11 21:01:31,393][flwr][INFO] - configure_evaluate: strategy sampled 2 clients (out of 2)
[2024-05-11 21:01:31,405][flwr][ERROR] - Traceback (most recent call last):
  File "C:\Users\jyaka\anaconda3\envs\flower\lib\site-packages\flwr\simulation\ray_transport\ray_client_proxy.py", line 73, in _submit_job
    out_mssg, updated_context = self.actor_pool.get_client_result(
  File "C:\Users\jyaka\anaconda3\envs\flower\lib\site-packages\flwr\simulation\ray_transport\ray_actor.py", line 399, in get_client_result
    return self._fetch_future_result(cid)
  File "C:\Users\jyaka\anaconda3\envs\flower\lib\site-packages\flwr\simulation\ray_transport\ray_actor.py", line 280, in _fetch_future_result
    res_cid, out_mssg, updated_context = ray.get(
  File "C:\Users\jyaka\anaconda3\envs\flower\lib\site-packages\ray\_private\auto_init_hook.py", line 24, in auto_init_wrapper
    return fn(*args, **kwargs)
  File "C:\Users\jyaka\anaconda3\envs\flower\lib\site-packages\ray\_private\client_mode_hook.py", line 103, in wrapper
    return func(*args, **kwargs)
  File "C:\Users\jyaka\anaconda3\envs\flower\lib\site-packages\ray\_private\worker.py", line 2524, in get
    raise value.as_instanceof_cause()
ray.exceptions.RayTaskError(ClientAppException): [36mray::ClientAppActor.run()[39m (pid=24760, ip=127.0.0.1, actor_id=0bda77c27b6b10b0fe356e3b01000000, repr=<flwr.simulation.ray_transport.ray_actor.ClientAppActor object at 0x0000023F214E7160>)
  File "C:\Users\jyaka\anaconda3\envs\flower\lib\site-packages\flwr\client\client_app.py", line 98, in __call__
    return self._call(message, context)
  File "C:\Users\jyaka\anaconda3\envs\flower\lib\site-packages\flwr\client\client_app.py", line 81, in ffn
    out_message = handle_legacy_message_from_msgtype(
  File "C:\Users\jyaka\anaconda3\envs\flower\lib\site-packages\flwr\client\message_handler\message_handler.py", line 137, in handle_legacy_message_from_msgtype
    evaluate_res = maybe_call_evaluate(
  File "C:\Users\jyaka\anaconda3\envs\flower\lib\site-packages\flwr\client\client.py", line 254, in maybe_call_evaluate
    return client.evaluate(evaluate_ins)
  File "C:\Users\jyaka\anaconda3\envs\flower\lib\site-packages\flwr\client\numpy_client.py", line 262, in _evaluate
    results = self.numpy_client.evaluate(parameters, ins.config)  # type: ignore
  File "C:\Users\jyaka\Documents\research\flower_tutorial\client.py", line 45, in evaluate
    self.set_parameters(self.model, parameters)
TypeError: set_parameters() takes 2 positional arguments but 3 were given

The above exception was the direct cause of the following exception:

[36mray::ClientAppActor.run()[39m (pid=24760, ip=127.0.0.1, actor_id=0bda77c27b6b10b0fe356e3b01000000, repr=<flwr.simulation.ray_transport.ray_actor.ClientAppActor object at 0x0000023F214E7160>)
  File "python\ray\_raylet.pyx", line 1418, in ray._raylet.execute_task
  File "python\ray\_raylet.pyx", line 1498, in ray._raylet.execute_task
  File "python\ray\_raylet.pyx", line 1424, in ray._raylet.execute_task
  File "python\ray\_raylet.pyx", line 1364, in ray._raylet.execute_task.function_executor
  File "C:\Users\jyaka\anaconda3\envs\flower\lib\site-packages\ray\_private\function_manager.py", line 726, in actor_method_executor
    return method(__ray_actor, *args, **kwargs)
  File "C:\Users\jyaka\anaconda3\envs\flower\lib\site-packages\ray\util\tracing\tracing_helper.py", line 464, in _resume_span
    return method(self, *_args, **_kwargs)
  File "C:\Users\jyaka\anaconda3\envs\flower\lib\site-packages\flwr\simulation\ray_transport\ray_actor.py", line 64, in run
    raise ClientAppException(str(ex)) from ex
flwr.client.client_app.ClientAppException: 
Exception ClientAppException occurred. Message: set_parameters() takes 2 positional arguments but 3 were given

[2024-05-11 21:01:31,409][flwr][ERROR] - Traceback (most recent call last):
  File "C:\Users\jyaka\anaconda3\envs\flower\lib\site-packages\flwr\simulation\ray_transport\ray_client_proxy.py", line 73, in _submit_job
    out_mssg, updated_context = self.actor_pool.get_client_result(
  File "C:\Users\jyaka\anaconda3\envs\flower\lib\site-packages\flwr\simulation\ray_transport\ray_actor.py", line 399, in get_client_result
    return self._fetch_future_result(cid)
  File "C:\Users\jyaka\anaconda3\envs\flower\lib\site-packages\flwr\simulation\ray_transport\ray_actor.py", line 280, in _fetch_future_result
    res_cid, out_mssg, updated_context = ray.get(
  File "C:\Users\jyaka\anaconda3\envs\flower\lib\site-packages\ray\_private\auto_init_hook.py", line 24, in auto_init_wrapper
    return fn(*args, **kwargs)
  File "C:\Users\jyaka\anaconda3\envs\flower\lib\site-packages\ray\_private\client_mode_hook.py", line 103, in wrapper
    return func(*args, **kwargs)
  File "C:\Users\jyaka\anaconda3\envs\flower\lib\site-packages\ray\_private\worker.py", line 2524, in get
    raise value.as_instanceof_cause()
ray.exceptions.RayTaskError(ClientAppException): [36mray::ClientAppActor.run()[39m (pid=9728, ip=127.0.0.1, actor_id=449d6fb233f4c3623911c51301000000, repr=<flwr.simulation.ray_transport.ray_actor.ClientAppActor object at 0x000001709AF0B0D0>)
  File "C:\Users\jyaka\anaconda3\envs\flower\lib\site-packages\flwr\client\client_app.py", line 98, in __call__
    return self._call(message, context)
  File "C:\Users\jyaka\anaconda3\envs\flower\lib\site-packages\flwr\client\client_app.py", line 81, in ffn
    out_message = handle_legacy_message_from_msgtype(
  File "C:\Users\jyaka\anaconda3\envs\flower\lib\site-packages\flwr\client\message_handler\message_handler.py", line 137, in handle_legacy_message_from_msgtype
    evaluate_res = maybe_call_evaluate(
  File "C:\Users\jyaka\anaconda3\envs\flower\lib\site-packages\flwr\client\client.py", line 254, in maybe_call_evaluate
    return client.evaluate(evaluate_ins)
  File "C:\Users\jyaka\anaconda3\envs\flower\lib\site-packages\flwr\client\numpy_client.py", line 262, in _evaluate
    results = self.numpy_client.evaluate(parameters, ins.config)  # type: ignore
  File "C:\Users\jyaka\Documents\research\flower_tutorial\client.py", line 45, in evaluate
    self.set_parameters(self.model, parameters)
TypeError: set_parameters() takes 2 positional arguments but 3 were given

The above exception was the direct cause of the following exception:

[36mray::ClientAppActor.run()[39m (pid=9728, ip=127.0.0.1, actor_id=449d6fb233f4c3623911c51301000000, repr=<flwr.simulation.ray_transport.ray_actor.ClientAppActor object at 0x000001709AF0B0D0>)
  File "python\ray\_raylet.pyx", line 1418, in ray._raylet.execute_task
  File "python\ray\_raylet.pyx", line 1498, in ray._raylet.execute_task
  File "python\ray\_raylet.pyx", line 1424, in ray._raylet.execute_task
  File "python\ray\_raylet.pyx", line 1364, in ray._raylet.execute_task.function_executor
  File "C:\Users\jyaka\anaconda3\envs\flower\lib\site-packages\ray\_private\function_manager.py", line 726, in actor_method_executor
    return method(__ray_actor, *args, **kwargs)
  File "C:\Users\jyaka\anaconda3\envs\flower\lib\site-packages\ray\util\tracing\tracing_helper.py", line 464, in _resume_span
    return method(self, *_args, **_kwargs)
  File "C:\Users\jyaka\anaconda3\envs\flower\lib\site-packages\flwr\simulation\ray_transport\ray_actor.py", line 64, in run
    raise ClientAppException(str(ex)) from ex
flwr.client.client_app.ClientAppException: 
Exception ClientAppException occurred. Message: set_parameters() takes 2 positional arguments but 3 were given

[2024-05-11 21:01:31,417][flwr][ERROR] - [36mray::ClientAppActor.run()[39m (pid=24760, ip=127.0.0.1, actor_id=0bda77c27b6b10b0fe356e3b01000000, repr=<flwr.simulation.ray_transport.ray_actor.ClientAppActor object at 0x0000023F214E7160>)
  File "C:\Users\jyaka\anaconda3\envs\flower\lib\site-packages\flwr\client\client_app.py", line 98, in __call__
    return self._call(message, context)
  File "C:\Users\jyaka\anaconda3\envs\flower\lib\site-packages\flwr\client\client_app.py", line 81, in ffn
    out_message = handle_legacy_message_from_msgtype(
  File "C:\Users\jyaka\anaconda3\envs\flower\lib\site-packages\flwr\client\message_handler\message_handler.py", line 137, in handle_legacy_message_from_msgtype
    evaluate_res = maybe_call_evaluate(
  File "C:\Users\jyaka\anaconda3\envs\flower\lib\site-packages\flwr\client\client.py", line 254, in maybe_call_evaluate
    return client.evaluate(evaluate_ins)
  File "C:\Users\jyaka\anaconda3\envs\flower\lib\site-packages\flwr\client\numpy_client.py", line 262, in _evaluate
    results = self.numpy_client.evaluate(parameters, ins.config)  # type: ignore
  File "C:\Users\jyaka\Documents\research\flower_tutorial\client.py", line 45, in evaluate
    self.set_parameters(self.model, parameters)
TypeError: set_parameters() takes 2 positional arguments but 3 were given

The above exception was the direct cause of the following exception:

[36mray::ClientAppActor.run()[39m (pid=24760, ip=127.0.0.1, actor_id=0bda77c27b6b10b0fe356e3b01000000, repr=<flwr.simulation.ray_transport.ray_actor.ClientAppActor object at 0x0000023F214E7160>)
  File "python\ray\_raylet.pyx", line 1418, in ray._raylet.execute_task
  File "python\ray\_raylet.pyx", line 1498, in ray._raylet.execute_task
  File "python\ray\_raylet.pyx", line 1424, in ray._raylet.execute_task
  File "python\ray\_raylet.pyx", line 1364, in ray._raylet.execute_task.function_executor
  File "C:\Users\jyaka\anaconda3\envs\flower\lib\site-packages\ray\_private\function_manager.py", line 726, in actor_method_executor
    return method(__ray_actor, *args, **kwargs)
  File "C:\Users\jyaka\anaconda3\envs\flower\lib\site-packages\ray\util\tracing\tracing_helper.py", line 464, in _resume_span
    return method(self, *_args, **_kwargs)
  File "C:\Users\jyaka\anaconda3\envs\flower\lib\site-packages\flwr\simulation\ray_transport\ray_actor.py", line 64, in run
    raise ClientAppException(str(ex)) from ex
flwr.client.client_app.ClientAppException: 
Exception ClientAppException occurred. Message: set_parameters() takes 2 positional arguments but 3 were given
[2024-05-11 21:01:31,425][flwr][ERROR] - [36mray::ClientAppActor.run()[39m (pid=9728, ip=127.0.0.1, actor_id=449d6fb233f4c3623911c51301000000, repr=<flwr.simulation.ray_transport.ray_actor.ClientAppActor object at 0x000001709AF0B0D0>)
  File "C:\Users\jyaka\anaconda3\envs\flower\lib\site-packages\flwr\client\client_app.py", line 98, in __call__
    return self._call(message, context)
  File "C:\Users\jyaka\anaconda3\envs\flower\lib\site-packages\flwr\client\client_app.py", line 81, in ffn
    out_message = handle_legacy_message_from_msgtype(
  File "C:\Users\jyaka\anaconda3\envs\flower\lib\site-packages\flwr\client\message_handler\message_handler.py", line 137, in handle_legacy_message_from_msgtype
    evaluate_res = maybe_call_evaluate(
  File "C:\Users\jyaka\anaconda3\envs\flower\lib\site-packages\flwr\client\client.py", line 254, in maybe_call_evaluate
    return client.evaluate(evaluate_ins)
  File "C:\Users\jyaka\anaconda3\envs\flower\lib\site-packages\flwr\client\numpy_client.py", line 262, in _evaluate
    results = self.numpy_client.evaluate(parameters, ins.config)  # type: ignore
  File "C:\Users\jyaka\Documents\research\flower_tutorial\client.py", line 45, in evaluate
    self.set_parameters(self.model, parameters)
TypeError: set_parameters() takes 2 positional arguments but 3 were given

The above exception was the direct cause of the following exception:

[36mray::ClientAppActor.run()[39m (pid=9728, ip=127.0.0.1, actor_id=449d6fb233f4c3623911c51301000000, repr=<flwr.simulation.ray_transport.ray_actor.ClientAppActor object at 0x000001709AF0B0D0>)
  File "python\ray\_raylet.pyx", line 1418, in ray._raylet.execute_task
  File "python\ray\_raylet.pyx", line 1498, in ray._raylet.execute_task
  File "python\ray\_raylet.pyx", line 1424, in ray._raylet.execute_task
  File "python\ray\_raylet.pyx", line 1364, in ray._raylet.execute_task.function_executor
  File "C:\Users\jyaka\anaconda3\envs\flower\lib\site-packages\ray\_private\function_manager.py", line 726, in actor_method_executor
    return method(__ray_actor, *args, **kwargs)
  File "C:\Users\jyaka\anaconda3\envs\flower\lib\site-packages\ray\util\tracing\tracing_helper.py", line 464, in _resume_span
    return method(self, *_args, **_kwargs)
  File "C:\Users\jyaka\anaconda3\envs\flower\lib\site-packages\flwr\simulation\ray_transport\ray_actor.py", line 64, in run
    raise ClientAppException(str(ex)) from ex
flwr.client.client_app.ClientAppException: 
Exception ClientAppException occurred. Message: set_parameters() takes 2 positional arguments but 3 were given
[2024-05-11 21:01:31,436][flwr][INFO] - aggregate_evaluate: received 0 results and 2 failures
[2024-05-11 21:01:31,436][flwr][INFO] - 
[2024-05-11 21:01:31,437][flwr][INFO] - [ROUND 8]
[2024-05-11 21:01:31,437][flwr][INFO] - configure_fit: strategy sampled 1 clients (out of 2)
[2024-05-11 21:01:31,448][flwr][ERROR] - Traceback (most recent call last):
  File "C:\Users\jyaka\anaconda3\envs\flower\lib\site-packages\flwr\simulation\ray_transport\ray_client_proxy.py", line 73, in _submit_job
    out_mssg, updated_context = self.actor_pool.get_client_result(
  File "C:\Users\jyaka\anaconda3\envs\flower\lib\site-packages\flwr\simulation\ray_transport\ray_actor.py", line 399, in get_client_result
    return self._fetch_future_result(cid)
  File "C:\Users\jyaka\anaconda3\envs\flower\lib\site-packages\flwr\simulation\ray_transport\ray_actor.py", line 280, in _fetch_future_result
    res_cid, out_mssg, updated_context = ray.get(
  File "C:\Users\jyaka\anaconda3\envs\flower\lib\site-packages\ray\_private\auto_init_hook.py", line 24, in auto_init_wrapper
    return fn(*args, **kwargs)
  File "C:\Users\jyaka\anaconda3\envs\flower\lib\site-packages\ray\_private\client_mode_hook.py", line 103, in wrapper
    return func(*args, **kwargs)
  File "C:\Users\jyaka\anaconda3\envs\flower\lib\site-packages\ray\_private\worker.py", line 2524, in get
    raise value.as_instanceof_cause()
ray.exceptions.RayTaskError(ClientAppException): [36mray::ClientAppActor.run()[39m (pid=9728, ip=127.0.0.1, actor_id=449d6fb233f4c3623911c51301000000, repr=<flwr.simulation.ray_transport.ray_actor.ClientAppActor object at 0x000001709AF0B0D0>)
  File "C:\Users\jyaka\anaconda3\envs\flower\lib\site-packages\flwr\client\client_app.py", line 98, in __call__
    return self._call(message, context)
  File "C:\Users\jyaka\anaconda3\envs\flower\lib\site-packages\flwr\client\client_app.py", line 81, in ffn
    out_message = handle_legacy_message_from_msgtype(
  File "C:\Users\jyaka\anaconda3\envs\flower\lib\site-packages\flwr\client\message_handler\message_handler.py", line 130, in handle_legacy_message_from_msgtype
    fit_res = maybe_call_fit(
  File "C:\Users\jyaka\anaconda3\envs\flower\lib\site-packages\flwr\client\client.py", line 234, in maybe_call_fit
    return client.fit(fit_ins)
  File "C:\Users\jyaka\anaconda3\envs\flower\lib\site-packages\flwr\client\numpy_client.py", line 238, in _fit
    results = self.numpy_client.fit(parameters, ins.config)  # type: ignore
  File "C:\Users\jyaka\Documents\research\flower_tutorial\client.py", line 37, in fit
    epochs = config["epochs"]
KeyError: 'epochs'

The above exception was the direct cause of the following exception:

[36mray::ClientAppActor.run()[39m (pid=9728, ip=127.0.0.1, actor_id=449d6fb233f4c3623911c51301000000, repr=<flwr.simulation.ray_transport.ray_actor.ClientAppActor object at 0x000001709AF0B0D0>)
  File "python\ray\_raylet.pyx", line 1418, in ray._raylet.execute_task
  File "python\ray\_raylet.pyx", line 1498, in ray._raylet.execute_task
  File "python\ray\_raylet.pyx", line 1424, in ray._raylet.execute_task
  File "python\ray\_raylet.pyx", line 1364, in ray._raylet.execute_task.function_executor
  File "C:\Users\jyaka\anaconda3\envs\flower\lib\site-packages\ray\_private\function_manager.py", line 726, in actor_method_executor
    return method(__ray_actor, *args, **kwargs)
  File "C:\Users\jyaka\anaconda3\envs\flower\lib\site-packages\ray\util\tracing\tracing_helper.py", line 464, in _resume_span
    return method(self, *_args, **_kwargs)
  File "C:\Users\jyaka\anaconda3\envs\flower\lib\site-packages\flwr\simulation\ray_transport\ray_actor.py", line 64, in run
    raise ClientAppException(str(ex)) from ex
flwr.client.client_app.ClientAppException: 
Exception ClientAppException occurred. Message: 'epochs'

[2024-05-11 21:01:31,460][flwr][ERROR] - [36mray::ClientAppActor.run()[39m (pid=9728, ip=127.0.0.1, actor_id=449d6fb233f4c3623911c51301000000, repr=<flwr.simulation.ray_transport.ray_actor.ClientAppActor object at 0x000001709AF0B0D0>)
  File "C:\Users\jyaka\anaconda3\envs\flower\lib\site-packages\flwr\client\client_app.py", line 98, in __call__
    return self._call(message, context)
  File "C:\Users\jyaka\anaconda3\envs\flower\lib\site-packages\flwr\client\client_app.py", line 81, in ffn
    out_message = handle_legacy_message_from_msgtype(
  File "C:\Users\jyaka\anaconda3\envs\flower\lib\site-packages\flwr\client\message_handler\message_handler.py", line 130, in handle_legacy_message_from_msgtype
    fit_res = maybe_call_fit(
  File "C:\Users\jyaka\anaconda3\envs\flower\lib\site-packages\flwr\client\client.py", line 234, in maybe_call_fit
    return client.fit(fit_ins)
  File "C:\Users\jyaka\anaconda3\envs\flower\lib\site-packages\flwr\client\numpy_client.py", line 238, in _fit
    results = self.numpy_client.fit(parameters, ins.config)  # type: ignore
  File "C:\Users\jyaka\Documents\research\flower_tutorial\client.py", line 37, in fit
    epochs = config["epochs"]
KeyError: 'epochs'

The above exception was the direct cause of the following exception:

[36mray::ClientAppActor.run()[39m (pid=9728, ip=127.0.0.1, actor_id=449d6fb233f4c3623911c51301000000, repr=<flwr.simulation.ray_transport.ray_actor.ClientAppActor object at 0x000001709AF0B0D0>)
  File "python\ray\_raylet.pyx", line 1418, in ray._raylet.execute_task
  File "python\ray\_raylet.pyx", line 1498, in ray._raylet.execute_task
  File "python\ray\_raylet.pyx", line 1424, in ray._raylet.execute_task
  File "python\ray\_raylet.pyx", line 1364, in ray._raylet.execute_task.function_executor
  File "C:\Users\jyaka\anaconda3\envs\flower\lib\site-packages\ray\_private\function_manager.py", line 726, in actor_method_executor
    return method(__ray_actor, *args, **kwargs)
  File "C:\Users\jyaka\anaconda3\envs\flower\lib\site-packages\ray\util\tracing\tracing_helper.py", line 464, in _resume_span
    return method(self, *_args, **_kwargs)
  File "C:\Users\jyaka\anaconda3\envs\flower\lib\site-packages\flwr\simulation\ray_transport\ray_actor.py", line 64, in run
    raise ClientAppException(str(ex)) from ex
flwr.client.client_app.ClientAppException: 
Exception ClientAppException occurred. Message: 'epochs'
[2024-05-11 21:01:31,466][flwr][INFO] - aggregate_fit: received 0 results and 1 failures
[2024-05-11 21:01:31,467][flwr][INFO] - configure_evaluate: strategy sampled 2 clients (out of 2)
[2024-05-11 21:01:31,478][flwr][ERROR] - Traceback (most recent call last):
  File "C:\Users\jyaka\anaconda3\envs\flower\lib\site-packages\flwr\simulation\ray_transport\ray_client_proxy.py", line 73, in _submit_job
    out_mssg, updated_context = self.actor_pool.get_client_result(
  File "C:\Users\jyaka\anaconda3\envs\flower\lib\site-packages\flwr\simulation\ray_transport\ray_actor.py", line 399, in get_client_result
    return self._fetch_future_result(cid)
  File "C:\Users\jyaka\anaconda3\envs\flower\lib\site-packages\flwr\simulation\ray_transport\ray_actor.py", line 280, in _fetch_future_result
    res_cid, out_mssg, updated_context = ray.get(
  File "C:\Users\jyaka\anaconda3\envs\flower\lib\site-packages\ray\_private\auto_init_hook.py", line 24, in auto_init_wrapper
    return fn(*args, **kwargs)
  File "C:\Users\jyaka\anaconda3\envs\flower\lib\site-packages\ray\_private\client_mode_hook.py", line 103, in wrapper
    return func(*args, **kwargs)
  File "C:\Users\jyaka\anaconda3\envs\flower\lib\site-packages\ray\_private\worker.py", line 2524, in get
    raise value.as_instanceof_cause()
ray.exceptions.RayTaskError(ClientAppException): [36mray::ClientAppActor.run()[39m (pid=9728, ip=127.0.0.1, actor_id=449d6fb233f4c3623911c51301000000, repr=<flwr.simulation.ray_transport.ray_actor.ClientAppActor object at 0x000001709AF0B0D0>)
  File "C:\Users\jyaka\anaconda3\envs\flower\lib\site-packages\flwr\client\client_app.py", line 98, in __call__
    return self._call(message, context)
  File "C:\Users\jyaka\anaconda3\envs\flower\lib\site-packages\flwr\client\client_app.py", line 81, in ffn
    out_message = handle_legacy_message_from_msgtype(
  File "C:\Users\jyaka\anaconda3\envs\flower\lib\site-packages\flwr\client\message_handler\message_handler.py", line 137, in handle_legacy_message_from_msgtype
    evaluate_res = maybe_call_evaluate(
  File "C:\Users\jyaka\anaconda3\envs\flower\lib\site-packages\flwr\client\client.py", line 254, in maybe_call_evaluate
    return client.evaluate(evaluate_ins)
  File "C:\Users\jyaka\anaconda3\envs\flower\lib\site-packages\flwr\client\numpy_client.py", line 262, in _evaluate
    results = self.numpy_client.evaluate(parameters, ins.config)  # type: ignore
  File "C:\Users\jyaka\Documents\research\flower_tutorial\client.py", line 45, in evaluate
    self.set_parameters(self.model, parameters)
TypeError: set_parameters() takes 2 positional arguments but 3 were given

The above exception was the direct cause of the following exception:

[36mray::ClientAppActor.run()[39m (pid=9728, ip=127.0.0.1, actor_id=449d6fb233f4c3623911c51301000000, repr=<flwr.simulation.ray_transport.ray_actor.ClientAppActor object at 0x000001709AF0B0D0>)
  File "python\ray\_raylet.pyx", line 1418, in ray._raylet.execute_task
  File "python\ray\_raylet.pyx", line 1498, in ray._raylet.execute_task
  File "python\ray\_raylet.pyx", line 1424, in ray._raylet.execute_task
  File "python\ray\_raylet.pyx", line 1364, in ray._raylet.execute_task.function_executor
  File "C:\Users\jyaka\anaconda3\envs\flower\lib\site-packages\ray\_private\function_manager.py", line 726, in actor_method_executor
    return method(__ray_actor, *args, **kwargs)
  File "C:\Users\jyaka\anaconda3\envs\flower\lib\site-packages\ray\util\tracing\tracing_helper.py", line 464, in _resume_span
    return method(self, *_args, **_kwargs)
  File "C:\Users\jyaka\anaconda3\envs\flower\lib\site-packages\flwr\simulation\ray_transport\ray_actor.py", line 64, in run
    raise ClientAppException(str(ex)) from ex
flwr.client.client_app.ClientAppException: 
Exception ClientAppException occurred. Message: set_parameters() takes 2 positional arguments but 3 were given

[2024-05-11 21:01:31,482][flwr][ERROR] - Traceback (most recent call last):
  File "C:\Users\jyaka\anaconda3\envs\flower\lib\site-packages\flwr\simulation\ray_transport\ray_client_proxy.py", line 73, in _submit_job
    out_mssg, updated_context = self.actor_pool.get_client_result(
  File "C:\Users\jyaka\anaconda3\envs\flower\lib\site-packages\flwr\simulation\ray_transport\ray_actor.py", line 399, in get_client_result
    return self._fetch_future_result(cid)
  File "C:\Users\jyaka\anaconda3\envs\flower\lib\site-packages\flwr\simulation\ray_transport\ray_actor.py", line 280, in _fetch_future_result
    res_cid, out_mssg, updated_context = ray.get(
  File "C:\Users\jyaka\anaconda3\envs\flower\lib\site-packages\ray\_private\auto_init_hook.py", line 24, in auto_init_wrapper
    return fn(*args, **kwargs)
  File "C:\Users\jyaka\anaconda3\envs\flower\lib\site-packages\ray\_private\client_mode_hook.py", line 103, in wrapper
    return func(*args, **kwargs)
  File "C:\Users\jyaka\anaconda3\envs\flower\lib\site-packages\ray\_private\worker.py", line 2524, in get
    raise value.as_instanceof_cause()
ray.exceptions.RayTaskError(ClientAppException): [36mray::ClientAppActor.run()[39m (pid=24760, ip=127.0.0.1, actor_id=0bda77c27b6b10b0fe356e3b01000000, repr=<flwr.simulation.ray_transport.ray_actor.ClientAppActor object at 0x0000023F214E7160>)
  File "C:\Users\jyaka\anaconda3\envs\flower\lib\site-packages\flwr\client\client_app.py", line 98, in __call__
    return self._call(message, context)
  File "C:\Users\jyaka\anaconda3\envs\flower\lib\site-packages\flwr\client\client_app.py", line 81, in ffn
    out_message = handle_legacy_message_from_msgtype(
  File "C:\Users\jyaka\anaconda3\envs\flower\lib\site-packages\flwr\client\message_handler\message_handler.py", line 137, in handle_legacy_message_from_msgtype
    evaluate_res = maybe_call_evaluate(
  File "C:\Users\jyaka\anaconda3\envs\flower\lib\site-packages\flwr\client\client.py", line 254, in maybe_call_evaluate
    return client.evaluate(evaluate_ins)
  File "C:\Users\jyaka\anaconda3\envs\flower\lib\site-packages\flwr\client\numpy_client.py", line 262, in _evaluate
    results = self.numpy_client.evaluate(parameters, ins.config)  # type: ignore
  File "C:\Users\jyaka\Documents\research\flower_tutorial\client.py", line 45, in evaluate
    self.set_parameters(self.model, parameters)
TypeError: set_parameters() takes 2 positional arguments but 3 were given

The above exception was the direct cause of the following exception:

[36mray::ClientAppActor.run()[39m (pid=24760, ip=127.0.0.1, actor_id=0bda77c27b6b10b0fe356e3b01000000, repr=<flwr.simulation.ray_transport.ray_actor.ClientAppActor object at 0x0000023F214E7160>)
  File "python\ray\_raylet.pyx", line 1418, in ray._raylet.execute_task
  File "python\ray\_raylet.pyx", line 1498, in ray._raylet.execute_task
  File "python\ray\_raylet.pyx", line 1424, in ray._raylet.execute_task
  File "python\ray\_raylet.pyx", line 1364, in ray._raylet.execute_task.function_executor
  File "C:\Users\jyaka\anaconda3\envs\flower\lib\site-packages\ray\_private\function_manager.py", line 726, in actor_method_executor
    return method(__ray_actor, *args, **kwargs)
  File "C:\Users\jyaka\anaconda3\envs\flower\lib\site-packages\ray\util\tracing\tracing_helper.py", line 464, in _resume_span
    return method(self, *_args, **_kwargs)
  File "C:\Users\jyaka\anaconda3\envs\flower\lib\site-packages\flwr\simulation\ray_transport\ray_actor.py", line 64, in run
    raise ClientAppException(str(ex)) from ex
flwr.client.client_app.ClientAppException: 
Exception ClientAppException occurred. Message: set_parameters() takes 2 positional arguments but 3 were given

[2024-05-11 21:01:31,491][flwr][ERROR] - [36mray::ClientAppActor.run()[39m (pid=9728, ip=127.0.0.1, actor_id=449d6fb233f4c3623911c51301000000, repr=<flwr.simulation.ray_transport.ray_actor.ClientAppActor object at 0x000001709AF0B0D0>)
  File "C:\Users\jyaka\anaconda3\envs\flower\lib\site-packages\flwr\client\client_app.py", line 98, in __call__
    return self._call(message, context)
  File "C:\Users\jyaka\anaconda3\envs\flower\lib\site-packages\flwr\client\client_app.py", line 81, in ffn
    out_message = handle_legacy_message_from_msgtype(
  File "C:\Users\jyaka\anaconda3\envs\flower\lib\site-packages\flwr\client\message_handler\message_handler.py", line 137, in handle_legacy_message_from_msgtype
    evaluate_res = maybe_call_evaluate(
  File "C:\Users\jyaka\anaconda3\envs\flower\lib\site-packages\flwr\client\client.py", line 254, in maybe_call_evaluate
    return client.evaluate(evaluate_ins)
  File "C:\Users\jyaka\anaconda3\envs\flower\lib\site-packages\flwr\client\numpy_client.py", line 262, in _evaluate
    results = self.numpy_client.evaluate(parameters, ins.config)  # type: ignore
  File "C:\Users\jyaka\Documents\research\flower_tutorial\client.py", line 45, in evaluate
    self.set_parameters(self.model, parameters)
TypeError: set_parameters() takes 2 positional arguments but 3 were given

The above exception was the direct cause of the following exception:

[36mray::ClientAppActor.run()[39m (pid=9728, ip=127.0.0.1, actor_id=449d6fb233f4c3623911c51301000000, repr=<flwr.simulation.ray_transport.ray_actor.ClientAppActor object at 0x000001709AF0B0D0>)
  File "python\ray\_raylet.pyx", line 1418, in ray._raylet.execute_task
  File "python\ray\_raylet.pyx", line 1498, in ray._raylet.execute_task
  File "python\ray\_raylet.pyx", line 1424, in ray._raylet.execute_task
  File "python\ray\_raylet.pyx", line 1364, in ray._raylet.execute_task.function_executor
  File "C:\Users\jyaka\anaconda3\envs\flower\lib\site-packages\ray\_private\function_manager.py", line 726, in actor_method_executor
    return method(__ray_actor, *args, **kwargs)
  File "C:\Users\jyaka\anaconda3\envs\flower\lib\site-packages\ray\util\tracing\tracing_helper.py", line 464, in _resume_span
    return method(self, *_args, **_kwargs)
  File "C:\Users\jyaka\anaconda3\envs\flower\lib\site-packages\flwr\simulation\ray_transport\ray_actor.py", line 64, in run
    raise ClientAppException(str(ex)) from ex
flwr.client.client_app.ClientAppException: 
Exception ClientAppException occurred. Message: set_parameters() takes 2 positional arguments but 3 were given
[2024-05-11 21:01:31,499][flwr][ERROR] - [36mray::ClientAppActor.run()[39m (pid=24760, ip=127.0.0.1, actor_id=0bda77c27b6b10b0fe356e3b01000000, repr=<flwr.simulation.ray_transport.ray_actor.ClientAppActor object at 0x0000023F214E7160>)
  File "C:\Users\jyaka\anaconda3\envs\flower\lib\site-packages\flwr\client\client_app.py", line 98, in __call__
    return self._call(message, context)
  File "C:\Users\jyaka\anaconda3\envs\flower\lib\site-packages\flwr\client\client_app.py", line 81, in ffn
    out_message = handle_legacy_message_from_msgtype(
  File "C:\Users\jyaka\anaconda3\envs\flower\lib\site-packages\flwr\client\message_handler\message_handler.py", line 137, in handle_legacy_message_from_msgtype
    evaluate_res = maybe_call_evaluate(
  File "C:\Users\jyaka\anaconda3\envs\flower\lib\site-packages\flwr\client\client.py", line 254, in maybe_call_evaluate
    return client.evaluate(evaluate_ins)
  File "C:\Users\jyaka\anaconda3\envs\flower\lib\site-packages\flwr\client\numpy_client.py", line 262, in _evaluate
    results = self.numpy_client.evaluate(parameters, ins.config)  # type: ignore
  File "C:\Users\jyaka\Documents\research\flower_tutorial\client.py", line 45, in evaluate
    self.set_parameters(self.model, parameters)
TypeError: set_parameters() takes 2 positional arguments but 3 were given

The above exception was the direct cause of the following exception:

[36mray::ClientAppActor.run()[39m (pid=24760, ip=127.0.0.1, actor_id=0bda77c27b6b10b0fe356e3b01000000, repr=<flwr.simulation.ray_transport.ray_actor.ClientAppActor object at 0x0000023F214E7160>)
  File "python\ray\_raylet.pyx", line 1418, in ray._raylet.execute_task
  File "python\ray\_raylet.pyx", line 1498, in ray._raylet.execute_task
  File "python\ray\_raylet.pyx", line 1424, in ray._raylet.execute_task
  File "python\ray\_raylet.pyx", line 1364, in ray._raylet.execute_task.function_executor
  File "C:\Users\jyaka\anaconda3\envs\flower\lib\site-packages\ray\_private\function_manager.py", line 726, in actor_method_executor
    return method(__ray_actor, *args, **kwargs)
  File "C:\Users\jyaka\anaconda3\envs\flower\lib\site-packages\ray\util\tracing\tracing_helper.py", line 464, in _resume_span
    return method(self, *_args, **_kwargs)
  File "C:\Users\jyaka\anaconda3\envs\flower\lib\site-packages\flwr\simulation\ray_transport\ray_actor.py", line 64, in run
    raise ClientAppException(str(ex)) from ex
flwr.client.client_app.ClientAppException: 
Exception ClientAppException occurred. Message: set_parameters() takes 2 positional arguments but 3 were given
[2024-05-11 21:01:31,512][flwr][INFO] - aggregate_evaluate: received 0 results and 2 failures
[2024-05-11 21:01:31,513][flwr][INFO] - 
[2024-05-11 21:01:31,513][flwr][INFO] - [ROUND 9]
[2024-05-11 21:01:31,513][flwr][INFO] - configure_fit: strategy sampled 1 clients (out of 2)
[2024-05-11 21:01:31,525][flwr][ERROR] - Traceback (most recent call last):
  File "C:\Users\jyaka\anaconda3\envs\flower\lib\site-packages\flwr\simulation\ray_transport\ray_client_proxy.py", line 73, in _submit_job
    out_mssg, updated_context = self.actor_pool.get_client_result(
  File "C:\Users\jyaka\anaconda3\envs\flower\lib\site-packages\flwr\simulation\ray_transport\ray_actor.py", line 399, in get_client_result
    return self._fetch_future_result(cid)
  File "C:\Users\jyaka\anaconda3\envs\flower\lib\site-packages\flwr\simulation\ray_transport\ray_actor.py", line 280, in _fetch_future_result
    res_cid, out_mssg, updated_context = ray.get(
  File "C:\Users\jyaka\anaconda3\envs\flower\lib\site-packages\ray\_private\auto_init_hook.py", line 24, in auto_init_wrapper
    return fn(*args, **kwargs)
  File "C:\Users\jyaka\anaconda3\envs\flower\lib\site-packages\ray\_private\client_mode_hook.py", line 103, in wrapper
    return func(*args, **kwargs)
  File "C:\Users\jyaka\anaconda3\envs\flower\lib\site-packages\ray\_private\worker.py", line 2524, in get
    raise value.as_instanceof_cause()
ray.exceptions.RayTaskError(ClientAppException): [36mray::ClientAppActor.run()[39m (pid=24760, ip=127.0.0.1, actor_id=0bda77c27b6b10b0fe356e3b01000000, repr=<flwr.simulation.ray_transport.ray_actor.ClientAppActor object at 0x0000023F214E7160>)
  File "C:\Users\jyaka\anaconda3\envs\flower\lib\site-packages\flwr\client\client_app.py", line 98, in __call__
    return self._call(message, context)
  File "C:\Users\jyaka\anaconda3\envs\flower\lib\site-packages\flwr\client\client_app.py", line 81, in ffn
    out_message = handle_legacy_message_from_msgtype(
  File "C:\Users\jyaka\anaconda3\envs\flower\lib\site-packages\flwr\client\message_handler\message_handler.py", line 130, in handle_legacy_message_from_msgtype
    fit_res = maybe_call_fit(
  File "C:\Users\jyaka\anaconda3\envs\flower\lib\site-packages\flwr\client\client.py", line 234, in maybe_call_fit
    return client.fit(fit_ins)
  File "C:\Users\jyaka\anaconda3\envs\flower\lib\site-packages\flwr\client\numpy_client.py", line 238, in _fit
    results = self.numpy_client.fit(parameters, ins.config)  # type: ignore
  File "C:\Users\jyaka\Documents\research\flower_tutorial\client.py", line 37, in fit
    epochs = config["epochs"]
KeyError: 'epochs'

The above exception was the direct cause of the following exception:

[36mray::ClientAppActor.run()[39m (pid=24760, ip=127.0.0.1, actor_id=0bda77c27b6b10b0fe356e3b01000000, repr=<flwr.simulation.ray_transport.ray_actor.ClientAppActor object at 0x0000023F214E7160>)
  File "python\ray\_raylet.pyx", line 1418, in ray._raylet.execute_task
  File "python\ray\_raylet.pyx", line 1498, in ray._raylet.execute_task
  File "python\ray\_raylet.pyx", line 1424, in ray._raylet.execute_task
  File "python\ray\_raylet.pyx", line 1364, in ray._raylet.execute_task.function_executor
  File "C:\Users\jyaka\anaconda3\envs\flower\lib\site-packages\ray\_private\function_manager.py", line 726, in actor_method_executor
    return method(__ray_actor, *args, **kwargs)
  File "C:\Users\jyaka\anaconda3\envs\flower\lib\site-packages\ray\util\tracing\tracing_helper.py", line 464, in _resume_span
    return method(self, *_args, **_kwargs)
  File "C:\Users\jyaka\anaconda3\envs\flower\lib\site-packages\flwr\simulation\ray_transport\ray_actor.py", line 64, in run
    raise ClientAppException(str(ex)) from ex
flwr.client.client_app.ClientAppException: 
Exception ClientAppException occurred. Message: 'epochs'

[2024-05-11 21:01:31,534][flwr][ERROR] - [36mray::ClientAppActor.run()[39m (pid=24760, ip=127.0.0.1, actor_id=0bda77c27b6b10b0fe356e3b01000000, repr=<flwr.simulation.ray_transport.ray_actor.ClientAppActor object at 0x0000023F214E7160>)
  File "C:\Users\jyaka\anaconda3\envs\flower\lib\site-packages\flwr\client\client_app.py", line 98, in __call__
    return self._call(message, context)
  File "C:\Users\jyaka\anaconda3\envs\flower\lib\site-packages\flwr\client\client_app.py", line 81, in ffn
    out_message = handle_legacy_message_from_msgtype(
  File "C:\Users\jyaka\anaconda3\envs\flower\lib\site-packages\flwr\client\message_handler\message_handler.py", line 130, in handle_legacy_message_from_msgtype
    fit_res = maybe_call_fit(
  File "C:\Users\jyaka\anaconda3\envs\flower\lib\site-packages\flwr\client\client.py", line 234, in maybe_call_fit
    return client.fit(fit_ins)
  File "C:\Users\jyaka\anaconda3\envs\flower\lib\site-packages\flwr\client\numpy_client.py", line 238, in _fit
    results = self.numpy_client.fit(parameters, ins.config)  # type: ignore
  File "C:\Users\jyaka\Documents\research\flower_tutorial\client.py", line 37, in fit
    epochs = config["epochs"]
KeyError: 'epochs'

The above exception was the direct cause of the following exception:

[36mray::ClientAppActor.run()[39m (pid=24760, ip=127.0.0.1, actor_id=0bda77c27b6b10b0fe356e3b01000000, repr=<flwr.simulation.ray_transport.ray_actor.ClientAppActor object at 0x0000023F214E7160>)
  File "python\ray\_raylet.pyx", line 1418, in ray._raylet.execute_task
  File "python\ray\_raylet.pyx", line 1498, in ray._raylet.execute_task
  File "python\ray\_raylet.pyx", line 1424, in ray._raylet.execute_task
  File "python\ray\_raylet.pyx", line 1364, in ray._raylet.execute_task.function_executor
  File "C:\Users\jyaka\anaconda3\envs\flower\lib\site-packages\ray\_private\function_manager.py", line 726, in actor_method_executor
    return method(__ray_actor, *args, **kwargs)
  File "C:\Users\jyaka\anaconda3\envs\flower\lib\site-packages\ray\util\tracing\tracing_helper.py", line 464, in _resume_span
    return method(self, *_args, **_kwargs)
  File "C:\Users\jyaka\anaconda3\envs\flower\lib\site-packages\flwr\simulation\ray_transport\ray_actor.py", line 64, in run
    raise ClientAppException(str(ex)) from ex
flwr.client.client_app.ClientAppException: 
Exception ClientAppException occurred. Message: 'epochs'
[2024-05-11 21:01:31,544][flwr][INFO] - aggregate_fit: received 0 results and 1 failures
[2024-05-11 21:01:31,545][flwr][INFO] - configure_evaluate: strategy sampled 2 clients (out of 2)
[2024-05-11 21:01:31,556][flwr][ERROR] - Traceback (most recent call last):
  File "C:\Users\jyaka\anaconda3\envs\flower\lib\site-packages\flwr\simulation\ray_transport\ray_client_proxy.py", line 73, in _submit_job
    out_mssg, updated_context = self.actor_pool.get_client_result(
  File "C:\Users\jyaka\anaconda3\envs\flower\lib\site-packages\flwr\simulation\ray_transport\ray_actor.py", line 399, in get_client_result
    return self._fetch_future_result(cid)
  File "C:\Users\jyaka\anaconda3\envs\flower\lib\site-packages\flwr\simulation\ray_transport\ray_actor.py", line 280, in _fetch_future_result
    res_cid, out_mssg, updated_context = ray.get(
  File "C:\Users\jyaka\anaconda3\envs\flower\lib\site-packages\ray\_private\auto_init_hook.py", line 24, in auto_init_wrapper
    return fn(*args, **kwargs)
  File "C:\Users\jyaka\anaconda3\envs\flower\lib\site-packages\ray\_private\client_mode_hook.py", line 103, in wrapper
    return func(*args, **kwargs)
  File "C:\Users\jyaka\anaconda3\envs\flower\lib\site-packages\ray\_private\worker.py", line 2524, in get
    raise value.as_instanceof_cause()
ray.exceptions.RayTaskError(ClientAppException): [36mray::ClientAppActor.run()[39m (pid=24760, ip=127.0.0.1, actor_id=0bda77c27b6b10b0fe356e3b01000000, repr=<flwr.simulation.ray_transport.ray_actor.ClientAppActor object at 0x0000023F214E7160>)
  File "C:\Users\jyaka\anaconda3\envs\flower\lib\site-packages\flwr\client\client_app.py", line 98, in __call__
    return self._call(message, context)
  File "C:\Users\jyaka\anaconda3\envs\flower\lib\site-packages\flwr\client\client_app.py", line 81, in ffn
    out_message = handle_legacy_message_from_msgtype(
  File "C:\Users\jyaka\anaconda3\envs\flower\lib\site-packages\flwr\client\message_handler\message_handler.py", line 137, in handle_legacy_message_from_msgtype
    evaluate_res = maybe_call_evaluate(
  File "C:\Users\jyaka\anaconda3\envs\flower\lib\site-packages\flwr\client\client.py", line 254, in maybe_call_evaluate
    return client.evaluate(evaluate_ins)
  File "C:\Users\jyaka\anaconda3\envs\flower\lib\site-packages\flwr\client\numpy_client.py", line 262, in _evaluate
    results = self.numpy_client.evaluate(parameters, ins.config)  # type: ignore
  File "C:\Users\jyaka\Documents\research\flower_tutorial\client.py", line 45, in evaluate
    self.set_parameters(self.model, parameters)
TypeError: set_parameters() takes 2 positional arguments but 3 were given

The above exception was the direct cause of the following exception:

[36mray::ClientAppActor.run()[39m (pid=24760, ip=127.0.0.1, actor_id=0bda77c27b6b10b0fe356e3b01000000, repr=<flwr.simulation.ray_transport.ray_actor.ClientAppActor object at 0x0000023F214E7160>)
  File "python\ray\_raylet.pyx", line 1418, in ray._raylet.execute_task
  File "python\ray\_raylet.pyx", line 1498, in ray._raylet.execute_task
  File "python\ray\_raylet.pyx", line 1424, in ray._raylet.execute_task
  File "python\ray\_raylet.pyx", line 1364, in ray._raylet.execute_task.function_executor
  File "C:\Users\jyaka\anaconda3\envs\flower\lib\site-packages\ray\_private\function_manager.py", line 726, in actor_method_executor
    return method(__ray_actor, *args, **kwargs)
  File "C:\Users\jyaka\anaconda3\envs\flower\lib\site-packages\ray\util\tracing\tracing_helper.py", line 464, in _resume_span
    return method(self, *_args, **_kwargs)
  File "C:\Users\jyaka\anaconda3\envs\flower\lib\site-packages\flwr\simulation\ray_transport\ray_actor.py", line 64, in run
    raise ClientAppException(str(ex)) from ex
flwr.client.client_app.ClientAppException: 
Exception ClientAppException occurred. Message: set_parameters() takes 2 positional arguments but 3 were given

[2024-05-11 21:01:31,559][flwr][ERROR] - Traceback (most recent call last):
  File "C:\Users\jyaka\anaconda3\envs\flower\lib\site-packages\flwr\simulation\ray_transport\ray_client_proxy.py", line 73, in _submit_job
    out_mssg, updated_context = self.actor_pool.get_client_result(
  File "C:\Users\jyaka\anaconda3\envs\flower\lib\site-packages\flwr\simulation\ray_transport\ray_actor.py", line 399, in get_client_result
    return self._fetch_future_result(cid)
  File "C:\Users\jyaka\anaconda3\envs\flower\lib\site-packages\flwr\simulation\ray_transport\ray_actor.py", line 280, in _fetch_future_result
    res_cid, out_mssg, updated_context = ray.get(
  File "C:\Users\jyaka\anaconda3\envs\flower\lib\site-packages\ray\_private\auto_init_hook.py", line 24, in auto_init_wrapper
    return fn(*args, **kwargs)
  File "C:\Users\jyaka\anaconda3\envs\flower\lib\site-packages\ray\_private\client_mode_hook.py", line 103, in wrapper
    return func(*args, **kwargs)
  File "C:\Users\jyaka\anaconda3\envs\flower\lib\site-packages\ray\_private\worker.py", line 2524, in get
    raise value.as_instanceof_cause()
ray.exceptions.RayTaskError(ClientAppException): [36mray::ClientAppActor.run()[39m (pid=9728, ip=127.0.0.1, actor_id=449d6fb233f4c3623911c51301000000, repr=<flwr.simulation.ray_transport.ray_actor.ClientAppActor object at 0x000001709AF0B0D0>)
  File "C:\Users\jyaka\anaconda3\envs\flower\lib\site-packages\flwr\client\client_app.py", line 98, in __call__
    return self._call(message, context)
  File "C:\Users\jyaka\anaconda3\envs\flower\lib\site-packages\flwr\client\client_app.py", line 81, in ffn
    out_message = handle_legacy_message_from_msgtype(
  File "C:\Users\jyaka\anaconda3\envs\flower\lib\site-packages\flwr\client\message_handler\message_handler.py", line 137, in handle_legacy_message_from_msgtype
    evaluate_res = maybe_call_evaluate(
  File "C:\Users\jyaka\anaconda3\envs\flower\lib\site-packages\flwr\client\client.py", line 254, in maybe_call_evaluate
    return client.evaluate(evaluate_ins)
  File "C:\Users\jyaka\anaconda3\envs\flower\lib\site-packages\flwr\client\numpy_client.py", line 262, in _evaluate
    results = self.numpy_client.evaluate(parameters, ins.config)  # type: ignore
  File "C:\Users\jyaka\Documents\research\flower_tutorial\client.py", line 45, in evaluate
    self.set_parameters(self.model, parameters)
TypeError: set_parameters() takes 2 positional arguments but 3 were given

The above exception was the direct cause of the following exception:

[36mray::ClientAppActor.run()[39m (pid=9728, ip=127.0.0.1, actor_id=449d6fb233f4c3623911c51301000000, repr=<flwr.simulation.ray_transport.ray_actor.ClientAppActor object at 0x000001709AF0B0D0>)
  File "python\ray\_raylet.pyx", line 1418, in ray._raylet.execute_task
  File "python\ray\_raylet.pyx", line 1498, in ray._raylet.execute_task
  File "python\ray\_raylet.pyx", line 1424, in ray._raylet.execute_task
  File "python\ray\_raylet.pyx", line 1364, in ray._raylet.execute_task.function_executor
  File "C:\Users\jyaka\anaconda3\envs\flower\lib\site-packages\ray\_private\function_manager.py", line 726, in actor_method_executor
    return method(__ray_actor, *args, **kwargs)
  File "C:\Users\jyaka\anaconda3\envs\flower\lib\site-packages\ray\util\tracing\tracing_helper.py", line 464, in _resume_span
    return method(self, *_args, **_kwargs)
  File "C:\Users\jyaka\anaconda3\envs\flower\lib\site-packages\flwr\simulation\ray_transport\ray_actor.py", line 64, in run
    raise ClientAppException(str(ex)) from ex
flwr.client.client_app.ClientAppException: 
Exception ClientAppException occurred. Message: set_parameters() takes 2 positional arguments but 3 were given

[2024-05-11 21:01:31,567][flwr][ERROR] - [36mray::ClientAppActor.run()[39m (pid=24760, ip=127.0.0.1, actor_id=0bda77c27b6b10b0fe356e3b01000000, repr=<flwr.simulation.ray_transport.ray_actor.ClientAppActor object at 0x0000023F214E7160>)
  File "C:\Users\jyaka\anaconda3\envs\flower\lib\site-packages\flwr\client\client_app.py", line 98, in __call__
    return self._call(message, context)
  File "C:\Users\jyaka\anaconda3\envs\flower\lib\site-packages\flwr\client\client_app.py", line 81, in ffn
    out_message = handle_legacy_message_from_msgtype(
  File "C:\Users\jyaka\anaconda3\envs\flower\lib\site-packages\flwr\client\message_handler\message_handler.py", line 137, in handle_legacy_message_from_msgtype
    evaluate_res = maybe_call_evaluate(
  File "C:\Users\jyaka\anaconda3\envs\flower\lib\site-packages\flwr\client\client.py", line 254, in maybe_call_evaluate
    return client.evaluate(evaluate_ins)
  File "C:\Users\jyaka\anaconda3\envs\flower\lib\site-packages\flwr\client\numpy_client.py", line 262, in _evaluate
    results = self.numpy_client.evaluate(parameters, ins.config)  # type: ignore
  File "C:\Users\jyaka\Documents\research\flower_tutorial\client.py", line 45, in evaluate
    self.set_parameters(self.model, parameters)
TypeError: set_parameters() takes 2 positional arguments but 3 were given

The above exception was the direct cause of the following exception:

[36mray::ClientAppActor.run()[39m (pid=24760, ip=127.0.0.1, actor_id=0bda77c27b6b10b0fe356e3b01000000, repr=<flwr.simulation.ray_transport.ray_actor.ClientAppActor object at 0x0000023F214E7160>)
  File "python\ray\_raylet.pyx", line 1418, in ray._raylet.execute_task
  File "python\ray\_raylet.pyx", line 1498, in ray._raylet.execute_task
  File "python\ray\_raylet.pyx", line 1424, in ray._raylet.execute_task
  File "python\ray\_raylet.pyx", line 1364, in ray._raylet.execute_task.function_executor
  File "C:\Users\jyaka\anaconda3\envs\flower\lib\site-packages\ray\_private\function_manager.py", line 726, in actor_method_executor
    return method(__ray_actor, *args, **kwargs)
  File "C:\Users\jyaka\anaconda3\envs\flower\lib\site-packages\ray\util\tracing\tracing_helper.py", line 464, in _resume_span
    return method(self, *_args, **_kwargs)
  File "C:\Users\jyaka\anaconda3\envs\flower\lib\site-packages\flwr\simulation\ray_transport\ray_actor.py", line 64, in run
    raise ClientAppException(str(ex)) from ex
flwr.client.client_app.ClientAppException: 
Exception ClientAppException occurred. Message: set_parameters() takes 2 positional arguments but 3 were given
[2024-05-11 21:01:31,574][flwr][ERROR] - [36mray::ClientAppActor.run()[39m (pid=9728, ip=127.0.0.1, actor_id=449d6fb233f4c3623911c51301000000, repr=<flwr.simulation.ray_transport.ray_actor.ClientAppActor object at 0x000001709AF0B0D0>)
  File "C:\Users\jyaka\anaconda3\envs\flower\lib\site-packages\flwr\client\client_app.py", line 98, in __call__
    return self._call(message, context)
  File "C:\Users\jyaka\anaconda3\envs\flower\lib\site-packages\flwr\client\client_app.py", line 81, in ffn
    out_message = handle_legacy_message_from_msgtype(
  File "C:\Users\jyaka\anaconda3\envs\flower\lib\site-packages\flwr\client\message_handler\message_handler.py", line 137, in handle_legacy_message_from_msgtype
    evaluate_res = maybe_call_evaluate(
  File "C:\Users\jyaka\anaconda3\envs\flower\lib\site-packages\flwr\client\client.py", line 254, in maybe_call_evaluate
    return client.evaluate(evaluate_ins)
  File "C:\Users\jyaka\anaconda3\envs\flower\lib\site-packages\flwr\client\numpy_client.py", line 262, in _evaluate
    results = self.numpy_client.evaluate(parameters, ins.config)  # type: ignore
  File "C:\Users\jyaka\Documents\research\flower_tutorial\client.py", line 45, in evaluate
    self.set_parameters(self.model, parameters)
TypeError: set_parameters() takes 2 positional arguments but 3 were given

The above exception was the direct cause of the following exception:

[36mray::ClientAppActor.run()[39m (pid=9728, ip=127.0.0.1, actor_id=449d6fb233f4c3623911c51301000000, repr=<flwr.simulation.ray_transport.ray_actor.ClientAppActor object at 0x000001709AF0B0D0>)
  File "python\ray\_raylet.pyx", line 1418, in ray._raylet.execute_task
  File "python\ray\_raylet.pyx", line 1498, in ray._raylet.execute_task
  File "python\ray\_raylet.pyx", line 1424, in ray._raylet.execute_task
  File "python\ray\_raylet.pyx", line 1364, in ray._raylet.execute_task.function_executor
  File "C:\Users\jyaka\anaconda3\envs\flower\lib\site-packages\ray\_private\function_manager.py", line 726, in actor_method_executor
    return method(__ray_actor, *args, **kwargs)
  File "C:\Users\jyaka\anaconda3\envs\flower\lib\site-packages\ray\util\tracing\tracing_helper.py", line 464, in _resume_span
    return method(self, *_args, **_kwargs)
  File "C:\Users\jyaka\anaconda3\envs\flower\lib\site-packages\flwr\simulation\ray_transport\ray_actor.py", line 64, in run
    raise ClientAppException(str(ex)) from ex
flwr.client.client_app.ClientAppException: 
Exception ClientAppException occurred. Message: set_parameters() takes 2 positional arguments but 3 were given
[2024-05-11 21:01:31,584][flwr][INFO] - aggregate_evaluate: received 0 results and 2 failures
[2024-05-11 21:01:31,585][flwr][INFO] - 
[2024-05-11 21:01:31,586][flwr][INFO] - [ROUND 10]
[2024-05-11 21:01:31,586][flwr][INFO] - configure_fit: strategy sampled 1 clients (out of 2)
[2024-05-11 21:01:31,597][flwr][ERROR] - Traceback (most recent call last):
  File "C:\Users\jyaka\anaconda3\envs\flower\lib\site-packages\flwr\simulation\ray_transport\ray_client_proxy.py", line 73, in _submit_job
    out_mssg, updated_context = self.actor_pool.get_client_result(
  File "C:\Users\jyaka\anaconda3\envs\flower\lib\site-packages\flwr\simulation\ray_transport\ray_actor.py", line 399, in get_client_result
    return self._fetch_future_result(cid)
  File "C:\Users\jyaka\anaconda3\envs\flower\lib\site-packages\flwr\simulation\ray_transport\ray_actor.py", line 280, in _fetch_future_result
    res_cid, out_mssg, updated_context = ray.get(
  File "C:\Users\jyaka\anaconda3\envs\flower\lib\site-packages\ray\_private\auto_init_hook.py", line 24, in auto_init_wrapper
    return fn(*args, **kwargs)
  File "C:\Users\jyaka\anaconda3\envs\flower\lib\site-packages\ray\_private\client_mode_hook.py", line 103, in wrapper
    return func(*args, **kwargs)
  File "C:\Users\jyaka\anaconda3\envs\flower\lib\site-packages\ray\_private\worker.py", line 2524, in get
    raise value.as_instanceof_cause()
ray.exceptions.RayTaskError(ClientAppException): [36mray::ClientAppActor.run()[39m (pid=9728, ip=127.0.0.1, actor_id=449d6fb233f4c3623911c51301000000, repr=<flwr.simulation.ray_transport.ray_actor.ClientAppActor object at 0x000001709AF0B0D0>)
  File "C:\Users\jyaka\anaconda3\envs\flower\lib\site-packages\flwr\client\client_app.py", line 98, in __call__
    return self._call(message, context)
  File "C:\Users\jyaka\anaconda3\envs\flower\lib\site-packages\flwr\client\client_app.py", line 81, in ffn
    out_message = handle_legacy_message_from_msgtype(
  File "C:\Users\jyaka\anaconda3\envs\flower\lib\site-packages\flwr\client\message_handler\message_handler.py", line 130, in handle_legacy_message_from_msgtype
    fit_res = maybe_call_fit(
  File "C:\Users\jyaka\anaconda3\envs\flower\lib\site-packages\flwr\client\client.py", line 234, in maybe_call_fit
    return client.fit(fit_ins)
  File "C:\Users\jyaka\anaconda3\envs\flower\lib\site-packages\flwr\client\numpy_client.py", line 238, in _fit
    results = self.numpy_client.fit(parameters, ins.config)  # type: ignore
  File "C:\Users\jyaka\Documents\research\flower_tutorial\client.py", line 37, in fit
    epochs = config["epochs"]
KeyError: 'epochs'

The above exception was the direct cause of the following exception:

[36mray::ClientAppActor.run()[39m (pid=9728, ip=127.0.0.1, actor_id=449d6fb233f4c3623911c51301000000, repr=<flwr.simulation.ray_transport.ray_actor.ClientAppActor object at 0x000001709AF0B0D0>)
  File "python\ray\_raylet.pyx", line 1418, in ray._raylet.execute_task
  File "python\ray\_raylet.pyx", line 1498, in ray._raylet.execute_task
  File "python\ray\_raylet.pyx", line 1424, in ray._raylet.execute_task
  File "python\ray\_raylet.pyx", line 1364, in ray._raylet.execute_task.function_executor
  File "C:\Users\jyaka\anaconda3\envs\flower\lib\site-packages\ray\_private\function_manager.py", line 726, in actor_method_executor
    return method(__ray_actor, *args, **kwargs)
  File "C:\Users\jyaka\anaconda3\envs\flower\lib\site-packages\ray\util\tracing\tracing_helper.py", line 464, in _resume_span
    return method(self, *_args, **_kwargs)
  File "C:\Users\jyaka\anaconda3\envs\flower\lib\site-packages\flwr\simulation\ray_transport\ray_actor.py", line 64, in run
    raise ClientAppException(str(ex)) from ex
flwr.client.client_app.ClientAppException: 
Exception ClientAppException occurred. Message: 'epochs'

[2024-05-11 21:01:31,609][flwr][ERROR] - [36mray::ClientAppActor.run()[39m (pid=9728, ip=127.0.0.1, actor_id=449d6fb233f4c3623911c51301000000, repr=<flwr.simulation.ray_transport.ray_actor.ClientAppActor object at 0x000001709AF0B0D0>)
  File "C:\Users\jyaka\anaconda3\envs\flower\lib\site-packages\flwr\client\client_app.py", line 98, in __call__
    return self._call(message, context)
  File "C:\Users\jyaka\anaconda3\envs\flower\lib\site-packages\flwr\client\client_app.py", line 81, in ffn
    out_message = handle_legacy_message_from_msgtype(
  File "C:\Users\jyaka\anaconda3\envs\flower\lib\site-packages\flwr\client\message_handler\message_handler.py", line 130, in handle_legacy_message_from_msgtype
    fit_res = maybe_call_fit(
  File "C:\Users\jyaka\anaconda3\envs\flower\lib\site-packages\flwr\client\client.py", line 234, in maybe_call_fit
    return client.fit(fit_ins)
  File "C:\Users\jyaka\anaconda3\envs\flower\lib\site-packages\flwr\client\numpy_client.py", line 238, in _fit
    results = self.numpy_client.fit(parameters, ins.config)  # type: ignore
  File "C:\Users\jyaka\Documents\research\flower_tutorial\client.py", line 37, in fit
    epochs = config["epochs"]
KeyError: 'epochs'

The above exception was the direct cause of the following exception:

[36mray::ClientAppActor.run()[39m (pid=9728, ip=127.0.0.1, actor_id=449d6fb233f4c3623911c51301000000, repr=<flwr.simulation.ray_transport.ray_actor.ClientAppActor object at 0x000001709AF0B0D0>)
  File "python\ray\_raylet.pyx", line 1418, in ray._raylet.execute_task
  File "python\ray\_raylet.pyx", line 1498, in ray._raylet.execute_task
  File "python\ray\_raylet.pyx", line 1424, in ray._raylet.execute_task
  File "python\ray\_raylet.pyx", line 1364, in ray._raylet.execute_task.function_executor
  File "C:\Users\jyaka\anaconda3\envs\flower\lib\site-packages\ray\_private\function_manager.py", line 726, in actor_method_executor
    return method(__ray_actor, *args, **kwargs)
  File "C:\Users\jyaka\anaconda3\envs\flower\lib\site-packages\ray\util\tracing\tracing_helper.py", line 464, in _resume_span
    return method(self, *_args, **_kwargs)
  File "C:\Users\jyaka\anaconda3\envs\flower\lib\site-packages\flwr\simulation\ray_transport\ray_actor.py", line 64, in run
    raise ClientAppException(str(ex)) from ex
flwr.client.client_app.ClientAppException: 
Exception ClientAppException occurred. Message: 'epochs'
[2024-05-11 21:01:31,615][flwr][INFO] - aggregate_fit: received 0 results and 1 failures
[2024-05-11 21:01:31,615][flwr][INFO] - configure_evaluate: strategy sampled 2 clients (out of 2)
[2024-05-11 21:01:31,628][flwr][ERROR] - Traceback (most recent call last):
  File "C:\Users\jyaka\anaconda3\envs\flower\lib\site-packages\flwr\simulation\ray_transport\ray_client_proxy.py", line 73, in _submit_job
    out_mssg, updated_context = self.actor_pool.get_client_result(
  File "C:\Users\jyaka\anaconda3\envs\flower\lib\site-packages\flwr\simulation\ray_transport\ray_actor.py", line 399, in get_client_result
    return self._fetch_future_result(cid)
  File "C:\Users\jyaka\anaconda3\envs\flower\lib\site-packages\flwr\simulation\ray_transport\ray_actor.py", line 280, in _fetch_future_result
    res_cid, out_mssg, updated_context = ray.get(
  File "C:\Users\jyaka\anaconda3\envs\flower\lib\site-packages\ray\_private\auto_init_hook.py", line 24, in auto_init_wrapper
    return fn(*args, **kwargs)
  File "C:\Users\jyaka\anaconda3\envs\flower\lib\site-packages\ray\_private\client_mode_hook.py", line 103, in wrapper
    return func(*args, **kwargs)
  File "C:\Users\jyaka\anaconda3\envs\flower\lib\site-packages\ray\_private\worker.py", line 2524, in get
    raise value.as_instanceof_cause()
ray.exceptions.RayTaskError(ClientAppException): [36mray::ClientAppActor.run()[39m (pid=9728, ip=127.0.0.1, actor_id=449d6fb233f4c3623911c51301000000, repr=<flwr.simulation.ray_transport.ray_actor.ClientAppActor object at 0x000001709AF0B0D0>)
  File "C:\Users\jyaka\anaconda3\envs\flower\lib\site-packages\flwr\client\client_app.py", line 98, in __call__
    return self._call(message, context)
  File "C:\Users\jyaka\anaconda3\envs\flower\lib\site-packages\flwr\client\client_app.py", line 81, in ffn
    out_message = handle_legacy_message_from_msgtype(
  File "C:\Users\jyaka\anaconda3\envs\flower\lib\site-packages\flwr\client\message_handler\message_handler.py", line 137, in handle_legacy_message_from_msgtype
    evaluate_res = maybe_call_evaluate(
  File "C:\Users\jyaka\anaconda3\envs\flower\lib\site-packages\flwr\client\client.py", line 254, in maybe_call_evaluate
    return client.evaluate(evaluate_ins)
  File "C:\Users\jyaka\anaconda3\envs\flower\lib\site-packages\flwr\client\numpy_client.py", line 262, in _evaluate
    results = self.numpy_client.evaluate(parameters, ins.config)  # type: ignore
  File "C:\Users\jyaka\Documents\research\flower_tutorial\client.py", line 45, in evaluate
    self.set_parameters(self.model, parameters)
TypeError: set_parameters() takes 2 positional arguments but 3 were given

The above exception was the direct cause of the following exception:

[36mray::ClientAppActor.run()[39m (pid=9728, ip=127.0.0.1, actor_id=449d6fb233f4c3623911c51301000000, repr=<flwr.simulation.ray_transport.ray_actor.ClientAppActor object at 0x000001709AF0B0D0>)
  File "python\ray\_raylet.pyx", line 1418, in ray._raylet.execute_task
  File "python\ray\_raylet.pyx", line 1498, in ray._raylet.execute_task
  File "python\ray\_raylet.pyx", line 1424, in ray._raylet.execute_task
  File "python\ray\_raylet.pyx", line 1364, in ray._raylet.execute_task.function_executor
  File "C:\Users\jyaka\anaconda3\envs\flower\lib\site-packages\ray\_private\function_manager.py", line 726, in actor_method_executor
    return method(__ray_actor, *args, **kwargs)
  File "C:\Users\jyaka\anaconda3\envs\flower\lib\site-packages\ray\util\tracing\tracing_helper.py", line 464, in _resume_span
    return method(self, *_args, **_kwargs)
  File "C:\Users\jyaka\anaconda3\envs\flower\lib\site-packages\flwr\simulation\ray_transport\ray_actor.py", line 64, in run
    raise ClientAppException(str(ex)) from ex
flwr.client.client_app.ClientAppException: 
Exception ClientAppException occurred. Message: set_parameters() takes 2 positional arguments but 3 were given

[2024-05-11 21:01:31,632][flwr][ERROR] - Traceback (most recent call last):
  File "C:\Users\jyaka\anaconda3\envs\flower\lib\site-packages\flwr\simulation\ray_transport\ray_client_proxy.py", line 73, in _submit_job
    out_mssg, updated_context = self.actor_pool.get_client_result(
  File "C:\Users\jyaka\anaconda3\envs\flower\lib\site-packages\flwr\simulation\ray_transport\ray_actor.py", line 399, in get_client_result
    return self._fetch_future_result(cid)
  File "C:\Users\jyaka\anaconda3\envs\flower\lib\site-packages\flwr\simulation\ray_transport\ray_actor.py", line 280, in _fetch_future_result
    res_cid, out_mssg, updated_context = ray.get(
  File "C:\Users\jyaka\anaconda3\envs\flower\lib\site-packages\ray\_private\auto_init_hook.py", line 24, in auto_init_wrapper
    return fn(*args, **kwargs)
  File "C:\Users\jyaka\anaconda3\envs\flower\lib\site-packages\ray\_private\client_mode_hook.py", line 103, in wrapper
    return func(*args, **kwargs)
  File "C:\Users\jyaka\anaconda3\envs\flower\lib\site-packages\ray\_private\worker.py", line 2524, in get
    raise value.as_instanceof_cause()
ray.exceptions.RayTaskError(ClientAppException): [36mray::ClientAppActor.run()[39m (pid=24760, ip=127.0.0.1, actor_id=0bda77c27b6b10b0fe356e3b01000000, repr=<flwr.simulation.ray_transport.ray_actor.ClientAppActor object at 0x0000023F214E7160>)
  File "C:\Users\jyaka\anaconda3\envs\flower\lib\site-packages\flwr\client\client_app.py", line 98, in __call__
    return self._call(message, context)
  File "C:\Users\jyaka\anaconda3\envs\flower\lib\site-packages\flwr\client\client_app.py", line 81, in ffn
    out_message = handle_legacy_message_from_msgtype(
  File "C:\Users\jyaka\anaconda3\envs\flower\lib\site-packages\flwr\client\message_handler\message_handler.py", line 137, in handle_legacy_message_from_msgtype
    evaluate_res = maybe_call_evaluate(
  File "C:\Users\jyaka\anaconda3\envs\flower\lib\site-packages\flwr\client\client.py", line 254, in maybe_call_evaluate
    return client.evaluate(evaluate_ins)
  File "C:\Users\jyaka\anaconda3\envs\flower\lib\site-packages\flwr\client\numpy_client.py", line 262, in _evaluate
    results = self.numpy_client.evaluate(parameters, ins.config)  # type: ignore
  File "C:\Users\jyaka\Documents\research\flower_tutorial\client.py", line 45, in evaluate
    self.set_parameters(self.model, parameters)
TypeError: set_parameters() takes 2 positional arguments but 3 were given

The above exception was the direct cause of the following exception:

[36mray::ClientAppActor.run()[39m (pid=24760, ip=127.0.0.1, actor_id=0bda77c27b6b10b0fe356e3b01000000, repr=<flwr.simulation.ray_transport.ray_actor.ClientAppActor object at 0x0000023F214E7160>)
  File "python\ray\_raylet.pyx", line 1418, in ray._raylet.execute_task
  File "python\ray\_raylet.pyx", line 1498, in ray._raylet.execute_task
  File "python\ray\_raylet.pyx", line 1424, in ray._raylet.execute_task
  File "python\ray\_raylet.pyx", line 1364, in ray._raylet.execute_task.function_executor
  File "C:\Users\jyaka\anaconda3\envs\flower\lib\site-packages\ray\_private\function_manager.py", line 726, in actor_method_executor
    return method(__ray_actor, *args, **kwargs)
  File "C:\Users\jyaka\anaconda3\envs\flower\lib\site-packages\ray\util\tracing\tracing_helper.py", line 464, in _resume_span
    return method(self, *_args, **_kwargs)
  File "C:\Users\jyaka\anaconda3\envs\flower\lib\site-packages\flwr\simulation\ray_transport\ray_actor.py", line 64, in run
    raise ClientAppException(str(ex)) from ex
flwr.client.client_app.ClientAppException: 
Exception ClientAppException occurred. Message: set_parameters() takes 2 positional arguments but 3 were given

[2024-05-11 21:01:31,641][flwr][ERROR] - [36mray::ClientAppActor.run()[39m (pid=9728, ip=127.0.0.1, actor_id=449d6fb233f4c3623911c51301000000, repr=<flwr.simulation.ray_transport.ray_actor.ClientAppActor object at 0x000001709AF0B0D0>)
  File "C:\Users\jyaka\anaconda3\envs\flower\lib\site-packages\flwr\client\client_app.py", line 98, in __call__
    return self._call(message, context)
  File "C:\Users\jyaka\anaconda3\envs\flower\lib\site-packages\flwr\client\client_app.py", line 81, in ffn
    out_message = handle_legacy_message_from_msgtype(
  File "C:\Users\jyaka\anaconda3\envs\flower\lib\site-packages\flwr\client\message_handler\message_handler.py", line 137, in handle_legacy_message_from_msgtype
    evaluate_res = maybe_call_evaluate(
  File "C:\Users\jyaka\anaconda3\envs\flower\lib\site-packages\flwr\client\client.py", line 254, in maybe_call_evaluate
    return client.evaluate(evaluate_ins)
  File "C:\Users\jyaka\anaconda3\envs\flower\lib\site-packages\flwr\client\numpy_client.py", line 262, in _evaluate
    results = self.numpy_client.evaluate(parameters, ins.config)  # type: ignore
  File "C:\Users\jyaka\Documents\research\flower_tutorial\client.py", line 45, in evaluate
    self.set_parameters(self.model, parameters)
TypeError: set_parameters() takes 2 positional arguments but 3 were given

The above exception was the direct cause of the following exception:

[36mray::ClientAppActor.run()[39m (pid=9728, ip=127.0.0.1, actor_id=449d6fb233f4c3623911c51301000000, repr=<flwr.simulation.ray_transport.ray_actor.ClientAppActor object at 0x000001709AF0B0D0>)
  File "python\ray\_raylet.pyx", line 1418, in ray._raylet.execute_task
  File "python\ray\_raylet.pyx", line 1498, in ray._raylet.execute_task
  File "python\ray\_raylet.pyx", line 1424, in ray._raylet.execute_task
  File "python\ray\_raylet.pyx", line 1364, in ray._raylet.execute_task.function_executor
  File "C:\Users\jyaka\anaconda3\envs\flower\lib\site-packages\ray\_private\function_manager.py", line 726, in actor_method_executor
    return method(__ray_actor, *args, **kwargs)
  File "C:\Users\jyaka\anaconda3\envs\flower\lib\site-packages\ray\util\tracing\tracing_helper.py", line 464, in _resume_span
    return method(self, *_args, **_kwargs)
  File "C:\Users\jyaka\anaconda3\envs\flower\lib\site-packages\flwr\simulation\ray_transport\ray_actor.py", line 64, in run
    raise ClientAppException(str(ex)) from ex
flwr.client.client_app.ClientAppException: 
Exception ClientAppException occurred. Message: set_parameters() takes 2 positional arguments but 3 were given
[2024-05-11 21:01:31,652][flwr][ERROR] - [36mray::ClientAppActor.run()[39m (pid=24760, ip=127.0.0.1, actor_id=0bda77c27b6b10b0fe356e3b01000000, repr=<flwr.simulation.ray_transport.ray_actor.ClientAppActor object at 0x0000023F214E7160>)
  File "C:\Users\jyaka\anaconda3\envs\flower\lib\site-packages\flwr\client\client_app.py", line 98, in __call__
    return self._call(message, context)
  File "C:\Users\jyaka\anaconda3\envs\flower\lib\site-packages\flwr\client\client_app.py", line 81, in ffn
    out_message = handle_legacy_message_from_msgtype(
  File "C:\Users\jyaka\anaconda3\envs\flower\lib\site-packages\flwr\client\message_handler\message_handler.py", line 137, in handle_legacy_message_from_msgtype
    evaluate_res = maybe_call_evaluate(
  File "C:\Users\jyaka\anaconda3\envs\flower\lib\site-packages\flwr\client\client.py", line 254, in maybe_call_evaluate
    return client.evaluate(evaluate_ins)
  File "C:\Users\jyaka\anaconda3\envs\flower\lib\site-packages\flwr\client\numpy_client.py", line 262, in _evaluate
    results = self.numpy_client.evaluate(parameters, ins.config)  # type: ignore
  File "C:\Users\jyaka\Documents\research\flower_tutorial\client.py", line 45, in evaluate
    self.set_parameters(self.model, parameters)
TypeError: set_parameters() takes 2 positional arguments but 3 were given

The above exception was the direct cause of the following exception:

[36mray::ClientAppActor.run()[39m (pid=24760, ip=127.0.0.1, actor_id=0bda77c27b6b10b0fe356e3b01000000, repr=<flwr.simulation.ray_transport.ray_actor.ClientAppActor object at 0x0000023F214E7160>)
  File "python\ray\_raylet.pyx", line 1418, in ray._raylet.execute_task
  File "python\ray\_raylet.pyx", line 1498, in ray._raylet.execute_task
  File "python\ray\_raylet.pyx", line 1424, in ray._raylet.execute_task
  File "python\ray\_raylet.pyx", line 1364, in ray._raylet.execute_task.function_executor
  File "C:\Users\jyaka\anaconda3\envs\flower\lib\site-packages\ray\_private\function_manager.py", line 726, in actor_method_executor
    return method(__ray_actor, *args, **kwargs)
  File "C:\Users\jyaka\anaconda3\envs\flower\lib\site-packages\ray\util\tracing\tracing_helper.py", line 464, in _resume_span
    return method(self, *_args, **_kwargs)
  File "C:\Users\jyaka\anaconda3\envs\flower\lib\site-packages\flwr\simulation\ray_transport\ray_actor.py", line 64, in run
    raise ClientAppException(str(ex)) from ex
flwr.client.client_app.ClientAppException: 
Exception ClientAppException occurred. Message: set_parameters() takes 2 positional arguments but 3 were given
[2024-05-11 21:01:31,664][flwr][INFO] - aggregate_evaluate: received 0 results and 2 failures
[2024-05-11 21:01:31,665][flwr][INFO] - 
[2024-05-11 21:01:31,665][flwr][INFO] - [SUMMARY]
[2024-05-11 21:01:31,665][flwr][INFO] - Run finished 10 rounds in 3.46s
[2024-05-11 21:01:31,666][flwr][INFO] - 
