[2024-05-11 21:15:56,708][flwr][INFO] - Starting Flower simulation, config: num_rounds=2, no round_timeout
[2024-05-11 21:16:01,803][flwr][INFO] - Flower VCE: Ray initialized with resources: {'node:127.0.0.1': 1.0, 'object_store_memory': 5403640627.0, 'memory': 10807281255.0, 'node:__internal_head__': 1.0, 'CPU': 8.0}
[2024-05-11 21:16:01,804][flwr][INFO] - Optimize your simulation with Flower VCE: https://flower.ai/docs/framework/how-to-run-simulations.html
[2024-05-11 21:16:01,804][flwr][INFO] - No `client_resources` specified. Using minimal resources for clients.
[2024-05-11 21:16:01,805][flwr][INFO] - Flower VCE: Resources for each Virtual Client: {'num_cpus': 1, 'num_gpus': 0.0}
[2024-05-11 21:16:01,814][flwr][INFO] - Flower VCE: Creating VirtualClientEngineActorPool with 8 actors
[2024-05-11 21:16:01,815][flwr][INFO] - [INIT]
[2024-05-11 21:16:01,816][flwr][INFO] - Requesting initial parameters from one random client
[2024-05-11 21:16:06,455][flwr][INFO] - Received initial parameters from one random client
[2024-05-11 21:16:06,457][flwr][INFO] - Evaluating initial global parameters
[2024-05-11 21:16:06,457][flwr][INFO] - 
[2024-05-11 21:16:06,457][flwr][INFO] - [ROUND 1]
[2024-05-11 21:16:06,458][flwr][INFO] - configure_fit: strategy sampled 1 clients (out of 2)
[2024-05-11 21:16:10,733][flwr][INFO] - aggregate_fit: received 1 results and 0 failures
[2024-05-11 21:16:10,735][flwr][WARNING] - No fit_metrics_aggregation_fn provided
[2024-05-11 21:16:10,736][flwr][INFO] - configure_evaluate: strategy sampled 2 clients (out of 2)
[2024-05-11 21:16:10,753][flwr][ERROR] - Traceback (most recent call last):
  File "C:\Users\jyaka\anaconda3\envs\flower\lib\site-packages\flwr\simulation\ray_transport\ray_client_proxy.py", line 73, in _submit_job
    out_mssg, updated_context = self.actor_pool.get_client_result(
  File "C:\Users\jyaka\anaconda3\envs\flower\lib\site-packages\flwr\simulation\ray_transport\ray_actor.py", line 399, in get_client_result
    return self._fetch_future_result(cid)
  File "C:\Users\jyaka\anaconda3\envs\flower\lib\site-packages\flwr\simulation\ray_transport\ray_actor.py", line 280, in _fetch_future_result
    res_cid, out_mssg, updated_context = ray.get(
  File "C:\Users\jyaka\anaconda3\envs\flower\lib\site-packages\ray\_private\auto_init_hook.py", line 24, in auto_init_wrapper
    return fn(*args, **kwargs)
  File "C:\Users\jyaka\anaconda3\envs\flower\lib\site-packages\ray\_private\client_mode_hook.py", line 103, in wrapper
    return func(*args, **kwargs)
  File "C:\Users\jyaka\anaconda3\envs\flower\lib\site-packages\ray\_private\worker.py", line 2524, in get
    raise value.as_instanceof_cause()
ray.exceptions.RayTaskError(ClientAppException): [36mray::ClientAppActor.run()[39m (pid=21472, ip=127.0.0.1, actor_id=67e56616aa6c08eb5efc71c101000000, repr=<flwr.simulation.ray_transport.ray_actor.ClientAppActor object at 0x0000020949D380D0>)
  File "C:\Users\jyaka\anaconda3\envs\flower\lib\site-packages\flwr\client\client_app.py", line 98, in __call__
    return self._call(message, context)
  File "C:\Users\jyaka\anaconda3\envs\flower\lib\site-packages\flwr\client\client_app.py", line 81, in ffn
    out_message = handle_legacy_message_from_msgtype(
  File "C:\Users\jyaka\anaconda3\envs\flower\lib\site-packages\flwr\client\message_handler\message_handler.py", line 137, in handle_legacy_message_from_msgtype
    evaluate_res = maybe_call_evaluate(
  File "C:\Users\jyaka\anaconda3\envs\flower\lib\site-packages\flwr\client\client.py", line 254, in maybe_call_evaluate
    return client.evaluate(evaluate_ins)
  File "C:\Users\jyaka\anaconda3\envs\flower\lib\site-packages\flwr\client\numpy_client.py", line 262, in _evaluate
    results = self.numpy_client.evaluate(parameters, ins.config)  # type: ignore
  File "C:\Users\jyaka\Documents\research\flower_tutorial\client.py", line 50, in evaluate
    loss, accuracy = test(self.model, self.valloader)
  File "C:\Users\jyaka\Documents\research\flower_tutorial\centralized.py", line 108, in test
    net.test()
  File "C:\Users\jyaka\anaconda3\envs\flower\lib\site-packages\torch\nn\modules\module.py", line 1688, in __getattr__
    raise AttributeError(f"'{type(self).__name__}' object has no attribute '{name}'")
AttributeError: 'Net' object has no attribute 'test'

The above exception was the direct cause of the following exception:

[36mray::ClientAppActor.run()[39m (pid=21472, ip=127.0.0.1, actor_id=67e56616aa6c08eb5efc71c101000000, repr=<flwr.simulation.ray_transport.ray_actor.ClientAppActor object at 0x0000020949D380D0>)
  File "python\ray\_raylet.pyx", line 1418, in ray._raylet.execute_task
  File "python\ray\_raylet.pyx", line 1498, in ray._raylet.execute_task
  File "python\ray\_raylet.pyx", line 1424, in ray._raylet.execute_task
  File "python\ray\_raylet.pyx", line 1364, in ray._raylet.execute_task.function_executor
  File "C:\Users\jyaka\anaconda3\envs\flower\lib\site-packages\ray\_private\function_manager.py", line 726, in actor_method_executor
    return method(__ray_actor, *args, **kwargs)
  File "C:\Users\jyaka\anaconda3\envs\flower\lib\site-packages\ray\util\tracing\tracing_helper.py", line 464, in _resume_span
    return method(self, *_args, **_kwargs)
  File "C:\Users\jyaka\anaconda3\envs\flower\lib\site-packages\flwr\simulation\ray_transport\ray_actor.py", line 64, in run
    raise ClientAppException(str(ex)) from ex
flwr.client.client_app.ClientAppException: 
Exception ClientAppException occurred. Message: 'Net' object has no attribute 'test'

[2024-05-11 21:16:10,765][flwr][ERROR] - [36mray::ClientAppActor.run()[39m (pid=21472, ip=127.0.0.1, actor_id=67e56616aa6c08eb5efc71c101000000, repr=<flwr.simulation.ray_transport.ray_actor.ClientAppActor object at 0x0000020949D380D0>)
  File "C:\Users\jyaka\anaconda3\envs\flower\lib\site-packages\flwr\client\client_app.py", line 98, in __call__
    return self._call(message, context)
  File "C:\Users\jyaka\anaconda3\envs\flower\lib\site-packages\flwr\client\client_app.py", line 81, in ffn
    out_message = handle_legacy_message_from_msgtype(
  File "C:\Users\jyaka\anaconda3\envs\flower\lib\site-packages\flwr\client\message_handler\message_handler.py", line 137, in handle_legacy_message_from_msgtype
    evaluate_res = maybe_call_evaluate(
  File "C:\Users\jyaka\anaconda3\envs\flower\lib\site-packages\flwr\client\client.py", line 254, in maybe_call_evaluate
    return client.evaluate(evaluate_ins)
  File "C:\Users\jyaka\anaconda3\envs\flower\lib\site-packages\flwr\client\numpy_client.py", line 262, in _evaluate
    results = self.numpy_client.evaluate(parameters, ins.config)  # type: ignore
  File "C:\Users\jyaka\Documents\research\flower_tutorial\client.py", line 50, in evaluate
    loss, accuracy = test(self.model, self.valloader)
  File "C:\Users\jyaka\Documents\research\flower_tutorial\centralized.py", line 108, in test
    net.test()
  File "C:\Users\jyaka\anaconda3\envs\flower\lib\site-packages\torch\nn\modules\module.py", line 1688, in __getattr__
    raise AttributeError(f"'{type(self).__name__}' object has no attribute '{name}'")
AttributeError: 'Net' object has no attribute 'test'

The above exception was the direct cause of the following exception:

[36mray::ClientAppActor.run()[39m (pid=21472, ip=127.0.0.1, actor_id=67e56616aa6c08eb5efc71c101000000, repr=<flwr.simulation.ray_transport.ray_actor.ClientAppActor object at 0x0000020949D380D0>)
  File "python\ray\_raylet.pyx", line 1418, in ray._raylet.execute_task
  File "python\ray\_raylet.pyx", line 1498, in ray._raylet.execute_task
  File "python\ray\_raylet.pyx", line 1424, in ray._raylet.execute_task
  File "python\ray\_raylet.pyx", line 1364, in ray._raylet.execute_task.function_executor
  File "C:\Users\jyaka\anaconda3\envs\flower\lib\site-packages\ray\_private\function_manager.py", line 726, in actor_method_executor
    return method(__ray_actor, *args, **kwargs)
  File "C:\Users\jyaka\anaconda3\envs\flower\lib\site-packages\ray\util\tracing\tracing_helper.py", line 464, in _resume_span
    return method(self, *_args, **_kwargs)
  File "C:\Users\jyaka\anaconda3\envs\flower\lib\site-packages\flwr\simulation\ray_transport\ray_actor.py", line 64, in run
    raise ClientAppException(str(ex)) from ex
flwr.client.client_app.ClientAppException: 
Exception ClientAppException occurred. Message: 'Net' object has no attribute 'test'
[2024-05-11 21:16:13,467][flwr][ERROR] - Traceback (most recent call last):
  File "C:\Users\jyaka\anaconda3\envs\flower\lib\site-packages\flwr\simulation\ray_transport\ray_client_proxy.py", line 73, in _submit_job
    out_mssg, updated_context = self.actor_pool.get_client_result(
  File "C:\Users\jyaka\anaconda3\envs\flower\lib\site-packages\flwr\simulation\ray_transport\ray_actor.py", line 399, in get_client_result
    return self._fetch_future_result(cid)
  File "C:\Users\jyaka\anaconda3\envs\flower\lib\site-packages\flwr\simulation\ray_transport\ray_actor.py", line 280, in _fetch_future_result
    res_cid, out_mssg, updated_context = ray.get(
  File "C:\Users\jyaka\anaconda3\envs\flower\lib\site-packages\ray\_private\auto_init_hook.py", line 24, in auto_init_wrapper
    return fn(*args, **kwargs)
  File "C:\Users\jyaka\anaconda3\envs\flower\lib\site-packages\ray\_private\client_mode_hook.py", line 103, in wrapper
    return func(*args, **kwargs)
  File "C:\Users\jyaka\anaconda3\envs\flower\lib\site-packages\ray\_private\worker.py", line 2524, in get
    raise value.as_instanceof_cause()
ray.exceptions.RayTaskError(ClientAppException): [36mray::ClientAppActor.run()[39m (pid=16284, ip=127.0.0.1, actor_id=58b28ffec8e0f63ec8d7cc6701000000, repr=<flwr.simulation.ray_transport.ray_actor.ClientAppActor object at 0x000001FFD92780D0>)
  File "C:\Users\jyaka\anaconda3\envs\flower\lib\site-packages\flwr\client\client_app.py", line 98, in __call__
    return self._call(message, context)
  File "C:\Users\jyaka\anaconda3\envs\flower\lib\site-packages\flwr\client\client_app.py", line 81, in ffn
    out_message = handle_legacy_message_from_msgtype(
  File "C:\Users\jyaka\anaconda3\envs\flower\lib\site-packages\flwr\client\message_handler\message_handler.py", line 137, in handle_legacy_message_from_msgtype
    evaluate_res = maybe_call_evaluate(
  File "C:\Users\jyaka\anaconda3\envs\flower\lib\site-packages\flwr\client\client.py", line 254, in maybe_call_evaluate
    return client.evaluate(evaluate_ins)
  File "C:\Users\jyaka\anaconda3\envs\flower\lib\site-packages\flwr\client\numpy_client.py", line 262, in _evaluate
    results = self.numpy_client.evaluate(parameters, ins.config)  # type: ignore
  File "C:\Users\jyaka\Documents\research\flower_tutorial\client.py", line 50, in evaluate
    loss, accuracy = test(self.model, self.valloader)
  File "C:\Users\jyaka\Documents\research\flower_tutorial\centralized.py", line 108, in test
    net.test()
  File "C:\Users\jyaka\anaconda3\envs\flower\lib\site-packages\torch\nn\modules\module.py", line 1688, in __getattr__
    raise AttributeError(f"'{type(self).__name__}' object has no attribute '{name}'")
AttributeError: 'Net' object has no attribute 'test'

The above exception was the direct cause of the following exception:

[36mray::ClientAppActor.run()[39m (pid=16284, ip=127.0.0.1, actor_id=58b28ffec8e0f63ec8d7cc6701000000, repr=<flwr.simulation.ray_transport.ray_actor.ClientAppActor object at 0x000001FFD92780D0>)
  File "python\ray\_raylet.pyx", line 1418, in ray._raylet.execute_task
  File "python\ray\_raylet.pyx", line 1498, in ray._raylet.execute_task
  File "python\ray\_raylet.pyx", line 1424, in ray._raylet.execute_task
  File "python\ray\_raylet.pyx", line 1364, in ray._raylet.execute_task.function_executor
  File "C:\Users\jyaka\anaconda3\envs\flower\lib\site-packages\ray\_private\function_manager.py", line 726, in actor_method_executor
    return method(__ray_actor, *args, **kwargs)
  File "C:\Users\jyaka\anaconda3\envs\flower\lib\site-packages\ray\util\tracing\tracing_helper.py", line 464, in _resume_span
    return method(self, *_args, **_kwargs)
  File "C:\Users\jyaka\anaconda3\envs\flower\lib\site-packages\flwr\simulation\ray_transport\ray_actor.py", line 64, in run
    raise ClientAppException(str(ex)) from ex
flwr.client.client_app.ClientAppException: 
Exception ClientAppException occurred. Message: 'Net' object has no attribute 'test'

[2024-05-11 21:16:13,476][flwr][ERROR] - [36mray::ClientAppActor.run()[39m (pid=16284, ip=127.0.0.1, actor_id=58b28ffec8e0f63ec8d7cc6701000000, repr=<flwr.simulation.ray_transport.ray_actor.ClientAppActor object at 0x000001FFD92780D0>)
  File "C:\Users\jyaka\anaconda3\envs\flower\lib\site-packages\flwr\client\client_app.py", line 98, in __call__
    return self._call(message, context)
  File "C:\Users\jyaka\anaconda3\envs\flower\lib\site-packages\flwr\client\client_app.py", line 81, in ffn
    out_message = handle_legacy_message_from_msgtype(
  File "C:\Users\jyaka\anaconda3\envs\flower\lib\site-packages\flwr\client\message_handler\message_handler.py", line 137, in handle_legacy_message_from_msgtype
    evaluate_res = maybe_call_evaluate(
  File "C:\Users\jyaka\anaconda3\envs\flower\lib\site-packages\flwr\client\client.py", line 254, in maybe_call_evaluate
    return client.evaluate(evaluate_ins)
  File "C:\Users\jyaka\anaconda3\envs\flower\lib\site-packages\flwr\client\numpy_client.py", line 262, in _evaluate
    results = self.numpy_client.evaluate(parameters, ins.config)  # type: ignore
  File "C:\Users\jyaka\Documents\research\flower_tutorial\client.py", line 50, in evaluate
    loss, accuracy = test(self.model, self.valloader)
  File "C:\Users\jyaka\Documents\research\flower_tutorial\centralized.py", line 108, in test
    net.test()
  File "C:\Users\jyaka\anaconda3\envs\flower\lib\site-packages\torch\nn\modules\module.py", line 1688, in __getattr__
    raise AttributeError(f"'{type(self).__name__}' object has no attribute '{name}'")
AttributeError: 'Net' object has no attribute 'test'

The above exception was the direct cause of the following exception:

[36mray::ClientAppActor.run()[39m (pid=16284, ip=127.0.0.1, actor_id=58b28ffec8e0f63ec8d7cc6701000000, repr=<flwr.simulation.ray_transport.ray_actor.ClientAppActor object at 0x000001FFD92780D0>)
  File "python\ray\_raylet.pyx", line 1418, in ray._raylet.execute_task
  File "python\ray\_raylet.pyx", line 1498, in ray._raylet.execute_task
  File "python\ray\_raylet.pyx", line 1424, in ray._raylet.execute_task
  File "python\ray\_raylet.pyx", line 1364, in ray._raylet.execute_task.function_executor
  File "C:\Users\jyaka\anaconda3\envs\flower\lib\site-packages\ray\_private\function_manager.py", line 726, in actor_method_executor
    return method(__ray_actor, *args, **kwargs)
  File "C:\Users\jyaka\anaconda3\envs\flower\lib\site-packages\ray\util\tracing\tracing_helper.py", line 464, in _resume_span
    return method(self, *_args, **_kwargs)
  File "C:\Users\jyaka\anaconda3\envs\flower\lib\site-packages\flwr\simulation\ray_transport\ray_actor.py", line 64, in run
    raise ClientAppException(str(ex)) from ex
flwr.client.client_app.ClientAppException: 
Exception ClientAppException occurred. Message: 'Net' object has no attribute 'test'
[2024-05-11 21:16:13,482][flwr][INFO] - aggregate_evaluate: received 0 results and 2 failures
[2024-05-11 21:16:13,482][flwr][INFO] - 
[2024-05-11 21:16:13,482][flwr][INFO] - [ROUND 2]
[2024-05-11 21:16:13,483][flwr][INFO] - configure_fit: strategy sampled 1 clients (out of 2)
[2024-05-11 21:16:17,869][flwr][INFO] - aggregate_fit: received 1 results and 0 failures
[2024-05-11 21:16:17,870][flwr][INFO] - configure_evaluate: strategy sampled 2 clients (out of 2)
[2024-05-11 21:16:17,883][flwr][ERROR] - Traceback (most recent call last):
  File "C:\Users\jyaka\anaconda3\envs\flower\lib\site-packages\flwr\simulation\ray_transport\ray_client_proxy.py", line 73, in _submit_job
    out_mssg, updated_context = self.actor_pool.get_client_result(
  File "C:\Users\jyaka\anaconda3\envs\flower\lib\site-packages\flwr\simulation\ray_transport\ray_actor.py", line 399, in get_client_result
    return self._fetch_future_result(cid)
  File "C:\Users\jyaka\anaconda3\envs\flower\lib\site-packages\flwr\simulation\ray_transport\ray_actor.py", line 280, in _fetch_future_result
    res_cid, out_mssg, updated_context = ray.get(
  File "C:\Users\jyaka\anaconda3\envs\flower\lib\site-packages\ray\_private\auto_init_hook.py", line 24, in auto_init_wrapper
    return fn(*args, **kwargs)
  File "C:\Users\jyaka\anaconda3\envs\flower\lib\site-packages\ray\_private\client_mode_hook.py", line 103, in wrapper
    return func(*args, **kwargs)
  File "C:\Users\jyaka\anaconda3\envs\flower\lib\site-packages\ray\_private\worker.py", line 2524, in get
    raise value.as_instanceof_cause()
ray.exceptions.RayTaskError(ClientAppException): [36mray::ClientAppActor.run()[39m (pid=16284, ip=127.0.0.1, actor_id=58b28ffec8e0f63ec8d7cc6701000000, repr=<flwr.simulation.ray_transport.ray_actor.ClientAppActor object at 0x000001FFD92780D0>)
  File "C:\Users\jyaka\anaconda3\envs\flower\lib\site-packages\flwr\client\client_app.py", line 98, in __call__
    return self._call(message, context)
  File "C:\Users\jyaka\anaconda3\envs\flower\lib\site-packages\flwr\client\client_app.py", line 81, in ffn
    out_message = handle_legacy_message_from_msgtype(
  File "C:\Users\jyaka\anaconda3\envs\flower\lib\site-packages\flwr\client\message_handler\message_handler.py", line 137, in handle_legacy_message_from_msgtype
    evaluate_res = maybe_call_evaluate(
  File "C:\Users\jyaka\anaconda3\envs\flower\lib\site-packages\flwr\client\client.py", line 254, in maybe_call_evaluate
    return client.evaluate(evaluate_ins)
  File "C:\Users\jyaka\anaconda3\envs\flower\lib\site-packages\flwr\client\numpy_client.py", line 262, in _evaluate
    results = self.numpy_client.evaluate(parameters, ins.config)  # type: ignore
  File "C:\Users\jyaka\Documents\research\flower_tutorial\client.py", line 50, in evaluate
    loss, accuracy = test(self.model, self.valloader)
  File "C:\Users\jyaka\Documents\research\flower_tutorial\centralized.py", line 108, in test
    net.test()
  File "C:\Users\jyaka\anaconda3\envs\flower\lib\site-packages\torch\nn\modules\module.py", line 1688, in __getattr__
    raise AttributeError(f"'{type(self).__name__}' object has no attribute '{name}'")
AttributeError: 'Net' object has no attribute 'test'

The above exception was the direct cause of the following exception:

[36mray::ClientAppActor.run()[39m (pid=16284, ip=127.0.0.1, actor_id=58b28ffec8e0f63ec8d7cc6701000000, repr=<flwr.simulation.ray_transport.ray_actor.ClientAppActor object at 0x000001FFD92780D0>)
  File "python\ray\_raylet.pyx", line 1418, in ray._raylet.execute_task
  File "python\ray\_raylet.pyx", line 1498, in ray._raylet.execute_task
  File "python\ray\_raylet.pyx", line 1424, in ray._raylet.execute_task
  File "python\ray\_raylet.pyx", line 1364, in ray._raylet.execute_task.function_executor
  File "C:\Users\jyaka\anaconda3\envs\flower\lib\site-packages\ray\_private\function_manager.py", line 726, in actor_method_executor
    return method(__ray_actor, *args, **kwargs)
  File "C:\Users\jyaka\anaconda3\envs\flower\lib\site-packages\ray\util\tracing\tracing_helper.py", line 464, in _resume_span
    return method(self, *_args, **_kwargs)
  File "C:\Users\jyaka\anaconda3\envs\flower\lib\site-packages\flwr\simulation\ray_transport\ray_actor.py", line 64, in run
    raise ClientAppException(str(ex)) from ex
flwr.client.client_app.ClientAppException: 
Exception ClientAppException occurred. Message: 'Net' object has no attribute 'test'

[2024-05-11 21:16:17,886][flwr][ERROR] - Traceback (most recent call last):
  File "C:\Users\jyaka\anaconda3\envs\flower\lib\site-packages\flwr\simulation\ray_transport\ray_client_proxy.py", line 73, in _submit_job
    out_mssg, updated_context = self.actor_pool.get_client_result(
  File "C:\Users\jyaka\anaconda3\envs\flower\lib\site-packages\flwr\simulation\ray_transport\ray_actor.py", line 399, in get_client_result
    return self._fetch_future_result(cid)
  File "C:\Users\jyaka\anaconda3\envs\flower\lib\site-packages\flwr\simulation\ray_transport\ray_actor.py", line 280, in _fetch_future_result
    res_cid, out_mssg, updated_context = ray.get(
  File "C:\Users\jyaka\anaconda3\envs\flower\lib\site-packages\ray\_private\auto_init_hook.py", line 24, in auto_init_wrapper
    return fn(*args, **kwargs)
  File "C:\Users\jyaka\anaconda3\envs\flower\lib\site-packages\ray\_private\client_mode_hook.py", line 103, in wrapper
    return func(*args, **kwargs)
  File "C:\Users\jyaka\anaconda3\envs\flower\lib\site-packages\ray\_private\worker.py", line 2524, in get
    raise value.as_instanceof_cause()
ray.exceptions.RayTaskError(ClientAppException): [36mray::ClientAppActor.run()[39m (pid=21472, ip=127.0.0.1, actor_id=67e56616aa6c08eb5efc71c101000000, repr=<flwr.simulation.ray_transport.ray_actor.ClientAppActor object at 0x0000020949D380D0>)
  File "C:\Users\jyaka\anaconda3\envs\flower\lib\site-packages\flwr\client\client_app.py", line 98, in __call__
    return self._call(message, context)
  File "C:\Users\jyaka\anaconda3\envs\flower\lib\site-packages\flwr\client\client_app.py", line 81, in ffn
    out_message = handle_legacy_message_from_msgtype(
  File "C:\Users\jyaka\anaconda3\envs\flower\lib\site-packages\flwr\client\message_handler\message_handler.py", line 137, in handle_legacy_message_from_msgtype
    evaluate_res = maybe_call_evaluate(
  File "C:\Users\jyaka\anaconda3\envs\flower\lib\site-packages\flwr\client\client.py", line 254, in maybe_call_evaluate
    return client.evaluate(evaluate_ins)
  File "C:\Users\jyaka\anaconda3\envs\flower\lib\site-packages\flwr\client\numpy_client.py", line 262, in _evaluate
    results = self.numpy_client.evaluate(parameters, ins.config)  # type: ignore
  File "C:\Users\jyaka\Documents\research\flower_tutorial\client.py", line 50, in evaluate
    loss, accuracy = test(self.model, self.valloader)
  File "C:\Users\jyaka\Documents\research\flower_tutorial\centralized.py", line 108, in test
    net.test()
  File "C:\Users\jyaka\anaconda3\envs\flower\lib\site-packages\torch\nn\modules\module.py", line 1688, in __getattr__
    raise AttributeError(f"'{type(self).__name__}' object has no attribute '{name}'")
AttributeError: 'Net' object has no attribute 'test'

The above exception was the direct cause of the following exception:

[36mray::ClientAppActor.run()[39m (pid=21472, ip=127.0.0.1, actor_id=67e56616aa6c08eb5efc71c101000000, repr=<flwr.simulation.ray_transport.ray_actor.ClientAppActor object at 0x0000020949D380D0>)
  File "python\ray\_raylet.pyx", line 1418, in ray._raylet.execute_task
  File "python\ray\_raylet.pyx", line 1498, in ray._raylet.execute_task
  File "python\ray\_raylet.pyx", line 1424, in ray._raylet.execute_task
  File "python\ray\_raylet.pyx", line 1364, in ray._raylet.execute_task.function_executor
  File "C:\Users\jyaka\anaconda3\envs\flower\lib\site-packages\ray\_private\function_manager.py", line 726, in actor_method_executor
    return method(__ray_actor, *args, **kwargs)
  File "C:\Users\jyaka\anaconda3\envs\flower\lib\site-packages\ray\util\tracing\tracing_helper.py", line 464, in _resume_span
    return method(self, *_args, **_kwargs)
  File "C:\Users\jyaka\anaconda3\envs\flower\lib\site-packages\flwr\simulation\ray_transport\ray_actor.py", line 64, in run
    raise ClientAppException(str(ex)) from ex
flwr.client.client_app.ClientAppException: 
Exception ClientAppException occurred. Message: 'Net' object has no attribute 'test'

[2024-05-11 21:16:17,894][flwr][ERROR] - [36mray::ClientAppActor.run()[39m (pid=16284, ip=127.0.0.1, actor_id=58b28ffec8e0f63ec8d7cc6701000000, repr=<flwr.simulation.ray_transport.ray_actor.ClientAppActor object at 0x000001FFD92780D0>)
  File "C:\Users\jyaka\anaconda3\envs\flower\lib\site-packages\flwr\client\client_app.py", line 98, in __call__
    return self._call(message, context)
  File "C:\Users\jyaka\anaconda3\envs\flower\lib\site-packages\flwr\client\client_app.py", line 81, in ffn
    out_message = handle_legacy_message_from_msgtype(
  File "C:\Users\jyaka\anaconda3\envs\flower\lib\site-packages\flwr\client\message_handler\message_handler.py", line 137, in handle_legacy_message_from_msgtype
    evaluate_res = maybe_call_evaluate(
  File "C:\Users\jyaka\anaconda3\envs\flower\lib\site-packages\flwr\client\client.py", line 254, in maybe_call_evaluate
    return client.evaluate(evaluate_ins)
  File "C:\Users\jyaka\anaconda3\envs\flower\lib\site-packages\flwr\client\numpy_client.py", line 262, in _evaluate
    results = self.numpy_client.evaluate(parameters, ins.config)  # type: ignore
  File "C:\Users\jyaka\Documents\research\flower_tutorial\client.py", line 50, in evaluate
    loss, accuracy = test(self.model, self.valloader)
  File "C:\Users\jyaka\Documents\research\flower_tutorial\centralized.py", line 108, in test
    net.test()
  File "C:\Users\jyaka\anaconda3\envs\flower\lib\site-packages\torch\nn\modules\module.py", line 1688, in __getattr__
    raise AttributeError(f"'{type(self).__name__}' object has no attribute '{name}'")
AttributeError: 'Net' object has no attribute 'test'

The above exception was the direct cause of the following exception:

[36mray::ClientAppActor.run()[39m (pid=16284, ip=127.0.0.1, actor_id=58b28ffec8e0f63ec8d7cc6701000000, repr=<flwr.simulation.ray_transport.ray_actor.ClientAppActor object at 0x000001FFD92780D0>)
  File "python\ray\_raylet.pyx", line 1418, in ray._raylet.execute_task
  File "python\ray\_raylet.pyx", line 1498, in ray._raylet.execute_task
  File "python\ray\_raylet.pyx", line 1424, in ray._raylet.execute_task
  File "python\ray\_raylet.pyx", line 1364, in ray._raylet.execute_task.function_executor
  File "C:\Users\jyaka\anaconda3\envs\flower\lib\site-packages\ray\_private\function_manager.py", line 726, in actor_method_executor
    return method(__ray_actor, *args, **kwargs)
  File "C:\Users\jyaka\anaconda3\envs\flower\lib\site-packages\ray\util\tracing\tracing_helper.py", line 464, in _resume_span
    return method(self, *_args, **_kwargs)
  File "C:\Users\jyaka\anaconda3\envs\flower\lib\site-packages\flwr\simulation\ray_transport\ray_actor.py", line 64, in run
    raise ClientAppException(str(ex)) from ex
flwr.client.client_app.ClientAppException: 
Exception ClientAppException occurred. Message: 'Net' object has no attribute 'test'
[2024-05-11 21:16:17,904][flwr][ERROR] - [36mray::ClientAppActor.run()[39m (pid=21472, ip=127.0.0.1, actor_id=67e56616aa6c08eb5efc71c101000000, repr=<flwr.simulation.ray_transport.ray_actor.ClientAppActor object at 0x0000020949D380D0>)
  File "C:\Users\jyaka\anaconda3\envs\flower\lib\site-packages\flwr\client\client_app.py", line 98, in __call__
    return self._call(message, context)
  File "C:\Users\jyaka\anaconda3\envs\flower\lib\site-packages\flwr\client\client_app.py", line 81, in ffn
    out_message = handle_legacy_message_from_msgtype(
  File "C:\Users\jyaka\anaconda3\envs\flower\lib\site-packages\flwr\client\message_handler\message_handler.py", line 137, in handle_legacy_message_from_msgtype
    evaluate_res = maybe_call_evaluate(
  File "C:\Users\jyaka\anaconda3\envs\flower\lib\site-packages\flwr\client\client.py", line 254, in maybe_call_evaluate
    return client.evaluate(evaluate_ins)
  File "C:\Users\jyaka\anaconda3\envs\flower\lib\site-packages\flwr\client\numpy_client.py", line 262, in _evaluate
    results = self.numpy_client.evaluate(parameters, ins.config)  # type: ignore
  File "C:\Users\jyaka\Documents\research\flower_tutorial\client.py", line 50, in evaluate
    loss, accuracy = test(self.model, self.valloader)
  File "C:\Users\jyaka\Documents\research\flower_tutorial\centralized.py", line 108, in test
    net.test()
  File "C:\Users\jyaka\anaconda3\envs\flower\lib\site-packages\torch\nn\modules\module.py", line 1688, in __getattr__
    raise AttributeError(f"'{type(self).__name__}' object has no attribute '{name}'")
AttributeError: 'Net' object has no attribute 'test'

The above exception was the direct cause of the following exception:

[36mray::ClientAppActor.run()[39m (pid=21472, ip=127.0.0.1, actor_id=67e56616aa6c08eb5efc71c101000000, repr=<flwr.simulation.ray_transport.ray_actor.ClientAppActor object at 0x0000020949D380D0>)
  File "python\ray\_raylet.pyx", line 1418, in ray._raylet.execute_task
  File "python\ray\_raylet.pyx", line 1498, in ray._raylet.execute_task
  File "python\ray\_raylet.pyx", line 1424, in ray._raylet.execute_task
  File "python\ray\_raylet.pyx", line 1364, in ray._raylet.execute_task.function_executor
  File "C:\Users\jyaka\anaconda3\envs\flower\lib\site-packages\ray\_private\function_manager.py", line 726, in actor_method_executor
    return method(__ray_actor, *args, **kwargs)
  File "C:\Users\jyaka\anaconda3\envs\flower\lib\site-packages\ray\util\tracing\tracing_helper.py", line 464, in _resume_span
    return method(self, *_args, **_kwargs)
  File "C:\Users\jyaka\anaconda3\envs\flower\lib\site-packages\flwr\simulation\ray_transport\ray_actor.py", line 64, in run
    raise ClientAppException(str(ex)) from ex
flwr.client.client_app.ClientAppException: 
Exception ClientAppException occurred. Message: 'Net' object has no attribute 'test'
[2024-05-11 21:16:17,918][flwr][INFO] - aggregate_evaluate: received 0 results and 2 failures
[2024-05-11 21:16:17,919][flwr][INFO] - 
[2024-05-11 21:16:17,920][flwr][INFO] - [SUMMARY]
[2024-05-11 21:16:17,920][flwr][INFO] - Run finished 2 rounds in 11.46s
[2024-05-11 21:16:17,921][flwr][INFO] - 
