[2024-05-13 18:07:05,213][flwr][INFO] - Starting Flower simulation, config: num_rounds=20, no round_timeout
[2024-05-13 18:07:10,616][flwr][INFO] - Flower VCE: Ray initialized with resources: {'memory': 11075415246.0, 'node:127.0.0.1': 1.0, 'object_store_memory': 5537707622.0, 'node:__internal_head__': 1.0, 'CPU': 8.0}
[2024-05-13 18:07:10,617][flwr][INFO] - Optimize your simulation with Flower VCE: https://flower.ai/docs/framework/how-to-run-simulations.html
[2024-05-13 18:07:10,617][flwr][INFO] - No `client_resources` specified. Using minimal resources for clients.
[2024-05-13 18:07:10,618][flwr][INFO] - Flower VCE: Resources for each Virtual Client: {'num_cpus': 1, 'num_gpus': 0.0}
[2024-05-13 18:07:10,628][flwr][INFO] - Flower VCE: Creating VirtualClientEngineActorPool with 8 actors
[2024-05-13 18:07:10,629][flwr][INFO] - [INIT]
[2024-05-13 18:07:10,630][flwr][INFO] - Requesting initial parameters from one random client
[2024-05-13 18:07:15,584][flwr][INFO] - Received initial parameters from one random client
[2024-05-13 18:07:15,584][flwr][INFO] - Evaluating initial global parameters
[2024-05-13 18:07:15,585][flwr][INFO] - 
[2024-05-13 18:07:15,586][flwr][INFO] - [ROUND 1]
[2024-05-13 18:07:15,587][flwr][INFO] - configure_fit: strategy sampled 1 clients (out of 13)
[2024-05-13 18:07:50,790][flwr][INFO] - aggregate_fit: received 1 results and 0 failures
[2024-05-13 18:07:50,792][flwr][WARNING] - No fit_metrics_aggregation_fn provided
[2024-05-13 18:07:50,793][flwr][INFO] - configure_evaluate: strategy sampled 1 clients (out of 13)
[2024-05-13 18:07:54,280][flwr][ERROR] - Traceback (most recent call last):
  File "C:\Users\jyaka\anaconda3\envs\flower\lib\site-packages\flwr\simulation\ray_transport\ray_client_proxy.py", line 73, in _submit_job
    out_mssg, updated_context = self.actor_pool.get_client_result(
  File "C:\Users\jyaka\anaconda3\envs\flower\lib\site-packages\flwr\simulation\ray_transport\ray_actor.py", line 399, in get_client_result
    return self._fetch_future_result(cid)
  File "C:\Users\jyaka\anaconda3\envs\flower\lib\site-packages\flwr\simulation\ray_transport\ray_actor.py", line 280, in _fetch_future_result
    res_cid, out_mssg, updated_context = ray.get(
  File "C:\Users\jyaka\anaconda3\envs\flower\lib\site-packages\ray\_private\auto_init_hook.py", line 24, in auto_init_wrapper
    return fn(*args, **kwargs)
  File "C:\Users\jyaka\anaconda3\envs\flower\lib\site-packages\ray\_private\client_mode_hook.py", line 103, in wrapper
    return func(*args, **kwargs)
  File "C:\Users\jyaka\anaconda3\envs\flower\lib\site-packages\ray\_private\worker.py", line 2524, in get
    raise value.as_instanceof_cause()
ray.exceptions.RayTaskError(ClientAppException): [36mray::ClientAppActor.run()[39m (pid=17688, ip=127.0.0.1, actor_id=3613b14cab92309504123db001000000, repr=<flwr.simulation.ray_transport.ray_actor.ClientAppActor object at 0x000001BCE60AB160>)
  File "C:\Users\jyaka\anaconda3\envs\flower\lib\site-packages\flwr\client\client_app.py", line 98, in __call__
    return self._call(message, context)
  File "C:\Users\jyaka\anaconda3\envs\flower\lib\site-packages\flwr\client\client_app.py", line 81, in ffn
    out_message = handle_legacy_message_from_msgtype(
  File "C:\Users\jyaka\anaconda3\envs\flower\lib\site-packages\flwr\client\message_handler\message_handler.py", line 137, in handle_legacy_message_from_msgtype
    evaluate_res = maybe_call_evaluate(
  File "C:\Users\jyaka\anaconda3\envs\flower\lib\site-packages\flwr\client\client.py", line 254, in maybe_call_evaluate
    return client.evaluate(evaluate_ins)
  File "C:\Users\jyaka\anaconda3\envs\flower\lib\site-packages\flwr\client\numpy_client.py", line 262, in _evaluate
    results = self.numpy_client.evaluate(parameters, ins.config)  # type: ignore
  File "C:\Users\jyaka\Documents\research\flower_tutorial\client.py", line 53, in evaluate
    loss, accuracy = test(self.model, self.valloader)
  File "C:\Users\jyaka\Documents\research\flower_tutorial\centralized.py", line 120, in test
    outputs = net(inputs)
  File "C:\Users\jyaka\anaconda3\envs\flower\lib\site-packages\torch\nn\modules\module.py", line 1511, in _wrapped_call_impl
    return self._call_impl(*args, **kwargs)
  File "C:\Users\jyaka\anaconda3\envs\flower\lib\site-packages\torch\nn\modules\module.py", line 1520, in _call_impl
    return forward_call(*args, **kwargs)
  File "C:\Users\jyaka\Documents\research\flower_tutorial\centralized.py", line 45, in forward
    x = self.l1(x)
  File "C:\Users\jyaka\anaconda3\envs\flower\lib\site-packages\torch\nn\modules\module.py", line 1511, in _wrapped_call_impl
    return self._call_impl(*args, **kwargs)
  File "C:\Users\jyaka\anaconda3\envs\flower\lib\site-packages\torch\nn\modules\module.py", line 1520, in _call_impl
    return forward_call(*args, **kwargs)
  File "C:\Users\jyaka\anaconda3\envs\flower\lib\site-packages\torch\nn\modules\linear.py", line 116, in forward
    return F.linear(input, self.weight, self.bias)
RuntimeError: mat1 and mat2 must have the same dtype, but got Double and Float

The above exception was the direct cause of the following exception:

[36mray::ClientAppActor.run()[39m (pid=17688, ip=127.0.0.1, actor_id=3613b14cab92309504123db001000000, repr=<flwr.simulation.ray_transport.ray_actor.ClientAppActor object at 0x000001BCE60AB160>)
  File "python\ray\_raylet.pyx", line 1418, in ray._raylet.execute_task
  File "python\ray\_raylet.pyx", line 1498, in ray._raylet.execute_task
  File "python\ray\_raylet.pyx", line 1424, in ray._raylet.execute_task
  File "python\ray\_raylet.pyx", line 1364, in ray._raylet.execute_task.function_executor
  File "C:\Users\jyaka\anaconda3\envs\flower\lib\site-packages\ray\_private\function_manager.py", line 726, in actor_method_executor
    return method(__ray_actor, *args, **kwargs)
  File "C:\Users\jyaka\anaconda3\envs\flower\lib\site-packages\ray\util\tracing\tracing_helper.py", line 464, in _resume_span
    return method(self, *_args, **_kwargs)
  File "C:\Users\jyaka\anaconda3\envs\flower\lib\site-packages\flwr\simulation\ray_transport\ray_actor.py", line 64, in run
    raise ClientAppException(str(ex)) from ex
flwr.client.client_app.ClientAppException: 
Exception ClientAppException occurred. Message: mat1 and mat2 must have the same dtype, but got Double and Float

[2024-05-13 18:07:54,293][flwr][ERROR] - [36mray::ClientAppActor.run()[39m (pid=17688, ip=127.0.0.1, actor_id=3613b14cab92309504123db001000000, repr=<flwr.simulation.ray_transport.ray_actor.ClientAppActor object at 0x000001BCE60AB160>)
  File "C:\Users\jyaka\anaconda3\envs\flower\lib\site-packages\flwr\client\client_app.py", line 98, in __call__
    return self._call(message, context)
  File "C:\Users\jyaka\anaconda3\envs\flower\lib\site-packages\flwr\client\client_app.py", line 81, in ffn
    out_message = handle_legacy_message_from_msgtype(
  File "C:\Users\jyaka\anaconda3\envs\flower\lib\site-packages\flwr\client\message_handler\message_handler.py", line 137, in handle_legacy_message_from_msgtype
    evaluate_res = maybe_call_evaluate(
  File "C:\Users\jyaka\anaconda3\envs\flower\lib\site-packages\flwr\client\client.py", line 254, in maybe_call_evaluate
    return client.evaluate(evaluate_ins)
  File "C:\Users\jyaka\anaconda3\envs\flower\lib\site-packages\flwr\client\numpy_client.py", line 262, in _evaluate
    results = self.numpy_client.evaluate(parameters, ins.config)  # type: ignore
  File "C:\Users\jyaka\Documents\research\flower_tutorial\client.py", line 53, in evaluate
    loss, accuracy = test(self.model, self.valloader)
  File "C:\Users\jyaka\Documents\research\flower_tutorial\centralized.py", line 120, in test
    outputs = net(inputs)
  File "C:\Users\jyaka\anaconda3\envs\flower\lib\site-packages\torch\nn\modules\module.py", line 1511, in _wrapped_call_impl
    return self._call_impl(*args, **kwargs)
  File "C:\Users\jyaka\anaconda3\envs\flower\lib\site-packages\torch\nn\modules\module.py", line 1520, in _call_impl
    return forward_call(*args, **kwargs)
  File "C:\Users\jyaka\Documents\research\flower_tutorial\centralized.py", line 45, in forward
    x = self.l1(x)
  File "C:\Users\jyaka\anaconda3\envs\flower\lib\site-packages\torch\nn\modules\module.py", line 1511, in _wrapped_call_impl
    return self._call_impl(*args, **kwargs)
  File "C:\Users\jyaka\anaconda3\envs\flower\lib\site-packages\torch\nn\modules\module.py", line 1520, in _call_impl
    return forward_call(*args, **kwargs)
  File "C:\Users\jyaka\anaconda3\envs\flower\lib\site-packages\torch\nn\modules\linear.py", line 116, in forward
    return F.linear(input, self.weight, self.bias)
RuntimeError: mat1 and mat2 must have the same dtype, but got Double and Float

The above exception was the direct cause of the following exception:

[36mray::ClientAppActor.run()[39m (pid=17688, ip=127.0.0.1, actor_id=3613b14cab92309504123db001000000, repr=<flwr.simulation.ray_transport.ray_actor.ClientAppActor object at 0x000001BCE60AB160>)
  File "python\ray\_raylet.pyx", line 1418, in ray._raylet.execute_task
  File "python\ray\_raylet.pyx", line 1498, in ray._raylet.execute_task
  File "python\ray\_raylet.pyx", line 1424, in ray._raylet.execute_task
  File "python\ray\_raylet.pyx", line 1364, in ray._raylet.execute_task.function_executor
  File "C:\Users\jyaka\anaconda3\envs\flower\lib\site-packages\ray\_private\function_manager.py", line 726, in actor_method_executor
    return method(__ray_actor, *args, **kwargs)
  File "C:\Users\jyaka\anaconda3\envs\flower\lib\site-packages\ray\util\tracing\tracing_helper.py", line 464, in _resume_span
    return method(self, *_args, **_kwargs)
  File "C:\Users\jyaka\anaconda3\envs\flower\lib\site-packages\flwr\simulation\ray_transport\ray_actor.py", line 64, in run
    raise ClientAppException(str(ex)) from ex
flwr.client.client_app.ClientAppException: 
Exception ClientAppException occurred. Message: mat1 and mat2 must have the same dtype, but got Double and Float
[2024-05-13 18:07:54,303][flwr][INFO] - aggregate_evaluate: received 0 results and 1 failures
[2024-05-13 18:07:54,304][flwr][INFO] - 
[2024-05-13 18:07:54,304][flwr][INFO] - [ROUND 2]
[2024-05-13 18:07:54,305][flwr][INFO] - configure_fit: strategy sampled 1 clients (out of 13)
[2024-05-13 18:08:29,216][flwr][INFO] - aggregate_fit: received 1 results and 0 failures
[2024-05-13 18:08:29,218][flwr][INFO] - configure_evaluate: strategy sampled 1 clients (out of 13)
[2024-05-13 18:08:32,637][flwr][ERROR] - Traceback (most recent call last):
  File "C:\Users\jyaka\anaconda3\envs\flower\lib\site-packages\flwr\simulation\ray_transport\ray_client_proxy.py", line 73, in _submit_job
    out_mssg, updated_context = self.actor_pool.get_client_result(
  File "C:\Users\jyaka\anaconda3\envs\flower\lib\site-packages\flwr\simulation\ray_transport\ray_actor.py", line 399, in get_client_result
    return self._fetch_future_result(cid)
  File "C:\Users\jyaka\anaconda3\envs\flower\lib\site-packages\flwr\simulation\ray_transport\ray_actor.py", line 280, in _fetch_future_result
    res_cid, out_mssg, updated_context = ray.get(
  File "C:\Users\jyaka\anaconda3\envs\flower\lib\site-packages\ray\_private\auto_init_hook.py", line 24, in auto_init_wrapper
    return fn(*args, **kwargs)
  File "C:\Users\jyaka\anaconda3\envs\flower\lib\site-packages\ray\_private\client_mode_hook.py", line 103, in wrapper
    return func(*args, **kwargs)
  File "C:\Users\jyaka\anaconda3\envs\flower\lib\site-packages\ray\_private\worker.py", line 2524, in get
    raise value.as_instanceof_cause()
ray.exceptions.RayTaskError(ClientAppException): [36mray::ClientAppActor.run()[39m (pid=17688, ip=127.0.0.1, actor_id=3613b14cab92309504123db001000000, repr=<flwr.simulation.ray_transport.ray_actor.ClientAppActor object at 0x000001BCE60AB160>)
  File "C:\Users\jyaka\anaconda3\envs\flower\lib\site-packages\flwr\client\client_app.py", line 98, in __call__
    return self._call(message, context)
  File "C:\Users\jyaka\anaconda3\envs\flower\lib\site-packages\flwr\client\client_app.py", line 81, in ffn
    out_message = handle_legacy_message_from_msgtype(
  File "C:\Users\jyaka\anaconda3\envs\flower\lib\site-packages\flwr\client\message_handler\message_handler.py", line 137, in handle_legacy_message_from_msgtype
    evaluate_res = maybe_call_evaluate(
  File "C:\Users\jyaka\anaconda3\envs\flower\lib\site-packages\flwr\client\client.py", line 254, in maybe_call_evaluate
    return client.evaluate(evaluate_ins)
  File "C:\Users\jyaka\anaconda3\envs\flower\lib\site-packages\flwr\client\numpy_client.py", line 262, in _evaluate
    results = self.numpy_client.evaluate(parameters, ins.config)  # type: ignore
  File "C:\Users\jyaka\Documents\research\flower_tutorial\client.py", line 53, in evaluate
    loss, accuracy = test(self.model, self.valloader)
  File "C:\Users\jyaka\Documents\research\flower_tutorial\centralized.py", line 120, in test
    outputs = net(inputs)
  File "C:\Users\jyaka\anaconda3\envs\flower\lib\site-packages\torch\nn\modules\module.py", line 1511, in _wrapped_call_impl
    return self._call_impl(*args, **kwargs)
  File "C:\Users\jyaka\anaconda3\envs\flower\lib\site-packages\torch\nn\modules\module.py", line 1520, in _call_impl
    return forward_call(*args, **kwargs)
  File "C:\Users\jyaka\Documents\research\flower_tutorial\centralized.py", line 45, in forward
    x = self.l1(x)
  File "C:\Users\jyaka\anaconda3\envs\flower\lib\site-packages\torch\nn\modules\module.py", line 1511, in _wrapped_call_impl
    return self._call_impl(*args, **kwargs)
  File "C:\Users\jyaka\anaconda3\envs\flower\lib\site-packages\torch\nn\modules\module.py", line 1520, in _call_impl
    return forward_call(*args, **kwargs)
  File "C:\Users\jyaka\anaconda3\envs\flower\lib\site-packages\torch\nn\modules\linear.py", line 116, in forward
    return F.linear(input, self.weight, self.bias)
RuntimeError: mat1 and mat2 must have the same dtype, but got Double and Float

The above exception was the direct cause of the following exception:

[36mray::ClientAppActor.run()[39m (pid=17688, ip=127.0.0.1, actor_id=3613b14cab92309504123db001000000, repr=<flwr.simulation.ray_transport.ray_actor.ClientAppActor object at 0x000001BCE60AB160>)
  File "python\ray\_raylet.pyx", line 1418, in ray._raylet.execute_task
  File "python\ray\_raylet.pyx", line 1498, in ray._raylet.execute_task
  File "python\ray\_raylet.pyx", line 1424, in ray._raylet.execute_task
  File "python\ray\_raylet.pyx", line 1364, in ray._raylet.execute_task.function_executor
  File "C:\Users\jyaka\anaconda3\envs\flower\lib\site-packages\ray\_private\function_manager.py", line 726, in actor_method_executor
    return method(__ray_actor, *args, **kwargs)
  File "C:\Users\jyaka\anaconda3\envs\flower\lib\site-packages\ray\util\tracing\tracing_helper.py", line 464, in _resume_span
    return method(self, *_args, **_kwargs)
  File "C:\Users\jyaka\anaconda3\envs\flower\lib\site-packages\flwr\simulation\ray_transport\ray_actor.py", line 64, in run
    raise ClientAppException(str(ex)) from ex
flwr.client.client_app.ClientAppException: 
Exception ClientAppException occurred. Message: mat1 and mat2 must have the same dtype, but got Double and Float

[2024-05-13 18:08:32,654][flwr][ERROR] - [36mray::ClientAppActor.run()[39m (pid=17688, ip=127.0.0.1, actor_id=3613b14cab92309504123db001000000, repr=<flwr.simulation.ray_transport.ray_actor.ClientAppActor object at 0x000001BCE60AB160>)
  File "C:\Users\jyaka\anaconda3\envs\flower\lib\site-packages\flwr\client\client_app.py", line 98, in __call__
    return self._call(message, context)
  File "C:\Users\jyaka\anaconda3\envs\flower\lib\site-packages\flwr\client\client_app.py", line 81, in ffn
    out_message = handle_legacy_message_from_msgtype(
  File "C:\Users\jyaka\anaconda3\envs\flower\lib\site-packages\flwr\client\message_handler\message_handler.py", line 137, in handle_legacy_message_from_msgtype
    evaluate_res = maybe_call_evaluate(
  File "C:\Users\jyaka\anaconda3\envs\flower\lib\site-packages\flwr\client\client.py", line 254, in maybe_call_evaluate
    return client.evaluate(evaluate_ins)
  File "C:\Users\jyaka\anaconda3\envs\flower\lib\site-packages\flwr\client\numpy_client.py", line 262, in _evaluate
    results = self.numpy_client.evaluate(parameters, ins.config)  # type: ignore
  File "C:\Users\jyaka\Documents\research\flower_tutorial\client.py", line 53, in evaluate
    loss, accuracy = test(self.model, self.valloader)
  File "C:\Users\jyaka\Documents\research\flower_tutorial\centralized.py", line 120, in test
    outputs = net(inputs)
  File "C:\Users\jyaka\anaconda3\envs\flower\lib\site-packages\torch\nn\modules\module.py", line 1511, in _wrapped_call_impl
    return self._call_impl(*args, **kwargs)
  File "C:\Users\jyaka\anaconda3\envs\flower\lib\site-packages\torch\nn\modules\module.py", line 1520, in _call_impl
    return forward_call(*args, **kwargs)
  File "C:\Users\jyaka\Documents\research\flower_tutorial\centralized.py", line 45, in forward
    x = self.l1(x)
  File "C:\Users\jyaka\anaconda3\envs\flower\lib\site-packages\torch\nn\modules\module.py", line 1511, in _wrapped_call_impl
    return self._call_impl(*args, **kwargs)
  File "C:\Users\jyaka\anaconda3\envs\flower\lib\site-packages\torch\nn\modules\module.py", line 1520, in _call_impl
    return forward_call(*args, **kwargs)
  File "C:\Users\jyaka\anaconda3\envs\flower\lib\site-packages\torch\nn\modules\linear.py", line 116, in forward
    return F.linear(input, self.weight, self.bias)
RuntimeError: mat1 and mat2 must have the same dtype, but got Double and Float

The above exception was the direct cause of the following exception:

[36mray::ClientAppActor.run()[39m (pid=17688, ip=127.0.0.1, actor_id=3613b14cab92309504123db001000000, repr=<flwr.simulation.ray_transport.ray_actor.ClientAppActor object at 0x000001BCE60AB160>)
  File "python\ray\_raylet.pyx", line 1418, in ray._raylet.execute_task
  File "python\ray\_raylet.pyx", line 1498, in ray._raylet.execute_task
  File "python\ray\_raylet.pyx", line 1424, in ray._raylet.execute_task
  File "python\ray\_raylet.pyx", line 1364, in ray._raylet.execute_task.function_executor
  File "C:\Users\jyaka\anaconda3\envs\flower\lib\site-packages\ray\_private\function_manager.py", line 726, in actor_method_executor
    return method(__ray_actor, *args, **kwargs)
  File "C:\Users\jyaka\anaconda3\envs\flower\lib\site-packages\ray\util\tracing\tracing_helper.py", line 464, in _resume_span
    return method(self, *_args, **_kwargs)
  File "C:\Users\jyaka\anaconda3\envs\flower\lib\site-packages\flwr\simulation\ray_transport\ray_actor.py", line 64, in run
    raise ClientAppException(str(ex)) from ex
flwr.client.client_app.ClientAppException: 
Exception ClientAppException occurred. Message: mat1 and mat2 must have the same dtype, but got Double and Float
[2024-05-13 18:08:32,666][flwr][INFO] - aggregate_evaluate: received 0 results and 1 failures
[2024-05-13 18:08:32,667][flwr][INFO] - 
[2024-05-13 18:08:32,668][flwr][INFO] - [ROUND 3]
[2024-05-13 18:08:32,668][flwr][INFO] - configure_fit: strategy sampled 1 clients (out of 13)
